package org.gtlcore.gtlcore.common.data.machines.structure;

import com.gregtechceu.gtceu.api.pattern.FactoryBlockPattern;
import com.gregtechceu.gtceu.api.pattern.util.RelativeDirection;

@SuppressWarnings("unused")
public class AdditionalMultiBlockMachineStructure {

    public static final FactoryBlockPattern ADVANCED_RARE_EARTH_CENTRIFUGAL = FactoryBlockPattern.start()
            .aisle("   AAAAAA     AAAAAA   ", "     B           B     ", "     B           B     ", "   CCCCC       CCCCC   ", "     B           B     ", "     B           B     ", "   CCCCC       CCCCC   ", "     B           B     ", "     B           B     ", "                       ", "                       ", "                       ", "                       ")
            .aisle("  AADDDDA     ADDDDAA  ", "                       ", "                       ", "  C     C     C     C  ", "                       ", "                       ", "  C     C     C     C  ", "                       ", "                       ", "                       ", "                       ", "                       ", "                       ")
            .aisle(" AADDDDDAA   AADDDDDAA ", "  B  D  B     B  D  B  ", "  B  E  B     B  E  B  ", " CB EEE BC   CB EEE BC ", "  B EEE B     B EEE B  ", "  B EEE B     B EEE B  ", " CB EEE BC   CB EEE BC ", "  B EEE B     B EEE B  ", "  B  E  B     B  E  B  ", "                       ", "                       ", "                       ", "                       ")
            .aisle("AADDDDDDDAAAAADDDDDDDAA", "     D           D     ", "   EEEEE       EEEEE   ", "C  EEEEE  C C  EEEEE  C", "   E F E       E F E   ", "   E F E       E F E   ", "C  E F E  C C  E F E  C", "   EEEEE       EEEEE   ", "   EEEEE       EEEEE   ", "                       ", "                       ", "                       ", "                       ")
            .aisle("ADDDDDDDDDDDDDDDDDDDDDA", "    DDD         DDD    ", "   EEEEE       EEEEE   ", "C EEGGGEE C C EEGGGEE C", "  E H H E     E H H E  ", "  E H H E     E H H E  ", "C E H H E C C E H H E C", "  EEGGGEE     EEGGGEE  ", "   EEEEE       EEEEE   ", "    DDD         DDD    ", "     III       III     ", "       IIIIIIIII       ", "                       ")
            .aisle("ADDDDDDDDDDDDDDDDDDDDDA", "B DDDDDDD B B DDDDDDD B", "B EEEEEEE B B EEEEEEE B", "C EEGGGEE C C EEGGGEE C", "B EF G FE B B EF G FE B", "B EF G FE B B EF G FE B", "C EF G FE C C EF G FE C", "B EEGGGEE B B EEGGGEE B", "B EEEGEEE B B EEEGEEE B", "    DGA         AGD    ", "     AAA       AAA     ", "       AAAAIAAAA       ", "          DDD          ")
            .aisle("ADDDDDDDDDDDDDDDDDDDDDA", "    DDD         DDD    ", "   EEEEE       EEEEE   ", "C EEGGGEE C C EEGGGEE C", "  E H H E     E H H E  ", "  E H H E     E H H E  ", "C E H H E C C E H H E C", "  EEGGGEE     EEGGGEE  ", "   EEEEE       EEEEE   ", "    DDD         DDD    ", "     III       III     ", "       IIIAIAIII       ", "          DDD          ")
            .aisle("ADDDDDDDDDDDDDDDDDDDDDA", "     D           D     ", "   EEEEE       EEEEE   ", "C  EEEEE  C C  EEEEE  C", "   E F E       E F E   ", "   E F E       E F E   ", "C  E F E  C C  E F E  C", "   EEEEE       EEEEE   ", "   EEEEE       EEEEE   ", "                       ", "                       ", "          AIA          ", "          DDD          ")
            .aisle("ADDDDDDDDDDDDDDDDDDDDDA", "  B  D  B  A  B  D  B  ", "  B     B  A  B     B  ", " CB EEE BC A CB EEE BC ", "  B EEE B  A  B EEE B  ", "  B EEE B  A  B EEE B  ", " CB EEE BC A CB EEE BC ", "  B EEE B  A  B EEE B  ", "  B  E  B  A  B  E  B  ", "           A           ", "           A           ", "          AAA          ", "          DDD          ")
            .aisle("AADDDDDDDDDDDDDDDDDDDAA", "          AAA          ", "          AAA          ", "  C     C AAA C     C  ", "          AAA          ", "          AAA          ", "  C     C AAA C     C  ", "          AAA          ", "          AAA          ", "          AAA          ", "          AAA          ", "          AAA          ", "          DDD          ")
            .aisle(" AAAADDDDDDDDDDDDDAAAA ", "     B     A     B     ", "     B     A     B     ", "   CCCCC   A   CCCCC   ", "     B     A     B     ", "     B     A     B     ", "   CCCCC   A   CCCCC   ", "     B     A     B     ", "     B     A     B     ", "           A           ", "           A           ", "          IAI          ", "          DDD          ")
            .aisle("    AADDDDDDDDDDDAA    ", "                       ", "                       ", "                       ", "                       ", "                       ", "                       ", "                       ", "                       ", "                       ", "                       ", "          IAI          ", "          DDD          ")
            .aisle("     ADDDDDDDDDDDA     ", "           B           ", "           B           ", "         CCCCC         ", "           B           ", "           B           ", "         CCCCC         ", "           B           ", "           B           ", "                       ", "                       ", "          IAI          ", "          DDD          ")
            .aisle("     AADDDDDDDDDAA     ", "                       ", "                       ", "        C     C        ", "                       ", "                       ", "        C     C        ", "                       ", "                       ", "                       ", "                       ", "          IAI          ", "                       ")
            .aisle("      AADDDDDDDAA      ", "        B  D  B        ", "        B  E  B        ", "       CB EEE BC       ", "        B EEE B        ", "        B EEE B        ", "       CB EEE BC       ", "        B EEE B        ", "        B  E  B        ", "                       ", "                       ", "          IAI          ", "                       ")
            .aisle("      ADDDDDDDDDA      ", "           D           ", "         EEEEE         ", "      C  EEEEE  C      ", "         E F E         ", "         E F E         ", "      C  E F E  C      ", "         EEEEE         ", "         EEEEE         ", "                       ", "          IAI          ", "          IAI          ", "                       ")
            .aisle("     AADDDDDDDDDAA     ", "          DDD          ", "         EEEEE         ", "      C EEGGGEE C      ", "        E H H E        ", "        E H H E        ", "      C E H H E C      ", "        EEGGGEE        ", "         EEEEE         ", "          DAD          ", "          IAI          ", "                       ", "                       ")
            .aisle("     ADDDDDDDDDDDA     ", "      B DDDDDDD B      ", "      B EEEEEEE B      ", "      C EEGGGEE C      ", "      B EF G FE B      ", "      B EF G FE B      ", "      C EF G FE C      ", "      B EEGGGEE B      ", "      B EEEGEEE B      ", "          DGD          ", "          IAI          ", "                       ", "                       ")
            .aisle("     ADDDDDDDDDDDA     ", "          DDD          ", "         EEEEE         ", "      C EEGGGEE C      ", "        E H H E        ", "        E H H E        ", "      C E H H E C      ", "        EEGGGEE        ", "         EEEEE         ", "          DDD          ", "                       ", "                       ", "                       ")
            .aisle("     ADDDDDDDDDDDA     ", "           D           ", "         EEEEE         ", "      C  EEEEE  C      ", "         E F E         ", "         E F E         ", "      C  E F E  C      ", "         EEEEE         ", "         EEEEE         ", "                       ", "                       ", "                       ", "                       ")
            .aisle("     AADDDDDDDDDAA     ", "        B  D  B        ", "        B     B        ", "       CB EEE BC       ", "        B EEE B        ", "        B EEE B        ", "       CB EEE BC       ", "        B EEE B        ", "        B  E  B        ", "                       ", "                       ", "                       ", "                       ")
            .aisle("      AAADDDDDAAA      ", "                       ", "                       ", "        C     C        ", "                       ", "                       ", "        C     C        ", "                       ", "                       ", "                       ", "                       ", "                       ", "                       ")
            .aisle("        AAAAAAA        ", "          ABA          ", "          ABA          ", "         CCCCC         ", "           B           ", "           B           ", "         CCCCC         ", "           B           ", "           B           ", "                       ", "                       ", "                       ", "                       ")
            .aisle("          AAA          ", "          AJA          ", "          AAA          ", "                       ", "                       ", "                       ", "                       ", "                       ", "                       ", "                       ", "                       ", "                       ", "                       ");

    public static final FactoryBlockPattern ADVANCED_VACUUM_DRYING_FURNACE = FactoryBlockPattern.start()
            .aisle("          AAAAAAA  ", "   BBBBBBBBBBBBBB  ", "   B         C     ", "           CCCCC   ", "          CCCCCCC  ", "         CCCCCCCCC ", "         CCCDDDCCC ", "        CCCCDDDCCCC", "         CCCDDDCCC ", "         CCCCCCCCC ", "          CCCCCCC  ", "           CCCCC   ", "             C     ", "                   ")
            .aisle("CCCCCCC   A CCC A  ", "  GGG       CCC B  ", "  GBG      FFFFF   ", "  GGG     FFFFFFF  ", "  GGG    FFFFFFFFF ", "  GGG   FFFFFFFFFFF", "  GGG   FFFFFFFFFFF", "  GGG   FFFFFFFFFFF", "  GGG   FFFFFFFFFFF", "   C    FFFFFFFFFFF", "         FFFFFFFFF ", "          FFFFFFF  ", "           FFFFF   ", "                   ")
            .aisle("CCCCCCC   A CCC A  ", " GGGGG      CCC B  ", " G B G     GGGGG   ", " G   G    GGHIHGG  ", " G   G   GG     GG ", " G   G  GG       GG", " G   G  GH       HG", " G   G  GI       IG", " G   G  GH       HG", " CCCCC  GG       GG", "   C     GG     GG ", "          GGHIHGG  ", "           GGGGG   ", "                   ")
            .aisle("CCCCCCC   A CCC A  ", "GGGGGGG     CCC B  ", "G  B  G    GGGGG   ", "G     G   GGHIHGG  ", "G     G  GG     GG ", "G     G GG       GG", "G     G GH       HG", "G     G GI       IG", "G     G GH       HG", " C   C  GG       GG", "  CCC    GG     GG ", "  JJJ     GGHIHGGA ", "           GGGGG A ", "          AAAAAAAA ")
            .aisle("CCCCCCC   A CCC A  ", "GGGGGGG     CCC B  ", "G  B  G    GGGGG   ", "G  B  G   GGHIHGG  ", "G  B  G  GG     GG ", "G  B  G GG       GG", "G  B  G GH       HG", "G  B  G GI       IG", "G  B  G GH       HG", "CC B CC GG       GG", " CCBCC   GG     GG ", "  JBJ     GGHIHGGA ", "   BBBBBBBBGGGGG   ", "          A        ")
            .aisle("CCCCCCC   A CCC A  ", "GGGGGGG     CCC B  ", "G  B  G    GGGGG   ", "G  B  G   GGHIHGG  ", "G  B  G  GG     GG ", "G  B  G GG       GG", "G  B  G GH       HG", "G  B  G GI       IG", "G  B  G GH       HG", "CC B CC GG       GG", " CCBCC   GG     GG ", "  JBJ     GGHIHGGA ", "   BBBBBBBBGGGGG A ", "          AAAAAAAA ")
            .aisle("CCCCCCC   A CCC A  ", "GGGGGGG     CCC B  ", "G     G    GGGGG   ", "G     G   GGHIHGG  ", "G     G  GG     GG ", "G     G GG       GG", "G     G GH       HG", "G     G GI       IG", "G     G GH       HG", " C   C  GG       GG", "  CCC    GG     GG ", "  JJJ     GGHIHGGA ", "          BGGGGG   ", "          A        ")
            .aisle("CCCCCCC   A CCC A  ", " GGGGG      CCC B  ", " G   G     GGGGG   ", " G   G    GGHIHGG  ", " G   G   GG     GG ", " G   G  GG       GG", " G   G  GH       HG", " G   G  GI       IG", " G   G  GH       HG", " CCCCC  GG       GG", "   C     GG     GG ", "          GGHIHGGA ", "          BGGGGG A ", "          AAAAAAAA ")
            .aisle("CCCCCCC   A CCC A  ", "  GGG       CCC B  ", "  GGG      GGGGGB  ", "  GGG     GGHIHGB  ", "  GGG    GG     BG ", "  GGG   GG       GG", "  GGG   GH       HG", "  GGG   GI       IG", "  GGG   GH       HG", "   C    GG       GG", "         GG     GG ", "          GGHIHGGA ", "          BGGGGG   ", "          A        ")
            .aisle("          A CCC A  ", "            CCC    ", "           GGGGG   ", "          GGHIHGG  ", "         GG     GG ", "        GG       GG", "        GH       HG", "        GI       IG", "        GH       HG", "        GG       GG", "         GG     GG ", "          GGHIHGGA ", "          BGGGGG A ", "          AAAAAAAA ")
            .aisle("          A CCC A  ", "            CCC    ", "           GGGGG   ", "          GGHIHGG  ", "         GG     GG ", "        GG       GG", "        GH       HG", "        GI       IG", "        GH       HG", "        GG       GG", "         GG     GG ", "          GGHIHGGA ", "          BGGGGG   ", "          A        ")
            .aisle("CCCCCCC   A CCC A  ", "GGGGGGG     CCC    ", "GGGGGGG    GGGGG   ", "GGGGGGG   GGHIHGG  ", "GGGGGGG  GG     GG ", "GGGGGGG GG       GG", "GGGGGGG HH       HH", "GGGGGGG GI       IG", "GGGGGGG HH       HH", "GGGGGGG GG       GG", "         GG     GG ", "          GGHIHGGA ", "          BGGGGG A ", "          AAAAAAAA ")
            .aisle("CCCCCCC   A CCC A  ", "GGGGGGG     CCC A  ", "G     G    GGGGGA  ", "G     G   GGHIHGA  ", "G     G  GG     AG ", "G     G GG       GG", "G     G HH       HH", "G     G GI       IG", "G     G HH       HH", "GGGGGGG GG       AG", "  JJJ    GG     GA ", "          GGHIHGGA ", "          BGGGGG   ", "          A        ")
            .aisle("CCCCCCC   A CCC    ", "GGGGGGG     CCC    ", "G     G    GGGGG   ", "G     G   GGHIHGG  ", "G     G  GG     GG ", "G     G GG       GG", "G     G HH       HH", "G     G GI       IG", "G     G HH       HH", "GGGAGGG GG       GG", "  JAJ    GG     GG ", "   A      GGHIHGG  ", "   A      BGGGGG   ", "   AAAAAAAA        ")
            .aisle("CCCCCCCAAAA CCC    ", "GGGGGGGA    CCC    ", "G   AAAA   FFFFF   ", "G     G   FGHIHGF  ", "G     G  FG     GF ", "G     G FG       GF", "G     G FH       HF", "G     G FI       IF", "G     G FH       HF", "GGGGGGG FG       GF", "  JJJ    FG     GF ", "          FGHIHGF  ", "          BFFFFF   ", "          A        ")
            .aisle("CCCCCCC  CCCCCCCCC ", "GGGGGGG  CCCCCCCCC ", "G     G  CCGGGGGCC ", "G     G  CGGHIHGGC ", "G     G  GG     GG ", "G     G GG       GG", "G     G HH       HH", "G     G GI       IG", "G     G HH       HH", "GGGAGGG GG       GG", "  JAJ    GG     GG ", "   A      GGHIHGG  ", "   A      BGGGGG   ", "   AAAAAAAA        ")
            .aisle("CCCCCCC  CCCCCCCCC ", "GGGGGGG  CCCCCCCCC ", "G     G  CCGGGGGCC ", "G     G  CGGHIHGGC ", "G     G  GG     GG ", "G     G GG       GG", "G     G HH       HH", "G     G GI       IG", "G     G HH       HH", "GGGGGGG GG       GG", "  JJJ    GG     GG ", "          GGHIHGG  ", "          BGGGGG   ", "                   ")
            .aisle("CCCCCCC  CCCCCCCCC ", "GGGGGGG  CCCCCCCCC ", "GGGGGGG  CCGGGGGCC ", "GGGGGGG  CGGHIHGGC ", "GGGGGGG  GG     GG ", "GGGGGGG GG       GG", "GGGGGGG HH       HH", "GGGGGGG GI       IG", "GGGGGGG HH       HH", "GGGGGGG GG       GG", "         GG     GG ", "          GGHIHGG  ", "          BGGGGG   ", "                   ")
            .aisle("         CCCCCCCCC ", "         CCCCCCCCC ", "         CCGGGGGCC ", "         CGGHIHGGC ", "         GG     GG ", "        GG       GG", "        GH       HG", "        GI       IG", "        GH       HG", "        GG       GG", "         GG     GG ", "          GGHIHGG  ", "          BGGGGG   ", "                   ")
            .aisle("         CCCCCCCCC ", "         CCCCCCCCC ", "         CCGGGGGCC ", "         CGGHIHGGC ", "         GG     GG ", "        GG       GG", "        GH       HG", "        GI       IG", "        GH       HG", "        GG       GG", "         GG     GG ", "          GGHIHGG  ", "          BGGGGG   ", "          BBBB     ")
            .aisle("         CCCCCCCCC ", "         CCCCCCCCC ", "         CCGGGGGCC ", "         CGGHIHGGC ", "         GG     GG ", "        GG       GG", "        GH       HG", "        GI       IG", "        GH       HG", "        GG       GG", "         GG     GG ", "          GGHIHGG  ", "           GGGGG   ", "             B     ")
            .aisle("         CCCCCCCCC ", "         CCCCCCCCC ", "         CCGGGGGCC ", "         CGGHIHGGC ", "         GG     GG ", "        GG       GG", "        GH       HG", "        GI       IG", "        GH       HG", "        GG       GG", "         GG     GG ", "          GGHIHGG  ", "           GGGGG   ", "             B     ")
            .aisle("  CCCCC  CCCCCCCCC ", "  KKKKK  CCCCCCCCC ", "  KKKKK  CCGGGGGCC ", "  KKKKK  CGGHIHGGC ", "  KKKKK  GG     GG ", "  KKKKK GG       GG", "  KKKKK GH       HG", "        GI       IG", "        GH       HG", "        GG       GG", "         GG     GG ", "          GGHIHGG  ", "           GGGGG   ", "             B     ")
            .aisle("  CCCCC  CCCCCCCCC ", "  KKKKK  CCCCCCCCC ", "  K   K  CCGGGGGCC ", "  L   L  CGGHIHGGC ", "  L   L  GG H H GG ", "  L   L GG  H H  GG", "  KKKKK GHHHHHHHHHG", "        GI  H H  IG", "        GHHHHHHHHHG", "        GG  H H  GG", "         GG H H GG ", "          GGHIHGG  ", "           GGBGG   ", "             B     ")
            .aisle("  CCCCC            ", "  KKKKK            ", "  KMMMK    FFFFF   ", "  KMNMK   FFOOOFF  ", "  KMMMK  FFO   OFF ", "  KMMMK FFO     OFF", "  KKKKK PO       OF", "        PO       OF", "        PO       OF", "        FFO     OFF", "         FFO   OFF ", "          FFOOOFF  ", "           FFFFF   ", "                   ")
            .aisle("                   ", "                   ", "            F F    ", "           CCCCC   ", "          CCCCCCC  ", "         CCCCCCCCC ", "        MCCCQQQCCCF", "        MCCCQQQCCC ", "        MCCCQQQCCCF", "         CCCCCCCCC ", "          CCCCCCC  ", "           CCCCC   ", "            F F    ", "                   ")
            .aisle("                   ", "                   ", "                   ", "                   ", "                   ", "                   ", "        MMM        ", "        MMM        ", "        MMM        ", "                   ", "                   ", "                   ", "                   ", "                   ");

    public static final FactoryBlockPattern HUGE_INCUBATOR = FactoryBlockPattern.start()
            .aisle("   ABBBBBA   CCC   ABBBBBA   ", "   AAAAAAA   CCC   AAAAAAA   ", "   A     A   CDC   A     A   ", "             CDC             ", "             CDC             ", "             CCC             ", "             CCC             ", "                             ", "                             ", "                             ", "                             ", "                             ", "                             ", "                             ", "                             ", "                             ", "                             ", "                             ", "                             ", "                             ", "                             ", "                             ", "                             ", "                             ", "                             ", "                             ")
            .aisle(" EEEEEEEEEEEEEEEEEEEEEEEEEEE ", "  AAAAAAAAAEECCCEEAAAAAAAAA  ", "   A     A EEC CEE A     A   ", "   AAAAAAA   C C   AAAAAAA   ", "   A     A   C C   A     A   ", "             C C             ", "             CFC             ", "                             ", "                             ", "                             ", "                             ", "                             ", "                             ", "                             ", "                             ", "                             ", "                             ", "                             ", "                             ", "                             ", "                             ", "                             ", "                             ", "                             ", "                             ", "                             ")
            .aisle(" EEEEEEEEEEEE E EEEEEEEEEEEE ", " AAAAAAAAAAAECCCEAAAAAAAAAAA ", "  GABBBBBAG EC CE GABBBBBAG  ", "  GAHHHHHAG EC CE GAHHHHHAG  ", "  GA     AG EC CE GA     AG  ", "  GAAAAAAAG  C C  GAAAAAAAG  ", "  G       G  CFC  G       G  ", "  I       I   J   I       I  ", "     HHH      J      HHH     ", "    HHHHH     J     HHHHH    ", "    HHHHH     J     HHHHH    ", "    HHHHH           HHHHH    ", "    HHHHH           HHHHH    ", "    HHHHH           HHHHH    ", "    KKKKK           KKKKK    ", "    HHHHH           HHHHH    ", "    HHHHH           HHHHH    ", "    HHHHH           HHHHH    ", "    HHHHH           HHHHH    ", "    HHHHH           HHHHH    ", "                             ", "                             ", "                             ", "                             ", "                             ", "                             ")
            .aisle("AEEEEEEEEEEEE E EEEEEEEEEEEEA", "AAAAAAAAAAAAECCCEAAAAAAAAAAAA", "AAAA     AAAEC CEAAA     AAAA", " AAAAAAAAAAAEC CEAAAAAAAAAAA ", " AAABBBBBAAAEC CEAAABBBBBAAA ", "  AAA   AAA EC CE AAA   AAA  ", "            ECFCE            ", "     HHH             HHH     ", "    HHHHH           HHHHH    ", "   HH   HH         HH   HH   ", "   HH   HH    J    HH   HH   ", "   HH   HH         HH   HH   ", "   HH   HH         HH   HH   ", "   HH   HH         HH   HH   ", "   KK   KK         KK   KK   ", "   HH   HH         HH   HH   ", "   HH   HH         HH   HH   ", "   HH   HH         HH   HH   ", "   HH   HH         HH   HH   ", "   HHHHHHH         HHHHHHH   ", "    HHHHH           HHHHH    ", "                             ", "                             ", "                             ", "                             ", "                             ")
            .aisle("BEEEEEEEEEEEE E EEEEEEEEEEEEB", "AAAAAAAAAAAAECCCEAAAAAAAAAAAA", "  B       B EC CE B       B  ", " AHA     AHAEC CEAHA     AHA ", "   B     B  EC CE  B     B   ", "  AA     AA EC CE AA     AA  ", "     HHH    ECCCE    HHH     ", "    HHHHH   ECCCE   HHHHH    ", "   H     H  ECCCE  H     H   ", "  HH     HH  CCC  HH     HH  ", "  HH     HH   J   HH     HH  ", "  HH     HH       HH     HH  ", "  HH     HH       HH     HH  ", "  HH     HH       HH     HH  ", "  KK     KK       KK     KK  ", "  HH     HH       HH     HH  ", "  HH     HH       HH     HH  ", "  HH     HH       HH     HH  ", "  HH     HH       HH     HH  ", "  HHH   HHH       HHH   HHH  ", "   HHHHHHH         HHHHHHH   ", "    HHHHH           HHHHH    ", "                             ", "                             ", "                             ", "                             ")
            .aisle("BEEEEEEEEEEEE E EEEEEEEEEEEEB", "AAAAAAAAAAAAECCCEAAAAAAAAAAAA", "  B  L L  B EC CE B  L L  B  ", " AHA L L AHAEC CEAHA L L AHA ", "   B L L B  EC CE  B L L B   ", "  A  HHH  A EC CE A  HHH  A  ", "    HHHHH   EC CE   HHHHH    ", "   HHMMMHH  EC CE  HHMMMHH   ", "  HH     HH EC CE HH     HH  ", "  H       H  CCC  H       H  ", "  H       H   J   H       H  ", "  H       H       H       H  ", "  H       H       H       H  ", "  H       H       H       H  ", "  K       K       K       K  ", "  H       H       H       H  ", "  H       H       H       H  ", "  H       H       H       H  ", "  H       H       H       H  ", "  HH     HH       HH     HH  ", "   HH   HH         HH   HH   ", "    HBBBH           HBBBH    ", "                             ", "                             ", "                             ", "                             ")
            .aisle("BEEEEEEEEEEEEEEEEEEEEEEEEEEEB", "AAAAAAAAAAAAECCCEAAAAAAAAAAAA", "  B   N   B ECFCE B   N   B  ", " AHA  N  AHAECFCEAHA  N  AHA ", "   B  N  B  ECFCE  B  N  B   ", "  A  HHH  A ECFCE A  HHH  A  ", "    HHHHH   ECFCE   HHHHH    ", "   HHMMMHH  ECFCE  HHMMMHH   ", "  HH     HH ECFCE HH     HH  ", "  H       H  CFC  H       H  ", "  H       H   J   H       H  ", "  H       H       H       H  ", "  H       H       H       H  ", "  H       H       H       H  ", "  K       K       K       K  ", "  H       H       H       H  ", "  H       H       H       H  ", "  H       H       H       H  ", "  H       H       H       H  ", "  HH     HH       HH     HH  ", "   HH   HH         HH   HH   ", "    HBFBH           HBFBH    ", "      O               O      ", "      O               O      ", "                             ", "                             ")
            .aisle("BEEEEEEEEEEEE E EEEEEEEEEEEEB", "AAAAAAAAAAAAECCCEAAAAAAAAAAAA", "  B  L L  B ECCCE B  L L  B  ", " AHA L L AHAECCCEAHA L L AHA ", "   B L L B  ECCCE  B L L B   ", "  A  HHH  A ECCCE A  HHH  A  ", "    HHHHH   ECCCE   HHHHH    ", "   HHMMMHH  ECCCE  HHMMMHH   ", "  HH     HH ECCCE HH     HH  ", "  H       H  CCC  H       H  ", "  H       H   J   H       H  ", "  H       H       H       H  ", "  H       H       H       H  ", "  H       H       H       H  ", "  K       K       K       K  ", "  H       H       H       H  ", "  H       H       H       H  ", "  H       H       H       H  ", "  H       H       H       H  ", "  HH     HH       HH     HH  ", "   HH   HH         HH   HH   ", "    HBBBH           HBBBH    ", "                             ", "      O               O      ", "                             ", "                             ")
            .aisle("BEEEEEEEEEEEE E EEEEEEEEEEEEB", "AAAAAAAAAAAAEEEEEAAAAAAAAAAAA", "  B       B EEEEE B       B  ", " AHA     AHAEEEEEAHA     AHA ", "   B     B  EEEEE  B     B   ", "  AA     AA EEEEE AA     AA  ", "     HHH    EEEEE    HHH     ", "    HHHHH   EEEEE   HHHHH    ", "   H     H  EEEEE  H     H   ", "  HH     HH       HH     HH  ", "  HH     HH   J   HH     HH  ", "  HH     HH       HH     HH  ", "  HH     HH       HH     HH  ", "  HH     HH       HH     HH  ", "  KK     KK       KK     KK  ", "  HH     HH       HH     HH  ", "  HH     HH       HH     HH  ", "  HH     HH       HH     HH  ", "  HH     HH       HH     HH  ", "  HHH   HHH       HHH   HHH  ", "   HHHHHHH         HHHHHHH   ", "    HHHHH           HHHHH    ", "                             ", "      O               O      ", "                             ", "                             ")
            .aisle("AEEEEEEEEEEE  E  EEEEEEEEEEEA", "AAAAAAAAAAAA     AAAAAAAAAAAA", "AAAA     AAA     AAA     AAAA", " AAAAAAAAAAA     AAAAAAAAAAA ", " AAABBBBBAAA     AAABBBBBAAA ", "  AAA   AAA       AAA   AAA  ", "                             ", "     HHH             HHH     ", "    HHHHH           HHHHH    ", "   HH   HH         HH   HH   ", "   HH   HH    J    HH   HH   ", "   HH   HH    J    HH   HH   ", "   HH   HH    J    HH   HH   ", "   HH   HH         HH   HH   ", "   KK   KK         KK   KK   ", "   HH   HH         HH   HH   ", "   HH   HH         HH   HH   ", "   HH   HH         HH   HH   ", "   HH   HH         HH   HH   ", "   HHHHHHH         HHHHHHH   ", "    HHHHH           HHHHH    ", "                             ", "                             ", "      O               O      ", "                             ", "                             ")
            .aisle(" EEEEEEEEEEEEEEEEEEEEEEEEEEE ", " AAAAAAAAAAA LLL AAAAAAAAAAA ", "  GABBBBBAG  LLL  GABBBBBAG  ", "  GAHHHHHAG  LLL  GAHHHHHAG  ", "  GA     AG  LLL  GA     AG  ", "  GAAAAAAAG  LLL  GAAAAAAAG  ", "  G       G  LLL  G       G  ", "  I       I  LLL  I       I  ", "     HHH     LLL     HHH     ", "    HHHHH    LLL    HHHHH    ", "    HHHHH    LLL    HHHHH    ", "    HHHHH    LLL    HHHHH    ", "    HHHHH    LLL    HHHHH    ", "    HHHHH    LLL    HHHHH    ", "    KKKKK    LLL    KKKKK    ", "    HHHHH    LLL    HHHHH    ", "    HHHHH    LLL    HHHHH    ", "    HHHHH    LLL    HHHHH    ", "    HHHHH    LLL    HHHHH    ", "    HHHHH           HHHHH    ", "                             ", "                             ", "                             ", "      O               O      ", "                             ", "                             ")
            .aisle(" EEEEEEEEEE   E   EEEEEEEEEE ", " EAAAAAAAAA LLBLL AAAAAAAAAE ", " E A     A  LLFLL  A     A E ", "   AAAAAAA  LLFLL  AAAAAAA   ", "   A     A  LLFLL  A     A   ", "            LLFLL            ", "            LLFLL            ", "            LLFLL            ", "            LLFLL            ", "            LLFLL            ", "            LLFLL            ", "            LLFLL            ", "            LLFLL            ", "            LLFLL            ", "            LLFLL            ", "            LLFLL            ", "            LLFLL            ", "            LLFLL            ", "            LLFLL            ", "             LLL             ", "                             ", "                             ", "                             ", "      O               O      ", "                             ", "                             ")
            .aisle(" EEEEEEEE E   E   E EEEEEEEE ", " EEEEEEEE  LLBBBLL  EEEEEEEE ", " EEEEEEEE  LL   LL  EEEEEEEE ", "  EEEEEEE  LL   LL  EEEEEEE  ", "  EEEEEEE  LL   LL  EEEEEEE  ", "   EEEEEE  LL   LL  EEEEEE   ", "   EEEEEE  LL   LL  EEEEEE   ", "    EEEEE  LL   LL  EEEEE    ", "    EEEEE  LL   LL  EEEEE    ", "           LL   LL           ", "           LL   LL           ", "           LL   LL           ", "           LL   LL           ", "           LL   LL           ", "           LL   LL           ", "           LL   LL           ", "           LL   LL           ", "           LL   LL           ", "           LL F LL           ", "            LLLLL            ", "             KKK             ", "                             ", "                             ", "      O               O      ", "                             ", "                             ")
            .aisle("CE    E   E   E   E   E    EC", "CCCCCCCCE LLBBBBBLL ECCCCCCCC", "CCCCCCCCE LL  N  LL ECCCCCCCC", "CCCCCCCCE LL  N  LL ECCCCCCCC", "CCCCCCCCE LL  N  LL ECCCCCCCC", "CCCCCCCCE LL  N  LL ECCCCCCCC", "CCCCCCCCE LL  I  LL ECCCCCCCC", "    CCCCE LL  I  LL ECCCC    ", "    CCCCE LL  I  LL ECCCC    ", "    CCCC  LL     LL  CCCC    ", "          LL     LL          ", "          LL     LL          ", "          LL     LL          ", "          LL     LL          ", "          LL     LL          ", "          LL     LL          ", "          LL     LL          ", "          LL     LL          ", "          LL  F  LL          ", "           LLKKKLL           ", "            KPPPK            ", "             P P             ", "             P P             ", "      O      P P      O      ", "             KKK             ", "                             ")
            .aisle("CEEEEEEEEEEEEEEEEEEEEEEEEEEEC", "CCCCCCCCE LBBBBBBBL ECCCCCCCC", "D     FCE LF NRN FL ECF     D", "D     FCE LF NRN FL ECF     D", "D     FCE LF NRN FL ECF     D", "C     FCE LF NRN FL ECF     C", "CFFFC FCE LF IRI FL ECF CFFFC", "  J C FCE LF IRI FL ECF C J  ", "  J C FCE LF IRI FL ECF C J  ", "  J CCFC  LF  F  FL  CFCC J  ", "  JJJJJJJJLF  F  FLJJJJJJJJ  ", "         JLF  F  FLJ         ", "         JLF  F  FLJ         ", "          LF  F  FL          ", "          LF  F  FL          ", "          LF  F  FL          ", "          LF  F  FL          ", "          LF  F  FL          ", "          LFFFFFFFL          ", "           LLFFFLL           ", "            KOPOK            ", "             OPO             ", "             OPO             ", "      OOOOOOOOPOOOOOOOO      ", "             KKK             ", "                             ")
            .aisle("CE    E   E   E   E   E    EC", "CCCCCCCCE LLBBBBBLL ECCCCCCCC", "CCCCCCCCE LL  N  LL ECCCCCCCC", "CCCCCCCCE LL  N  LL ECCCCCCCC", "CCCCCCCCE LL  N  LL ECCCCCCCC", "CCCCCCCCE LL  N  LL ECCCCCCCC", "CCCCCCCCE LL  I  LL ECCCCCCCC", "    CCCCE LL  I  LL ECCCC    ", "    CCCCE LL  I  LL ECCCC    ", "    CCCC  LL     LL  CCCC    ", "          LL     LL          ", "          LL     LL          ", "          LL     LL          ", "          LL     LL          ", "          LL     LL          ", "          LL     LL          ", "          LL     LL          ", "          LL     LL          ", "          LL  F  LL          ", "           LLKKKLL           ", "            KPPPK            ", "             P P             ", "             P P             ", "      O      P P      O      ", "             KKK             ", "                             ")
            .aisle(" EEEEEEEE E   E   E EEEEEEEE ", " EEEEEEEE  LLBBBLL  EEEEEEEE ", " EEEEEEEE  LL   LL  EEEEEEEE ", "  EEEEEEE  LL   LL  EEEEEEE  ", "  EEEEEEE  LL   LL  EEEEEEE  ", "   EEEEEE  LL   LL  EEEEEE   ", "   EEEEEE  LL   LL  EEEEEE   ", "    EEEEE  LL   LL  EEEEE    ", "    EEEEE  LL   LL  EEEEE    ", "           LL   LL           ", "           LL   LL           ", "           LL   LL           ", "           LL   LL           ", "           LL   LL           ", "           LL   LL           ", "           LL   LL           ", "           LL   LL           ", "           LL   LL           ", "           LL F LL           ", "            LLLLL            ", "             KKK             ", "                             ", "                             ", "      O               O      ", "                             ", "                             ")
            .aisle(" EEEEEEEEEE   E   EEEEEEEEEE ", " EAAAAAAAAA LLBLL AAAAAAAAAE ", " E A     A  LLFLL  A     A E ", "   AAAAAAA  LLFLL  AAAAAAA   ", "   A     A  LLFLL  A     A   ", "            LLFLL            ", "            LLFLL            ", "            LLFLL            ", "            LLFLL            ", "            LLFLL            ", "            LLFLL            ", "            LLFLL            ", "            LLFLL            ", "            LLFLL            ", "            LLFLL            ", "            LLFLL            ", "            LLFLL            ", "            LLFLL            ", "            LLFLL            ", "             LLL             ", "                             ", "                             ", "                             ", "      O               O      ", "                             ", "                             ")
            .aisle(" EEEEEEEEEEEEEEEEEEEEEEEEEEE ", " AAAAAAAAAAA LLL AAAAAAAAAAA ", "  GABBBBBAG  LLL  GABBBBBAG  ", "  GAHHHHHAG  LLL  GAHHHHHAG  ", "  GA     AG  LLL  GA     AG  ", "  GAAAAAAAG  LLL  GAAAAAAAG  ", "  G       G  LLL  G       G  ", "  I       I  LLL  I       I  ", "     HHH     LLL     HHH     ", "    HHHHH    LLL    HHHHH    ", "    HHHHH    LLL    HHHHH    ", "    HHHHH    LLL    HHHHH    ", "    HHHHH    LLL    HHHHH    ", "    HHHHH    LLL    HHHHH    ", "    KKKKK    LLL    KKKKK    ", "    HHHHH    LLL    HHHHH    ", "    HHHHH    LLL    HHHHH    ", "    HHHHH    LLL    HHHHH    ", "    HHHHH    LLL    HHHHH    ", "    HHHHH           HHHHH    ", "                             ", "                             ", "                             ", "      O               O      ", "                             ", "                             ")
            .aisle("AEEEEEEEEEEE  E  EEEEEEEEEEEA", "AAAAAAAAAAAA     AAAAAAAAAAAA", "AAAA     AAA     AAA     AAAA", " AAAAAAAAAAA     AAAAAAAAAAA ", " AAABBBBBAAA     AAABBBBBAAA ", "  AAA   AAA       AAA   AAA  ", "                             ", "     HHH             HHH     ", "    HHHHH           HHHHH    ", "   HH   HH         HH   HH   ", "   HH   HH    J    HH   HH   ", "   HH   HH    J    HH   HH   ", "   HH   HH    J    HH   HH   ", "   HH   HH         HH   HH   ", "   KK   KK         KK   KK   ", "   HH   HH         HH   HH   ", "   HH   HH         HH   HH   ", "   HH   HH         HH   HH   ", "   HH   HH         HH   HH   ", "   HHHHHHH         HHHHHHH   ", "    HHHHH           HHHHH    ", "                             ", "                             ", "      O               O      ", "                             ", "                             ")
            .aisle("BEEEEEEEEEEEE E EEEEEEEEEEEEB", "AAAAAAAAAAAAEEEEEAAAAAAAAAAAA", "  B       B EEEEE B       B  ", " AHA     AHAEEEEEAHA     AHA ", "   B     B  EEEEE  B     B   ", "  AA     AA EEEEE AA     AA  ", "     HHH    EEEEE    HHH     ", "    HHHHH   EEEEE   HHHHH    ", "   H     H  EEEEE  H     H   ", "  HH     HH       HH     HH  ", "  HH     HH   J   HH     HH  ", "  HH     HH       HH     HH  ", "  HH     HH       HH     HH  ", "  HH     HH       HH     HH  ", "  KK     KK       KK     KK  ", "  HH     HH       HH     HH  ", "  HH     HH       HH     HH  ", "  HH     HH       HH     HH  ", "  HH     HH       HH     HH  ", "  HHH   HHH       HHH   HHH  ", "   HHHHHHH         HHHHHHH   ", "    HHHHH           HHHHH    ", "                             ", "      O               O      ", "                             ", "                             ")
            .aisle("BEEEEEEEEEEEE E EEEEEEEEEEEEB", "AAAAAAAAAAAAECCCEAAAAAAAAAAAA", "  B  L L  B ECCCE B  L L  B  ", " AHA L L AHAECCCEAHA L L AHA ", "   B L L B  ECCCE  B L L B   ", "  A  HHH  A ECCCE A  HHH  A  ", "    HHHHH   ECCCE   HHHHH    ", "   HHMMMHH  ECCCE  HHMMMHH   ", "  HH     HH ECCCE HH     HH  ", "  H       H  CCC  H       H  ", "  H       H   J   H       H  ", "  H       H       H       H  ", "  H       H       H       H  ", "  H       H       H       H  ", "  K       K       K       K  ", "  H       H       H       H  ", "  H       H       H       H  ", "  H       H       H       H  ", "  H       H       H       H  ", "  HH     HH       HH     HH  ", "   HH   HH         HH   HH   ", "    HBBBH           HBBBH    ", "                             ", "      O               O      ", "                             ", "                             ")
            .aisle("BEEEEEEEEEEEEEEEEEEEEEEEEEEEB", "AAAAAAAAAAAAECCCEAAAAAAAAAAAA", "  B   N   B ECFCE B   N   B  ", " AHA  N  AHAECFCEAHA  N  AHA ", "   B  N  B  ECFCE  B  N  B   ", "  A  HHH  A ECFCE A  HHH  A  ", "    HHHHH   ECFCE   HHHHH    ", "   HHMMMHH  ECFCE  HHMMMHH   ", "  HH     HH ECFCE HH     HH  ", "  H       H  CFC  H       H  ", "  H       H   J   H       H  ", "  H       H       H       H  ", "  H       H       H       H  ", "  H       H       H       H  ", "  K       K       K       K  ", "  H       H       H       H  ", "  H       H       H       H  ", "  H       H       H       H  ", "  H       H       H       H  ", "  HH     HH       HH     HH  ", "   HH   HH         HH   HH   ", "    HBFBH           HBFBH    ", "      O               O      ", "      O               O      ", "                             ", "                             ")
            .aisle("BEEEEEEEEEEEE E EEEEEEEEEEEEB", "AAAAAAAAAAAAECCCEAAAAAAAAAAAA", "  B  L L  B EC CE B  L L  B  ", " AHA L L AHAEC CEAHA L L AHA ", "   B L L B  EC CE  B L L B   ", "  A  HHH  A EC CE A  HHH  A  ", "    HHHHH   EC CE   HHHHH    ", "   HHMMMHH  EC CE  HHMMMHH   ", "  HH     HH EC CE HH     HH  ", "  H       H  CCC  H       H  ", "  H       H   J   H       H  ", "  H       H       H       H  ", "  H       H       H       H  ", "  H       H       H       H  ", "  K       K       K       K  ", "  H       H       H       H  ", "  H       H       H       H  ", "  H       H       H       H  ", "  H       H       H       H  ", "  HH     HH       HH     HH  ", "   HH   HH         HH   HH   ", "    HBBBH           HBBBH    ", "                             ", "                             ", "                             ", "                             ")
            .aisle("BEEEEEEEEEEEE E EEEEEEEEEEEEB", "AAAAAAAAAAAAECCCEAAAAAAAAAAAA", "  B       B EC CE B       B  ", " AHA     AHAEC CEAHA     AHA ", "   B     B  EC CE  B     B   ", "  AA     AA EC CE AA     AA  ", "     HHH    ECCCE    HHH     ", "    HHHHH   ECCCE   HHHHH    ", "   H     H  ECCCE  H     H   ", "  HH     HH  CCC  HH     HH  ", "  HH     HH   J   HH     HH  ", "  HH     HH       HH     HH  ", "  HH     HH       HH     HH  ", "  HH     HH       HH     HH  ", "  KK     KK       KK     KK  ", "  HH     HH       HH     HH  ", "  HH     HH       HH     HH  ", "  HH     HH       HH     HH  ", "  HH     HH       HH     HH  ", "  HHH   HHH       HHH   HHH  ", "   HHHHHHH         HHHHHHH   ", "    HHHHH           HHHHH    ", "                             ", "                             ", "                             ", "                             ")
            .aisle("AEEEEEEEEEEEE E EEEEEEEEEEEEA", "AAAAAAAAAAAAECCCEAAAAAAAAAAAA", "AAAA     AAAEC CEAAA     AAAA", " AAAAAAAAAAAEC CEAAAAAAAAAAA ", " AAABBBBBAAAEC CEAAABBBBBAAA ", "  AAA   AAA EC CE AAA   AAA  ", "            ECFCE            ", "     HHH             HHH     ", "    HHHHH           HHHHH    ", "   HH   HH         HH   HH   ", "   HH   HH    J    HH   HH   ", "   HH   HH         HH   HH   ", "   HH   HH         HH   HH   ", "   HH   HH         HH   HH   ", "   KK   KK         KK   KK   ", "   HH   HH         HH   HH   ", "   HH   HH         HH   HH   ", "   HH   HH         HH   HH   ", "   HH   HH         HH   HH   ", "   HHHHHHH         HHHHHHH   ", "    HHHHH           HHHHH    ", "                             ", "                             ", "                             ", "                             ", "                             ")
            .aisle(" EEEEEEEEEEEE E EEEEEEEEEEEE ", " AAAAAAAAAAAECCCEAAAAAAAAAAA ", "  GABBBBBAG EC CE GABBBBBAG  ", "  GAHHHHHAG EC CE GAHHHHHAG  ", "  GA     AG EC CE GA     AG  ", "  GAAAAAAAG  C C  GAAAAAAAG  ", "  G       G  CFC  G       G  ", "  I       I   J   I       I  ", "     HHH      J      HHH     ", "    HHHHH     J     HHHHH    ", "    HHHHH     J     HHHHH    ", "    HHHHH           HHHHH    ", "    HHHHH           HHHHH    ", "    HHHHH           HHHHH    ", "    KKKKK           KKKKK    ", "    HHHHH           HHHHH    ", "    HHHHH           HHHHH    ", "    HHHHH           HHHHH    ", "    HHHHH           HHHHH    ", "    HHHHH           HHHHH    ", "                             ", "                             ", "                             ", "                             ", "                             ", "                             ")
            .aisle(" EEEEEEEEEEEEEEEEEEEEEEEEEEE ", "  AAAAAAAAAEECCCEEAAAAAAAAA  ", "   A     A EEC CEE A     A   ", "   AAAAAAA   C C   AAAAAAA   ", "   A     A   C C   A     A   ", "             C C             ", "             CFC             ", "                             ", "                             ", "                             ", "                             ", "                             ", "                             ", "                             ", "                             ", "                             ", "                             ", "                             ", "                             ", "                             ", "                             ", "                             ", "                             ", "                             ", "                             ", "                             ")
            .aisle("   ABBBBBA   CCC   ABBBBBA   ", "   AAAAAAA   CCC   AAAAAAA   ", "   A     A   CDC   A     A   ", "             CDC             ", "             CDC             ", "             CCC             ", "             CCC             ", "                             ", "                             ", "                             ", "                             ", "                             ", "                             ", "                             ", "                             ", "                             ", "                             ", "                             ", "                             ", "                             ", "                             ", "                             ", "                             ", "                             ", "                             ", "                             ")
            .aisle("             CCC             ", "             C~C             ", "                             ", "                             ", "                             ", "                             ", "                             ", "                             ", "                             ", "                             ", "                             ", "                             ", "                             ", "                             ", "                             ", "                             ", "                             ", "                             ", "                             ", "                             ", "                             ", "                             ", "                             ", "                             ", "                             ", "                             ");

    public static final FactoryBlockPattern HUGE_INCUBATOR_2 = FactoryBlockPattern.start()
            .aisle("       AAAAAAA       ", "       AAAAAAA       ", "       A     A       ", "       A     A       ", "       A     A       ", "       A     A       ", "       A     A       ", "       A     A       ", "       A     A       ", "       A     A       ", "       A     A       ", "       A     A       ", "       A     A       ", "       A     A       ", "       A     A       ", "       A     A       ", "       A     A       ", "       A     A       ", "       A     A       ", "       A     A       ", "       A     A       ", "       A     A       ", "       A     A       ", "       A     A       ", "       A     A       ", "       A     A       ", "       A     A       ", "       A     A       ", "       A     A       ", "       A     A       ", "       A     A       ", "       A     A       ", "       A     A       ", "       A     A       ", "       A     A       ", "       A     A       ", "       A     A       ", "       A     A       ", "       AAAAAAA       ", "       AAAAAAA       ")
            .aisle("     AABBBBBBBAA     ", "     AA   C   AA     ", "         C           ", "        C            ", "                     ", "                     ", "                     ", "                     ", "                     ", "                     ", "                     ", "                     ", "                     ", "                     ", "            D        ", "           D         ", "          D          ", "         D           ", "        D            ", "                     ", "                     ", "            C        ", "           C         ", "          C          ", "         C           ", "        C            ", "                     ", "                     ", "                     ", "                     ", "                     ", "                     ", "                     ", "                     ", "                     ", "                     ", "            D        ", "           D         ", "     AA   D   AA     ", "     AABBBBBBBAA     ")
            .aisle("   AABBBEEEEEBBBAA   ", "   AA   FFFFF   AA   ", "        FFFFF        ", "        FFFFF        ", "       CFFFFF        ", "      C FFFFF        ", "        FFFFF        ", "        FFFFF        ", "        FFFFF        ", "        FFFFF        ", "        FFFFF        ", "        FFFFF        ", "        FFFFF D      ", "        FFFFFD       ", "        FFFFF        ", "        FFFFF        ", "        FFFFF        ", "        FFFFF        ", "        FFFFF        ", "       DFFFFF C      ", "      D FFFFFC       ", "        FFFFF        ", "        FFFFF        ", "        FFFFF        ", "        FFFFF        ", "        FFFFF        ", "       CFFFFF        ", "      C FFFFF        ", "        FFFFF        ", "        FFFFF        ", "        FFFFF        ", "        FFFFF        ", "        FFFFF        ", "        FFFFF        ", "        FFFFF D      ", "        FFFFFD       ", "        FFFFF        ", "        FFFFF        ", "   AA   FFFFF   AA   ", "   AABBBEEEEEBBBAA   ")
            .aisle(" AABBBEEEEEEEEEBBBAA ", " AA   FFFGFGFFF   AA ", "      FFFGFGFFF      ", "      FFFGFGFFF      ", "      FFFGFGFFF      ", "      FFFGFGFFF      ", "     CFFFGFGFFF      ", "    C FFFGFGFFF      ", "      FFFGFGFFF      ", "      FFFGFGFFF      ", "      FFFGFGFFF D    ", "      FFFGFGFFFD     ", "      FFFGFGFFF      ", "      FFFGFGFFF      ", "      FFFGFGFFF      ", "      FFFGFGFFF      ", "      FFFGFGFFF      ", "      FFFGFGFFF C    ", "      FFFGFGFFFC     ", "      FFFGFGFFF      ", "      FFFGFGFFF      ", "     DFFFGFGFFF      ", "    D FFFGFGFFF      ", "      FFFGFGFFF      ", "      FFFGFGFFF      ", "      FFFGFGFFF      ", "      FFFGFGFFF      ", "      FFFGFGFFF      ", "     CFFFGFGFFF      ", "    C FFFGFGFFF      ", "      FFFGFGFFF      ", "      FFFGFGFFF      ", "      FFFGFGFFF D    ", "      FFFGFGFFFD     ", "      FFFGFGFFF      ", "      FFFGFGFFF      ", "      FFFGFGFFF      ", "      FFFGFGFFF      ", " AA   FFFGFGFFF   AA ", " AABBBEEEEEEEEEBBBAA ")
            .aisle("ABBBEEEEEEEEEEEEEBBBA", "A  DFFFGFFFFFGFFF   A", "A D FFFGFFFFFGFFF   A", "A   FFFGFFFFFGFFF   A", "A   FFFGFFFFFGFFF   A", "A   FFFGFFFFFGFFF   A", "A   FFFGFFFFFGFFF   A", "A   FFFGFFFFFGFFF   A", "A  CFFFGFFFFFGFFF D A", "A C FFFGFFFFFGFFFD  A", "A   FFFGFFFFFGFFF   A", "A   FFFGFFFFFGFFF   A", "A   FFFGFFFFFGFFF   A", "A   FFFGFFFFFGFFF   A", "A   FFFGFFFFFGFFF   A", "A   FFFGFFFFFGFFF C A", "A   FFFGFFFFFGFFFC  A", "A   FFFGFFFFFGFFF   A", "A   FFFGFFFFFGFFF   A", "A   FFFGFFFFFGFFF   A", "A   FFFGFFFFFGFFF   A", "A   FFFGFFFFFGFFF   A", "A   FFFGFFFFFGFFF   A", "A  DFFFGFFFFFGFFF   A", "A D FFFGFFFFFGFFF   A", "A   FFFGFFFFFGFFF   A", "A   FFFGFFFFFGFFF   A", "A   FFFGFFFFFGFFF   A", "A   FFFGFFFFFGFFF   A", "A   FFFGFFFFFGFFF   A", "A  CFFFGFFFFFGFFF D A", "A C FFFGFFFFFGFFFD  A", "A   FFFGFFFFFGFFF   A", "A   FFFGFFFFFGFFF   A", "A   FFFGFFFFFGFFF   A", "A   FFFGFFFFFGFFF   A", "A   FFFGFFFFFGFFF   A", "A   FFFGFFFFFGFFF C A", "A   FFFGFFFFFGFFFC  A", "ABBBEEEEEEEEEEEEEBBBA")
            .aisle("HBEEEEEEEEEEEEEEEEEBH", "H FFFGFFIIIIIFFGFFF H", "  FFFGFFIIIIIFFGFFF  ", " DFFFGFFIIIIIFFGFFF  ", "  FFFGFFIIIIIFFGFFF  ", "  FFFGFFIIIIIFFGFFF  ", "  FFFGFFIIIIIFFGFFF  ", "  FFFGFFIIIIIFFGFFFD ", "  FFFGFFIIIIIFFGFFF  ", "  FFFGFFIIIIIFFGFFF  ", " CFFFGFFIIIIIFFGFFF  ", "  FFFGFFIIIIIFFGFFF  ", "  FFFGFFIIIIIFFGFFF  ", "  FFFGFFIIIIIFFGFFF  ", "  FFFGFFIIIIIFFGFFFC ", "  FFFGFFIIIIIFFGFFF  ", "  FFFGFFIIIIIFFGFFF  ", "  FFFGFFIIIIIFFGFFF  ", "  FFFGFFIIIIIFFGFFF  ", "  FFFGFFIIIIIFFGFFF  ", "  FFFGFFIIIIIFFGFFF  ", "  FFFGFFIIIIIFFGFFF  ", "  FFFGFFIIIIIFFGFFF  ", "  FFFGFFIIIIIFFGFFF  ", "  FFFGFFIIIIIFFGFFF  ", " DFFFGFFIIIIIFFGFFF  ", "  FFFGFFIIIIIFFGFFF  ", "  FFFGFFIIIIIFFGFFF  ", "  FFFGFFIIIIIFFGFFF  ", "  FFFGFFIIIIIFFGFFFD ", "  FFFGFFIIIIIFFGFFF  ", "  FFFGFFIIIIIFFGFFF  ", " CFFFGFFIIIIIFFGFFF  ", "  FFFGFFIIIIIFFGFFF  ", "  FFFGFFIIIIIFFGFFF  ", "  FFFGFFIIIIIFFGFFF  ", "  FFFGFFIIIIIFFGFFFC ", "  FFFGFFIIIIIFFGFFF  ", "A FFFGFFIIIIIFFGFFF A", "ABEEEEEEEEEEEEEEEEEBA")
            .aisle("HBEEEEEEEEEEEEEEEEEBH", "H FGFFFGIJIJIGFFFGF H", "  FGFFFGIJIJIGFFFGF  ", "  FGFFFGIJIJIGFFFGF  ", " DFGFFFGIJIJIGFFFGF  ", "  FGFFFGIJIJIGFFFGF  ", "  FGFFFGIJIJIGFFFGFD ", "  FGFFFGIJIJIGFFFGF  ", "  FGFFFGIJIJIGFFFGF  ", "  FGFFFGIJIJIGFFFGF  ", "  FGFFFGIJIJIGFFFGF  ", " CFGFFFGIJIJIGFFFGF  ", "  FGFFFGIJIJIGFFFGF  ", "  FGFFFGIJIJIGFFFGFC ", "  FGFFFGIJIJIGFFFGF  ", "  FGFFFGIJIJIGFFFGF  ", "  FGFFFGIJIJIGFFFGF  ", "  FGFFFGIJIJIGFFFGF  ", "  FGFFFGIJIJIGFFFGF  ", "  FGFFFGIJIJIGFFFGF  ", "  FGFFFGIJIJIGFFFGF  ", "  FGFFFGIJIJIGFFFGF  ", "  FGFFFGIJIJIGFFFGF  ", "  FGFFFGIJIJIGFFFGF  ", "  FGFFFGIJIJIGFFFGF  ", "  FGFFFGIJIJIGFFFGF  ", " DFGFFFGIJIJIGFFFGF  ", "  FGFFFGIJIJIGFFFGF  ", "  FGFFFGIJIJIGFFFGFD ", "  FGFFFGIJIJIGFFFGF  ", "  FGFFFGIJIJIGFFFGF  ", "  FGFFFGIJIJIGFFFGF  ", "  FGFFFGIJIJIGFFFGF  ", " CFGFFFGIJIJIGFFFGF  ", "  FGFFFGIJIJIGFFFGF  ", "  FGFFFGIJIJIGFFFGFC ", "  FGFFFGIJIJIGFFFGF  ", "  FGFFFGIJIJIGFFFGF  ", "A FGFFFGIJIJIGFFFGF A", "ABEEEEEEEEEEEEEEEEEBA")
            .aisle("HBEEEEEEEEEEEEEEEEEBH", "H FFFGFFIIIIIFFGFFF H", "  FFFGFFIIIIIFFGFFF  ", "  FFFGFFIIIIIFFGFFF  ", "  FFFGFFIIIIIFFGFFF  ", " DFFFGFFIIIIIFFGFFFD ", "  FFFGFFIIIIIFFGFFF  ", "  FFFGFFIIIIIFFGFFF  ", "  FFFGFFIIIIIFFGFFF  ", "  FFFGFFIIIIIFFGFFF  ", "  FFFGFFIIIIIFFGFFF  ", "  FFFGFFIIIIIFFGFFF  ", " CFFFGFFIIIIIFFGFFFC ", "  FFFGFFIIIIIFFGFFF  ", "  FFFGFFIIIIIFFGFFF  ", "  FFFGFFIIIIIFFGFFF  ", "  FFFGFFIIIIIFFGFFF  ", "  FFFGFFIIIIIFFGFFF  ", "  FFFGFFIIIIIFFGFFF  ", "  FFFGFFIIIIIFFGFFF  ", "  FFFGFFIIIIIFFGFFF  ", "  FFFGFFIIIIIFFGFFF  ", "  FFFGFFIIIIIFFGFFF  ", "  FFFGFFIIIIIFFGFFF  ", "  FFFGFFIIIIIFFGFFF  ", "  FFFGFFIIIIIFFGFFF  ", "  FFFGFFIIIIIFFGFFF  ", " DFFFGFFIIIIIFFGFFFD ", "  FFFGFFIIIIIFFGFFF  ", "  FFFGFFIIIIIFFGFFF  ", "  FFFGFFIIIIIFFGFFF  ", "  FFFGFFIIIIIFFGFFF  ", "  FFFGFFIIIIIFFGFFF  ", "  FFFGFFIIIIIFFGFFF  ", " CFFFGFFIIIIIFFGFFFC ", "  FFFGFFIIIIIFFGFFF  ", "  FFFGFFIIIIIFFGFFF  ", "  FFFGFFIIIIIFFGFFF  ", "A FFFGFFIIIIIFFGFFF A", "ABEEEEEEEEEEEEEEEEEBA")
            .aisle("HBEEEEEEEEEEEEEEEEEBH", "H FGFFFGIJIJIGFFFGF H", "  FGFFFGIJIJIGFFFGF  ", "  FGFFFGIJIJIGFFFGF  ", "  FGFFFGIJIJIGFFFGFD ", "  FGFFFGIJIJIGFFFGF  ", " DFGFFFGIJIJIGFFFGF  ", "  FGFFFGIJIJIGFFFGF  ", "  FGFFFGIJIJIGFFFGF  ", "  FGFFFGIJIJIGFFFGF  ", "  FGFFFGIJIJIGFFFGF  ", "  FGFFFGIJIJIGFFFGFC ", "  FGFFFGIJIJIGFFFGF  ", " CFGFFFGIJIJIGFFFGF  ", "  FGFFFGIJIJIGFFFGF  ", "  FGFFFGIJIJIGFFFGF  ", "  FGFFFGIJIJIGFFFGF  ", "  FGFFFGIJIJIGFFFGF  ", "  FGFFFGIJIJIGFFFGF  ", "  FGFFFGIJIJIGFFFGF  ", "  FGFFFGIJIJIGFFFGF  ", "  FGFFFGIJIJIGFFFGF  ", "  FGFFFGIJIJIGFFFGF  ", "  FGFFFGIJIJIGFFFGF  ", "  FGFFFGIJIJIGFFFGF  ", "  FGFFFGIJIJIGFFFGF  ", "  FGFFFGIJIJIGFFFGFD ", "  FGFFFGIJIJIGFFFGF  ", " DFGFFFGIJIJIGFFFGF  ", "  FGFFFGIJIJIGFFFGF  ", "  FGFFFGIJIJIGFFFGF  ", "  FGFFFGIJIJIGFFFGF  ", "  FGFFFGIJIJIGFFFGF  ", "  FGFFFGIJIJIGFFFGFC ", "  FGFFFGIJIJIGFFFGF  ", " CFGFFFGIJIJIGFFFGF  ", "  FGFFFGIJIJIGFFFGF  ", "  FGFFFGIJIJIGFFFGF  ", "A FGFFFGIJIJIGFFFGF A", "ABEEEEEEEEEEEEEEEEEBA")
            .aisle("HBEEEEEEEEEEEEEEEEEBH", "H FFFGFFIIIIIFFGFFF H", "  FFFGFFIIIIIFFGFFF  ", "  FFFGFFIIIIIFFGFFFD ", "  FFFGFFIIIIIFFGFFF  ", "  FFFGFFIIIIIFFGFFF  ", "  FFFGFFIIIIIFFGFFF  ", " DFFFGFFIIIIIFFGFFF  ", "  FFFGFFIIIIIFFGFFF  ", "  FFFGFFIIIIIFFGFFF  ", "  FFFGFFIIIIIFFGFFFC ", "  FFFGFFIIIIIFFGFFF  ", "  FFFGFFIIIIIFFGFFF  ", "  FFFGFFIIIIIFFGFFF  ", " CFFFGFFIIIIIFFGFFF  ", "  FFFGFFIIIIIFFGFFF  ", "  FFFGFFIIIIIFFGFFF  ", "  FFFGFFIIIIIFFGFFF  ", "  FFFGFFIIIIIFFGFFF  ", "  FFFGFFIIIIIFFGFFF  ", "  FFFGFFIIIIIFFGFFF  ", "  FFFGFFIIIIIFFGFFF  ", "  FFFGFFIIIIIFFGFFF  ", "  FFFGFFIIIIIFFGFFF  ", "  FFFGFFIIIIIFFGFFF  ", "  FFFGFFIIIIIFFGFFFD ", "  FFFGFFIIIIIFFGFFF  ", "  FFFGFFIIIIIFFGFFF  ", "  FFFGFFIIIIIFFGFFF  ", " DFFFGFFIIIIIFFGFFF  ", "  FFFGFFIIIIIFFGFFF  ", "  FFFGFFIIIIIFFGFFF  ", "  FFFGFFIIIIIFFGFFFC ", "  FFFGFFIIIIIFFGFFF  ", "  FFFGFFIIIIIFFGFFF  ", "  FFFGFFIIIIIFFGFFF  ", " CFFFGFFIIIIIFFGFFF  ", "  FFFGFFIIIIIFFGFFF  ", "A FFFGFFIIIIIFFGFFF A", "ABEEEEEEEEEEEEEEEEEBA")
            .aisle("ABBBEEEEEEEEEEEEEBBBA", "A   FFFGFFFFFGFFFD  A", "A   FFFGFFFFFGFFF D A", "A   FFFGFFFFFGFFF   A", "A   FFFGFFFFFGFFF   A", "A   FFFGFFFFFGFFF   A", "A   FFFGFFFFFGFFF   A", "A   FFFGFFFFFGFFF   A", "A D FFFGFFFFFGFFFC  A", "A  DFFFGFFFFFGFFF C A", "A   FFFGFFFFFGFFF   A", "A   FFFGFFFFFGFFF   A", "A   FFFGFFFFFGFFF   A", "A   FFFGFFFFFGFFF   A", "A   FFFGFFFFFGFFF   A", "A C FFFGFFFFFGFFF   A", "A  CFFFGFFFFFGFFF   A", "A   FFFGFFFFFGFFF   A", "A   FFFGFFFFFGFFF   A", "A   FFFGFFFFFGFFF   A", "A   FFFGFFFFFGFFF   A", "A   FFFGFFFFFGFFF   A", "A   FFFGFFFFFGFFF   A", "A   FFFGFFFFFGFFFD  A", "A   FFFGFFFFFGFFF D A", "A   FFFGFFFFFGFFF   A", "A   FFFGFFFFFGFFF   A", "A   FFFGFFFFFGFFF   A", "A   FFFGFFFFFGFFF   A", "A   FFFGFFFFFGFFF   A", "A D FFFGFFFFFGFFFC  A", "A  DFFFGFFFFFGFFF C A", "A   FFFGFFFFFGFFF   A", "A   FFFGFFFFFGFFF   A", "A   FFFGFFFFFGFFF   A", "A   FFFGFFFFFGFFF   A", "A   FFFGFFFFFGFFF   A", "A C FFFGFFFFFGFFF   A", "A  CFFFGFFFFFGFFF   A", "ABBBEEEEEEEEEEEEEBBBA")
            .aisle(" AABBBEEEEEEEEEBBBAA ", " AA   FFFGFGFFF   AA ", "      FFFGFGFFF      ", "      FFFGFGFFF      ", "      FFFGFGFFF      ", "      FFFGFGFFF      ", "      FFFGFGFFFC     ", "      FFFGFGFFF C    ", "      FFFGFGFFF      ", "      FFFGFGFFF      ", "    D FFFGFGFFF      ", "     DFFFGFGFFF      ", "      FFFGFGFFF      ", "      FFFGFGFFF      ", "      FFFGFGFFF      ", "      FFFGFGFFF      ", "      FFFGFGFFF      ", "    C FFFGFGFFF      ", "     CFFFGFGFFF      ", "      FFFGFGFFF      ", "      FFFGFGFFF      ", "      FFFGFGFFFD     ", "      FFFGFGFFF D    ", "      FFFGFGFFF      ", "      FFFGFGFFF      ", "      FFFGFGFFF      ", "      FFFGFGFFF      ", "      FFFGFGFFF      ", "      FFFGFGFFFC     ", "      FFFGFGFFF C    ", "      FFFGFGFFF      ", "      FFFGFGFFF      ", "    D FFFGFGFFF      ", "     DFFFGFGFFF      ", "      FFFGFGFFF      ", "      FFFGFGFFF      ", "      FFFGFGFFF      ", "      FFFGFGFFF      ", " AA   FFFGFGFFF   AA ", " AABBBEEEEEEEEEBBBAA ")
            .aisle("   AABBBEEEEEBBBAA   ", "   AA   FFFFF   AA   ", "        FFFFF        ", "        FFFFF        ", "        FFFFFC       ", "        FFFFF C      ", "        FFFFF        ", "        FFFFF        ", "        FFFFF        ", "        FFFFF        ", "        FFFFF        ", "        FFFFF        ", "      D FFFFF        ", "       DFFFFF        ", "        FFFFF        ", "        FFFFF        ", "        FFFFF        ", "        FFFFF        ", "        FFFFF        ", "      C FFFFFD       ", "       CFFFFF D      ", "        FFFFF        ", "        FFFFF        ", "        FFFFF        ", "        FFFFF        ", "        FFFFF        ", "        FFFFFC       ", "        FFFFF C      ", "        FFFFF        ", "        FFFFF        ", "        FFFFF        ", "        FFFFF        ", "        FFFFF        ", "        FFFFF        ", "      D FFFFF        ", "       DFFFFF        ", "        FFFFF        ", "        FFFFF        ", "   AA   FFFFF   AA   ", "   AABBBEEEEEBBBAA   ")
            .aisle("     AABBBBBBBAA     ", "     AA   C   AA     ", "           C         ", "            C        ", "                     ", "                     ", "                     ", "                     ", "                     ", "                     ", "                     ", "                     ", "                     ", "                     ", "        D            ", "         D           ", "          D          ", "           D         ", "            D        ", "                     ", "                     ", "        C            ", "         C           ", "          C          ", "           C         ", "            C        ", "                     ", "                     ", "                     ", "                     ", "                     ", "                     ", "                     ", "                     ", "                     ", "                     ", "        D            ", "         D           ", "     AA   D   AA     ", "     AABBBBBBBAA     ")
            .aisle("       AHHHHHA       ", "       AHHKHHA       ", "       A     A       ", "       A     A       ", "       A     A       ", "       A     A       ", "       A     A       ", "       A     A       ", "       A     A       ", "       A     A       ", "       A     A       ", "       A     A       ", "       A     A       ", "       A     A       ", "       A     A       ", "       A     A       ", "       A     A       ", "       A     A       ", "       A     A       ", "       A     A       ", "       A     A       ", "       A     A       ", "       A     A       ", "       A     A       ", "       A     A       ", "       A     A       ", "       A     A       ", "       A     A       ", "       A     A       ", "       A     A       ", "       A     A       ", "       A     A       ", "       A     A       ", "       A     A       ", "       A     A       ", "       A     A       ", "       A     A       ", "       A     A       ", "       AAAAAAA       ", "       AAAAAAA       ");

    public static final FactoryBlockPattern MOLECULAR_ASSEMBLER_MATRIX = FactoryBlockPattern.start()
            .aisle("                                     ", "                                     ", "                                     ", "                                     ", "                                     ", "                                     ", "                                     ", "                  A                  ", "                  B                  ", "                  B                  ", "                  B                  ", "                  A                  ", "                                     ", "                                     ", "                                     ", "                                     ", "                                     ", "                                     ", "                                     ")
            .aisle("                                     ", "                                     ", "                                     ", "                                     ", "                                     ", "                  A                  ", "                  A                  ", "                 ACA                 ", "                 DED                 ", "              DDDDEDDDD              ", "                 DED                 ", "                 ACA                 ", "                  A                  ", "                  A                  ", "                                     ", "                                     ", "                                     ", "                                     ", "                                     ")
            .aisle("                                     ", "                                     ", "                                     ", "                                     ", "                                     ", "                                     ", "                                     ", "                  A                  ", "              AAAAAAAAA              ", "           DDDFFFFFFFFFDDD           ", "              AAAAAAAAA              ", "                  A                  ", "                                     ", "                                     ", "                                     ", "                                     ", "                                     ", "                                     ", "                                     ")
            .aisle("                                     ", "                                     ", "                                     ", "                                     ", "                                     ", "                                     ", "                                     ", "                                     ", "           AAAA       AAAA           ", "         DDFFFGHHHHHHHGFFFDD         ", "           AAAA       AAAA           ", "                                     ", "                                     ", "                                     ", "                                     ", "                                     ", "                                     ", "                                     ", "                                     ")
            .aisle("                                     ", "                                     ", "                                     ", "                                     ", "                                     ", "                                     ", "                                     ", "                                     ", "         AAA             AAA         ", "        DFFGHHH       HHHGFFD        ", "         AAA             AAA         ", "                                     ", "                                     ", "                                     ", "                                     ", "                                     ", "                                     ", "                                     ", "                                     ")
            .aisle("                                     ", "                                     ", "                                     ", "                                     ", "                                     ", "                                     ", "                                     ", "      I                       I      ", "      BAAA                 AAAB      ", "      BDFGHH             HHGFDB      ", "      BAAA                 AAAB      ", "      I                       I      ", "                                     ", "                                     ", "                                     ", "                                     ", "                                     ", "                                     ", "                                     ")
            .aisle("                                     ", "                                     ", "                                     ", "                                     ", "      G                       G      ", "      J                       J      ", "      J                       J      ", "     ICI                     ICI     ", "     BEAA                   AAEB     ", "     BEFGH                 HGFEB     ", "     BEAA                   AAEB     ", "     ICI                     ICI     ", "      J                       J      ", "      J                       J      ", "      G                       G      ", "                                     ", "                                     ", "                                     ", "                                     ")
            .aisle("                                     ", "                                     ", "                                     ", "                                     ", "                                     ", "                                     ", "                                     ", "      I       KLL   LLK       I      ", "     AAA                     AAA     ", "     DFGH                   HGFD     ", "     AAA                     AAA     ", "      I       KLL   LLK       I      ", "                                     ", "                                     ", "                                     ", "                                     ", "                                     ", "                                     ", "                                     ")
            .aisle("                                     ", "                                     ", "                                     ", "                                     ", "                                     ", "                                     ", "                                     ", "               K     K               ", "     AA      LL       LL      AA     ", "    DFGH    K           K    HGFD    ", "     AA      LL       LL      AA     ", "               K     K               ", "                                     ", "                                     ", "                                     ", "                                     ", "                                     ", "                                     ", "                                     ")
            .aisle("                                     ", "                                     ", "                                     ", "                                     ", "                                     ", "                                     ", "                                     ", "                                     ", "    AA    D               D    AA    ", "   DFGH   KLLK         KLLK   HGFD   ", "    AA    D               D    AA    ", "                                     ", "                                     ", "                                     ", "                                     ", "                                     ", "                                     ", "                                     ", "                                     ")
            .aisle("                                     ", "                                     ", "                                     ", "                                     ", "                                     ", "                                     ", "          D               D          ", "          D               D          ", "    A    DFD             DFD    A    ", "   DFH   KFG             GFK   HFD   ", "    A    DFD             DFD    A    ", "          D               D          ", "          D               D          ", "                                     ", "                                     ", "                                     ", "                                     ", "                                     ", "                                     ")
            .aisle("                                     ", "                                     ", "                                     ", "                                     ", "                                     ", "                                     ", "                                     ", "                                     ", "   AA     D               D     AA   ", "  DFGH   LG               GL   HGFD  ", "   AA     D               D     AA   ", "                                     ", "                                     ", "                                     ", "                                     ", "                                     ", "                                     ", "                                     ", "                                     ")
            .aisle("                                     ", "                                     ", "                                     ", "                                     ", "                                     ", "                                     ", "                                     ", "                                     ", "   A                             A   ", "  DFH   KL                 LK   HFD  ", "   A                             A   ", "                                     ", "                                     ", "                                     ", "                                     ", "                                     ", "                                     ", "                                     ", "                                     ")
            .aisle("                                     ", "                                     ", "                                     ", "                                     ", "                                     ", "                                     ", "                                     ", "                                     ", "   A    L                   L    A   ", "  DFH    K                 K    HFD  ", "   A    L                   L    A   ", "                                     ", "                                     ", "                                     ", "                                     ", "                                     ", "                                     ", "                                     ", "                                     ")
            .aisle("                                     ", "                                     ", "                                     ", "                                     ", "                                     ", "              D       D              ", "               D     D               ", "       K      M   N   M      K       ", "  AA    L        ENE        L    AA  ", " DFGH           NNNNN           HGFD ", "  AA    L        ENE        L    AA  ", "       K      M   N   M      K       ", "               D     D               ", "              D       D              ", "                                     ", "                                     ", "                                     ", "                                     ", "                                     ")
            .aisle("                                     ", "                                     ", "                                     ", "                                     ", "                                     ", "               D     D               ", "              DDDNNNDDD              ", "       LK      DGDDDGD      KL       ", "  A            MDCCCDM            A  ", " DFH           MDCCCDM           HFD ", "  A            MDCCCDM            A  ", "       LK      DGDDDGD      KL       ", "              DDDNNNDDD              ", "               D     D               ", "                                     ", "                                     ", "                                     ", "                                     ", "                                     ")
            .aisle("                                     ", "                                     ", "                                     ", "                                     ", "                                     ", "                  O                  ", "               DGDDDGD               ", "       L       GDPPPDG       L       ", "  A            DPQQQPD            A  ", " DFH          NDPQQQPDN          HFD ", "  A            DPQQQPD            A  ", "       L       GDPPPDG       L       ", "               DGDDDGD               ", "                  O                  ", "                                     ", "                                     ", "                                     ", "                                     ", "                                     ")
            .aisle("                                     ", "                                     ", "                                     ", "                  O                  ", "                  O                  ", "                 EOE                 ", "               NDCCCDN               ", " A             DPQQQPD             A ", " DA           ECQQQQQCE           AD ", " DFH          NCQQQQQCN          HFD ", " DA           ECQQQQQCE           AD ", " A             DPQQQPD             A ", "               NDCCCDN               ", "                 EOE                 ", "                  O                  ", "                  O                  ", "                                     ", "                                     ", "                                     ")
            .aisle("                  G                  ", "                  D                  ", "                  D                  ", "                 ODO                 ", "                 ODO                 ", " A              OODOO              A ", " A             NDCCCDN             A ", "ACA           NDPQQQPDN           ACA", "BEA           NCQQQQQCN           AEB", "BEFH          NCQQQQQCN          HFEB", "BEA           NCQQQQQCN           AEB", "ACA           NDPQQQPDN           ACA", " A             NDCCCDN             A ", " A              OODOO              A ", "                 ODO                 ", "                 ODO                 ", "                  D                  ", "                  D                  ", "                  G                  ")
            .aisle("                                     ", "                                     ", "                                     ", "                  O                  ", "                  O                  ", "                 EOE                 ", "               NDCCCDN               ", " A             DPQQQPD             A ", " DA           ECQQQQQCE           AD ", " DFH          NCQQQQQCN          HFD ", " DA           ECQQQQQCE           AD ", " A             DPQQQPD             A ", "               NDCCCDN               ", "                 EOE                 ", "                  O                  ", "                  O                  ", "                                     ", "                                     ", "                                     ")
            .aisle("                                     ", "                                     ", "                                     ", "                                     ", "                                     ", "                  O                  ", "               DGDDDGD               ", "       L       GDPPPDG       L       ", "  A            DPQQQPD            A  ", " DFH          NDPQQQPDN          HFD ", "  A            DPQQQPD            A  ", "       L       GDPPPDG       L       ", "               DGDDDGD               ", "                  O                  ", "                                     ", "                                     ", "                                     ", "                                     ", "                                     ")
            .aisle("                                     ", "                                     ", "                                     ", "                                     ", "                                     ", "               D     D               ", "              DDDNNNDDD              ", "       LK      DGDDDGD      KL       ", "  A            MDCCCDM            A  ", " DFH           MDCCCDM           HFD ", "  A            MDCCCDM            A  ", "       LK      DGDDDGD      KL       ", "              DDDNNNDDD              ", "               D     D               ", "                                     ", "                                     ", "                                     ", "                                     ", "                                     ")
            .aisle("                                     ", "                                     ", "                                     ", "                                     ", "                                     ", "              D       D              ", "               D     D               ", "       K      M   N   M      K       ", "  AA    L        ENE        L    AA  ", " DFGH           NNRNN           HGFD ", "  AA    L        ENE        L    AA  ", "       K      M   N   M      K       ", "               D     D               ", "              D       D              ", "                                     ", "                                     ", "                                     ", "                                     ", "                                     ")
            .aisle("                                     ", "                                     ", "                                     ", "                                     ", "                                     ", "                                     ", "                                     ", "                                     ", "   A    L                   L    A   ", "  DFH    K                 K    HFD  ", "   A    L                   L    A   ", "                                     ", "                                     ", "                                     ", "                                     ", "                                     ", "                                     ", "                                     ", "                                     ")
            .aisle("                                     ", "                                     ", "                                     ", "                                     ", "                                     ", "                                     ", "                                     ", "                                     ", "   A                             A   ", "  DFH   KL                 LK   HFD  ", "   A                             A   ", "                                     ", "                                     ", "                                     ", "                                     ", "                                     ", "                                     ", "                                     ", "                                     ")
            .aisle("                                     ", "                                     ", "                                     ", "                                     ", "                                     ", "                                     ", "                                     ", "                                     ", "   AA     D               D     AA   ", "  DFGH   LG               GL   HGFD  ", "   AA     D               D     AA   ", "                                     ", "                                     ", "                                     ", "                                     ", "                                     ", "                                     ", "                                     ", "                                     ")
            .aisle("                                     ", "                                     ", "                                     ", "                                     ", "                                     ", "                                     ", "          D               D          ", "          D               D          ", "    A    DFD             DFD    A    ", "   DFH   KFG             GFK   HFD   ", "    A    DFD             DFD    A    ", "          D               D          ", "          D               D          ", "                                     ", "                                     ", "                                     ", "                                     ", "                                     ", "                                     ")
            .aisle("                                     ", "                                     ", "                                     ", "                                     ", "                                     ", "                                     ", "                                     ", "                                     ", "    AA    D               D    AA    ", "   DFGH   KLLK         KLLK   HGFD   ", "    AA    D               D    AA    ", "                                     ", "                                     ", "                                     ", "                                     ", "                                     ", "                                     ", "                                     ", "                                     ")
            .aisle("                                     ", "                                     ", "                                     ", "                                     ", "                                     ", "                                     ", "                                     ", "               K     K               ", "     AA      LL       LL      AA     ", "    DFGH    K           K    HGFD    ", "     AA      LL       LL      AA     ", "               K     K               ", "                                     ", "                                     ", "                                     ", "                                     ", "                                     ", "                                     ", "                                     ")
            .aisle("                                     ", "                                     ", "                                     ", "                                     ", "                                     ", "                                     ", "                                     ", "      I       KLL   LLK       I      ", "     AAA                     AAA     ", "     DFGH                   HGFD     ", "     AAA                     AAA     ", "      I       KLL   LLK       I      ", "                                     ", "                                     ", "                                     ", "                                     ", "                                     ", "                                     ", "                                     ")
            .aisle("                                     ", "                                     ", "                                     ", "                                     ", "      G                       G      ", "      J                       J      ", "      J                       J      ", "     ICI                     ICI     ", "     BEAA                   AAEB     ", "     BEFGH                 HGFEB     ", "     BEAA                   AAEB     ", "     ICI                     ICI     ", "      J                       J      ", "      J                       J      ", "      G                       G      ", "                                     ", "                                     ", "                                     ", "                                     ")
            .aisle("                                     ", "                                     ", "                                     ", "                                     ", "                                     ", "                                     ", "                                     ", "      I                       I      ", "      BAAA                 AAAB      ", "      BDFGHH             HHGFDB      ", "      BAAA                 AAAB      ", "      I                       I      ", "                                     ", "                                     ", "                                     ", "                                     ", "                                     ", "                                     ", "                                     ")
            .aisle("                                     ", "                                     ", "                                     ", "                                     ", "                                     ", "                                     ", "                                     ", "                                     ", "         AAA             AAA         ", "        DFFGHHH       HHHGFFD        ", "         AAA             AAA         ", "                                     ", "                                     ", "                                     ", "                                     ", "                                     ", "                                     ", "                                     ", "                                     ")
            .aisle("                                     ", "                                     ", "                                     ", "                                     ", "                                     ", "                                     ", "                                     ", "                                     ", "           AAAA       AAAA           ", "         DDFFFGHHHHHHHGFFFDD         ", "           AAAA       AAAA           ", "                                     ", "                                     ", "                                     ", "                                     ", "                                     ", "                                     ", "                                     ", "                                     ")
            .aisle("                                     ", "                                     ", "                                     ", "                                     ", "                                     ", "                                     ", "                                     ", "                  A                  ", "              AAAAAAAAA              ", "           DDDFFFFFFFFFDDD           ", "              AAAAAAAAA              ", "                  A                  ", "                                     ", "                                     ", "                                     ", "                                     ", "                                     ", "                                     ", "                                     ")
            .aisle("                                     ", "                                     ", "                                     ", "                                     ", "                                     ", "                  A                  ", "                  A                  ", "                 ACA                 ", "                 DED                 ", "              DDDDEDDDD              ", "                 DED                 ", "                 ACA                 ", "                  A                  ", "                  A                  ", "                                     ", "                                     ", "                                     ", "                                     ", "                                     ")
            .aisle("                                     ", "                                     ", "                                     ", "                                     ", "                                     ", "                                     ", "                                     ", "                  A                  ", "                  B                  ", "                  B                  ", "                  B                  ", "                  A                  ", "                                     ", "                                     ", "                                     ", "                                     ", "                                     ", "                                     ", "                                     ");

    public static final FactoryBlockPattern MOLECULAR_ASSEMBLER_MATRIX_2 = FactoryBlockPattern.start(RelativeDirection.FRONT, RelativeDirection.UP, RelativeDirection.LEFT)
            .aisle("    BBBFFEFFBBB    ", "    KKJ  E  JKK    ", "         E         ", "         E         ", "                   ", "                   ", "                   ", "                   ", "                   ", "                   ", "                   ", "                   ", "                   ", "                   ", "                   ", "                   ", "                   ", "                   ", "                   ", "                   ")
            .aisle("    FBBBBBBBBBF    ", "     KJJJJJJJK     ", "     AAAAAAAAA     ", "      AAAAAAA      ", "         E         ", "                   ", "                   ", "                   ", "                   ", "                   ", "                   ", "                   ", "                   ", "                   ", "                   ", "                   ", "                   ", "                   ", "                   ", "                   ")
            .aisle("   FBBBBBBBBBBBF   ", "    OKJBBBBBJKO    ", "    OAAAAAAAAAO    ", "     AAAAAAAAA     ", "       AAAAA       ", "       EEEEE       ", "         E         ", "         E         ", "         E         ", "         E         ", "         E         ", "         E         ", "         E         ", "         E         ", "         E         ", "         E         ", "         E         ", "       EEEEE       ", "       AAAAA       ", "                   ")
            .aisle("  FBBBBBBBBBBBBBF  ", "   OJBBBBBBBBBJO   ", "   OAAAAAAAAAAAO   ", "    AAAAAAAAAAA    ", "     AAAAAAAAA     ", "     EEDDADDEE     ", "       FDADF       ", "       FDADF       ", "       FDADF       ", "       FDADF       ", "       FDADF       ", "       FDADF       ", "       FDADF       ", "       FDADF       ", "       FDADF       ", "       DDADD       ", "       LLALL       ", "     EEDDADDEE     ", "     AADDWDDAA     ", "       DDADD       ")
            .aisle("BFBBBBBBBBBBBBBBBFB", "K OJBBBBBBBBBBBJO K", "  OAAAAAAAAAAAAAO  ", "   AAAAAAAAAAAAA   ", "    AAAAAAAAAAA    ", "    HDDCCACCDDH    ", "    HBGCCACCGBH    ", "    HBGCCACCGBH    ", "    HBGCCACCGBH    ", "    HBGCCACCGBH    ", "    HBGCCACCGBH    ", "    HBGCCACCGBH    ", "    HBGCCACCGBH    ", "    HBGCCACCGBH    ", "    HBGCCACCGBH    ", "    HDDCCACCDDH    ", "    HLLEEAEELLH    ", "    HDDAAAAADDH    ", "    ADDWWWWWDDA    ", "     DDNNANNDD     ")
            .aisle("BBBBBBBBBBBBBBBBBBB", "KKKBBBBBBBBBBBBBKKK", " AAAAAAAAAAAAAAAAA ", "  AAAAAAAAAAAAAAA  ", "   AAAAAAAAAAAAA   ", "   EDCCWWWWWCCDE   ", "    BCCWWWWWCCB    ", "    BCCWWWWWCCB    ", "    BCCWWWWWCCB    ", "    BCCWWWWWCCB    ", "    BCCWWWWWCCB    ", "    BCCWWWWWCCB    ", "    BCCWWWWWCCB    ", "    BCCWWWWWCCB    ", "    BCCWWWWWCCB    ", "    DCCWWWWWCCD    ", "    LEEWWWWWEEL    ", "   EDAAWWWWWAADE   ", "   ADWWWWWWWWWDA   ", "    DNNAAAAANND    ")
            .aisle("BBBBBBBBBBBBBBBBBBB", "JJJBBBBBBBBBBBBBJJJ", " AAAAAAAAAAAAAAAAA ", " AAAAAAAAAAAAAAAAA ", "   AAAAAAAAAAAAA   ", "   EDCWWWWWWWCDE   ", "    GCWWWWWWWCG    ", "    GCWWWWWWWCG    ", "    GCWWWWWWWCG    ", "    GCWWWWWWWCG    ", "    GCWWWWWWWCG    ", "    GCWWWWWWWCG    ", "    GCWWWWWWWCG    ", "    GCWWWWWWWCG    ", "    GCWWWWWWWCG    ", "    DCWWWWWWWCD    ", "    LEWWWWWWWEL    ", "   EDAWWWWWWWADE   ", "   ADWWWWWWWWWDA   ", "    DNAPPPPPAND    ")
            .aisle("FBBBBBBBBBBBBBBBBBF", " JBBBBBBBBBBBBBBBJ ", " AAAAAAAAAAAAAAAAA ", " AAAAAAAAAAAAAAAAA ", "  AAAAAAAAAAAAAAA  ", "  EDCWWWWWWWWWCDE  ", "   FCWWWWWWWWWCF   ", "   FCWWWWWWWWWCF   ", "   FCWWWWWWWWWCF   ", "   FCWWWWWWWWWCF   ", "   FCWWWWWWWWWCF   ", "   FCWWWWWWWWWCF   ", "   FCWWWWWWWWWCF   ", "   FCWWWWWWWWWCF   ", "   FCWWWWWWWWWCF   ", "   DCWWWWWWWWWCD   ", "   LEWWWWWWWWWEL   ", "  EDAWWWWWWWWWADE  ", "  ADWWWWWWWWWWWDA  ", "   DNAPPQQQPPAND   ")
            .aisle("FBBBBBBBBBBBBBBBBBF", " JBBBBBBBBBBBBBBBJ ", " AAAAAAAAAAAAAAAAU ", " AAAAAAAAAAAAAAAAU ", "  AAAAAAAAAAAAAAAU ", "  EDCWWWWWWWWWCDE  ", "   DCWWWWWWWWWCD   ", "   DCWWWWWWWWWCD   ", "   DCWWWWWWWWWCD   ", "   DCWWWWWWWWWCD   ", "   DCWWWWWWWWWCD   ", "   DCWWWWWWWWWCD   ", "   DCWWWWWWWWWCD   ", "   DCWWWWWWWWWCD   ", "   DCWWWWWWWWWCD   ", "   DCWWWWWWWWWCD   ", "   LEWWWWWWWWWEL   ", "  EDAWWWWWWWWWADE  ", "  ADWWWWWWWWWWWDA  ", "   DNAPQQTQQPAND   ")
            .aisle("EBBBBBBBBBBBBBBBBBF", "EJBBBBBBBBBBBBBBBJ ", "EAAAAAAAAAAAAAAAAU ", "EAAAAAAAAAAAAAAAAS ", " EAAAAAAAAAAAAAAAU ", "  EAAWWWWRWWWWAAE  ", "  EAAWWWWRWWWWAAE  ", "  EAAWWWWRWWWWAAE  ", "  EAAWWWWRWWWWAAE  ", "  EAAWWWWRWWWWAAE  ", "  EAAWWWWRWWWWAAE  ", "  EAAWWWWMWWWWAAE  ", "  EAAWWWWRWWWWAAE  ", "  EAAWWWWRWWWWAAE  ", "  EAAWWWWRWWWWAAE  ", "  EAAWWWWRWWWWAAE  ", "  EAAWWWWRWWWWAAE  ", "  EAAWWWWRWWWWAAE  ", "  AWWWWWWRWWWWWWA  ", "   AAAPQTTTQPAAA   ")
            .aisle("FBBBBBBBBBBBBBBBBBF", " JBBBBBBBBBBBBBBBJ ", " AAAAAAAAAAAAAAAAU ", " AAAAAAAAAAAAAAAAU ", "  AAAAAAAAAAAAAAAU ", "  EDCWWWWWWWWWCDE  ", "   DCWWWWWWWWWCD   ", "   DCWWWWWWWWWCD   ", "   DCWWWWWWWWWCD   ", "   DCWWWWWWWWWCD   ", "   DCWWWWWWWWWCD   ", "   DCWWWWWWWWWCD   ", "   DCWWWWWWWWWCD   ", "   DCWWWWWWWWWCD   ", "   DCWWWWWWWWWCD   ", "   DCWWWWWWWWWCD   ", "   LEWWWWWWWWWEL   ", "  EDAWWWWWWWWWADE  ", "  ADWWWWWWWWWWWDA  ", "   DNAPQQTQQPAND   ")
            .aisle("FBBBBBBBBBBBBBBBBBF", " JBBBBBBBBBBBBBBBJ ", " AAAAAAAAAAAAAAAAA ", " AAAAAAAAAAAAAAAAA ", "  AAAAAAAAAAAAAAA  ", "  EDCWWWWWWWWWCDE  ", "   FCWWWWWWWWWCF   ", "   FCWWWWWWWWWCF   ", "   FCWWWWWWWWWCF   ", "   FCWWWWWWWWWCF   ", "   FCWWWWWWWWWCF   ", "   FCWWWWWWWWWCF   ", "   FCWWWWWWWWWCF   ", "   FCWWWWWWWWWCF   ", "   FCWWWWWWWWWCF   ", "   DCWWWWWWWWWCD   ", "   LEWWWWWWWWWEL   ", "  EDAWWWWWWWWWADE  ", "  ADWWWWWWWWWWWDA  ", "   DNAPPQQQPPAND   ")
            .aisle("BBBBBBBBBBBBBBBBBBB", "JJJBBBBBBBBBBBBBJJJ", " AAAAAAAAAAAAAAAAA ", " AAAAAAAAAAAAAAAAA ", "   AAAAAAAAAAAAA   ", "   EDCWWWWWWWCDE   ", "    GCWWWWWWWCG    ", "    GCWWWWWWWCG    ", "    GCWWWWWWWCG    ", "    GCWWWWWWWCG    ", "    GCWWWWWWWCG    ", "    GCWWWWWWWCG    ", "    GCWWWWWWWCG    ", "    GCWWWWWWWCG    ", "    GCWWWWWWWCG    ", "    DCWWWWWWWCD    ", "    LEWWWWWWWEL    ", "   EDAWWWWWWWADE   ", "   ADWWWWWWWWWDA   ", "    DNAPPPPPAND    ")
            .aisle("BBBBBBBBBBBBBBBBBBB", "KKKBBBBBBBBBBBBBKKK", " AKAAAAAAAAAAAAAAA ", "  KAAAAAAAAAAAAAA  ", "   AAAAAAAAAAAAA   ", "   EDCCWWWWWCCDE   ", "    BCCWWWWWCCB    ", "    BCCWWWWWCCB    ", "    BCCWWWWWCCB    ", "    BCCWWWWWCCB    ", "    BCCWWWWWCCB    ", "    BCCWWWWWCCB    ", "    BCCWWWWWCCB    ", "    BCCWWWWWCCB    ", "    BCCWWWWWCCB    ", "    DCCWWWWWCCD    ", "    LEEWWWWWEEL    ", "   EDAAWWWWWAADE   ", "   ADWWWWWWWWWDA   ", "    DNNAAAAANND    ")
            .aisle("BFBBBBBBBBBBBBBBBFB", "K OOBBBBBBBBBBBJO K", "  OAAAAAAAAAAAAAO  ", "   AAAAAAAAAAAAA   ", "    AAAAAAAAAAA    ", "    HDDCCACCDDH    ", "    HBGCCACCGBH    ", "    HBGCCACCGBH    ", "    HBGCCACCGBH    ", "    HBGCCACCGBH    ", "    HBGCCACCGBH    ", "    HBGCCACCGBH    ", "    HBGCCACCGBH    ", "    HBGCCACCGBH    ", "    HBGCCACCGBH    ", "    HDDCCACCDDH    ", "    HLLEEAEELLH    ", "    HDDAAAAADDH    ", "    ADDWWWWWDDA    ", "     DDNNANNDD     ")
            .aisle("  FBBBBBBBBBBBBBF  ", "   OOBBBBBBBBBJO   ", "   OAAAAAAAAAAAO   ", "    AAAAAAAAAAA    ", "     AAAAAAAAA     ", "     EEDDADDEE     ", "       FDADF       ", "       FDADF       ", "       FDADF       ", "       FDADF       ", "       FDADF       ", "       FDADF       ", "       FDADF       ", "       FDADF       ", "       FDADF       ", "       DDADD       ", "       LLALL       ", "     EEDDADDEE     ", "     AADDWDDAA     ", "       DDADD       ")
            .aisle("   FBBBBBBBBBBBF   ", "    OKJBBBBBJKO    ", "    OKAAAAAAAAO    ", "     KAAAAAAAA     ", "       AAAAA       ", "       EEEEE       ", "         E         ", "         E         ", "         E         ", "         E         ", "         E         ", "         E         ", "         E         ", "         E         ", "         E         ", "         E         ", "         E         ", "       EEEEE       ", "       AAAAA       ", "                   ")
            .aisle("    FBBBBBBBBBF    ", "     KJJJJJJJK     ", "     AAAAAAAAA     ", "      AAAAAAA      ", "         E         ", "                   ", "                   ", "                   ", "                   ", "                   ", "                   ", "                   ", "                   ", "                   ", "                   ", "                   ", "                   ", "                   ", "                   ", "                   ")
            .aisle("    BBBFFEFFBBB    ", "    KKJ  E  JKK    ", "         E         ", "         E         ", "                   ", "                   ", "                   ", "                   ", "                   ", "                   ", "                   ", "                   ", "                   ", "                   ", "                   ", "                   ", "                   ", "                   ", "                   ", "                   ");
}
