package org.gtlcore.gtlcore.common.data.machines.structure;

import com.gregtechceu.gtceu.api.pattern.FactoryBlockPattern;
import com.gregtechceu.gtceu.api.pattern.util.RelativeDirection;

import static com.gregtechceu.gtceu.api.pattern.util.RelativeDirection.*;

@SuppressWarnings("unused")
public class AdvancedMultiBlockMachineStructureB {

    public static final FactoryBlockPattern SEPARATED_PLANT = FactoryBlockPattern.start()
            .aisle("bbb", "bbb", "bbb")
            .aisle("bbb", "bcb", "bbb")
            .aisle("bbb", "bab", "bbb");

    public static final FactoryBlockPattern MIXED_PLANT = FactoryBlockPattern.start()
            .aisle("bbb", "bbb", "bbb")
            .aisle("bbb", "bcb", "bbb")
            .aisle("bbb", "bab", "bbb");

    public static final FactoryBlockPattern WEATHER_CONTROL = FactoryBlockPattern.start()
            .aisle("AAA", " A ", " A ", "   ", "   ", "   ", "   ")
            .aisle("AAA", "ABA", "ABA", " B ", " B ", " B ", " C ")
            .aisle("A~A", " A ", " A ", "   ", "   ", "   ", "   ");

    public static final FactoryBlockPattern NANO_FORGE_1 = FactoryBlockPattern.start()
            .aisle("         ", "         ", "         ", "         ", "         ", "         ", "         ", "         ", "         ", "         ", "         ", "         ", "    B    ", "    B    ", "    B    ", "    B    ", "    B    ", "    B    ", "    B    ", "    B    ", "         ", "         ", "         ", "         ", "         ", "         ", "         ", "         ", "         ", "         ", "         ", "         ", "         ", "         ", "         ", "         ", "         ", "         ")
            .aisle("  AAAAA  ", "         ", "         ", "         ", "         ", "         ", "         ", "         ", "   CBC   ", "   CBC   ", "   CBC   ", "   CBC   ", "   CBC   ", "   CBC   ", "   CBC   ", "   CBC   ", "   CBC   ", "   CBC   ", "   CBC   ", "   CBC   ", "   CBC   ", "   CBC   ", "   CBC   ", "   CBC   ", "         ", "         ", "         ", "         ", "         ", "         ", "         ", "         ", "         ", "         ", "         ", "         ", "         ", "         ")
            .aisle(" ABBBBBA ", "   CBC   ", "   CBC   ", "   CBC   ", "   CBC   ", "   CBC   ", "   CBC   ", "   CBC   ", "  CB BC  ", "  CB BC  ", "  CB BC  ", "  CB BC  ", "  BB BB  ", "  BB BB  ", "  BB BB  ", "  BB BB  ", "  BB BB  ", "  BB BB  ", "  BB BB  ", "  BB BB  ", "  CB BC  ", "  CB BC  ", "  CB BC  ", "  CB BC  ", "   CBC   ", "   CBC   ", "   CBC   ", "   CBC   ", "   CBC   ", "   CBC   ", "   CBC   ", "   CBC   ", "   CBC   ", "    C    ", "    C    ", "    C    ", "    C    ", "    C    ")
            .aisle("ABBBBBBBA", "   B B   ", "   B B   ", "   B B   ", "   B B   ", "   B B   ", "   B B   ", "   B B   ", "   B B   ", "   B B   ", "  B   B  ", "  B   B  ", "  B   B  ", "  B   B  ", "  B   B  ", " BB   BB ", " BB   BB ", "  B   B  ", "  B   B  ", "  B   B  ", "  B   B  ", "  B   B  ", "   B B   ", "   B B   ", "   B B   ", "   B B   ", "   B B   ", "   B B   ", "   B B   ", "   B B   ", "   B B   ", "   B B   ", "   B B   ", "    B    ", "    B    ", "    B    ", "    B    ", "    B    ")
            .aisle("ABBBBBBBA", "   B B   ", "   B B   ", "   B B   ", "   B B   ", "   B B   ", "   B B   ", "   B B   ", "   B B   ", "   B B   ", "  B   B  ", "  B   B  ", "  B   B  ", "  B   B  ", "  B   B  ", " BB   BB ", " BB   BB ", "  B   B  ", "  B   B  ", "  B   B  ", "  B   B  ", "  B   B  ", "   B B   ", "   B B   ", "   B B   ", "   B B   ", "   B B   ", "   B B   ", "   B B   ", "   B B   ", "   B B   ", "   B B   ", "   B B   ", "    B    ", "    B    ", "    B    ", "    B    ", "    B    ")
            .aisle("ABBBBBBBA", "   B B   ", "   B B   ", "   B B   ", "   B B   ", "   B B   ", "   B B   ", "   B B   ", "   B B   ", "   B B   ", "  B   B  ", "  B   B  ", "  B   B  ", "  B   B  ", "  B   B  ", " BB   BB ", " BB   BB ", "  B   B  ", "  B   B  ", "  B   B  ", "  B   B  ", "  B   B  ", "   B B   ", "   B B   ", "   B B   ", "   B B   ", "   B B   ", "   B B   ", "   B B   ", "   B B   ", "   B B   ", "   B B   ", "   B B   ", "    B    ", "    B    ", "    B    ", "    B    ", "    B    ")
            .aisle("ABBBBBBBA", "   B B   ", "   B B   ", "   B B   ", "   B B   ", "   B B   ", "   B B   ", "   B B   ", "   B B   ", "   B B   ", "  B   B  ", "  B   B  ", "  B   B  ", "  B   B  ", "  B   B  ", " BB   BB ", " BB   BB ", "  B   B  ", "  B   B  ", "  B   B  ", "  B   B  ", "  B   B  ", "   B B   ", "   B B   ", "   B B   ", "   B B   ", "   B B   ", "   B B   ", "   B B   ", "   B B   ", "   B B   ", "   B B   ", "   B B   ", "    B    ", "    B    ", "    B    ", "    B    ", "    B    ")
            .aisle(" ABBBBBA ", "   CBC   ", "   CBC   ", "   CBC   ", "   CBC   ", "   CBC   ", "   CBC   ", "   CBC   ", "  CB BC  ", "  CB BC  ", "  CB BC  ", "  CB BC  ", "  BB BB  ", "  BB BB  ", "  BB BB  ", "  BB BB  ", "  BB BB  ", "  BB BB  ", "  BB BB  ", "  BB BB  ", "  CB BC  ", "  CB BC  ", "  CB BC  ", "  CB BC  ", "   CBC   ", "   CBC   ", "   CBC   ", "   CBC   ", "   CBC   ", "   CBC   ", "   CBC   ", "   CBC   ", "   CBC   ", "    C    ", "    C    ", "    C    ", "    C    ", "    C    ")
            .aisle("  AA~AA  ", "         ", "         ", "         ", "         ", "         ", "         ", "         ", "   CBC   ", "   CBC   ", "   CBC   ", "   CBC   ", "   CBC   ", "   CBC   ", "   CBC   ", "   CBC   ", "   CBC   ", "   CBC   ", "   CBC   ", "   CBC   ", "   CBC   ", "   CBC   ", "   CBC   ", "   CBC   ", "         ", "         ", "         ", "         ", "         ", "         ", "         ", "         ", "         ", "         ", "         ", "         ", "         ", "         ");

    public static final FactoryBlockPattern NANO_FORGE_2 = FactoryBlockPattern.start()
            .aisle("                   ", "                   ", "                   ", "                   ", "                   ", "                   ", "                   ", "                   ", "                   ", "                   ", "                   ", "                   ", "    A              ", "    A              ", "    A              ", "    A              ", "    A              ", "    A              ", "    A              ", "    A              ", "                   ", "                   ", "                   ", "                   ", "                   ", "                   ", "                   ", "                   ", "                   ", "                   ", "                   ", "                   ", "                   ", "                   ", "                   ", "                   ", "                   ", "                   ")
            .aisle("  CCCCC            ", "                   ", "                   ", "                   ", "                   ", "                   ", "                   ", "                   ", "   DAD             ", "   DAD             ", "   DAD             ", "   DAD             ", "   DAD             ", "   DAD             ", "   DAD             ", "   DAD             ", "   DAD             ", "   DAD             ", "   DAD             ", "   DAD             ", "   DAD             ", "   DAD             ", "   DAD             ", "   DAD             ", "                   ", "                   ", "                   ", "                   ", "                   ", "                   ", "                   ", "                   ", "                   ", "                   ", "                   ", "                   ", "                   ", "                   ")
            .aisle(" CAAAAAC           ", "   DAD             ", "   DAD             ", "   DAD             ", "   DAD             ", "   DAD             ", "   DAD             ", "   DAD             ", "  DA AD            ", "  DA AD            ", "  DA AD            ", "  DA AD            ", "  AA AA            ", "  AA AA            ", "  AA AA            ", "  AA AA            ", "  AA AA            ", "  AA AA            ", "  AA AA            ", "  AA AA            ", "  DA AD            ", "  DA AD            ", "  DA AD            ", "  DA AD            ", "   DAD             ", "   DAD             ", "   DAD             ", "   DAD             ", "   DAD             ", "   DAD             ", "   DAD             ", "   DAD             ", "   DAD             ", "    D              ", "    D              ", "    D              ", "    D              ", "    D              ")
            .aisle("CAAAAAAAC          ", "   A A             ", "   A A             ", "   A A             ", "   A A             ", "   A A             ", "   A A             ", "   A A             ", "   A A             ", "   A A             ", "  A   A            ", "  A   A            ", "  A   A            ", "  A   A            ", "  A   A            ", " AA   AA           ", " AA   AA           ", "  A   A            ", "  A   A            ", "  A   A            ", "  A   A            ", "  A   A            ", "   A A             ", "   A A             ", "   A A             ", "   A A             ", "   A A             ", "   A A             ", "   A A             ", "   A A             ", "   A A             ", "   A A             ", "   A A             ", "    A              ", "    A              ", "    A              ", "    A              ", "    A              ")
            .aisle("CAAAAAAAC          ", "   A A             ", "   A A             ", "   A A             ", "   A A             ", "   A A             ", "   A A             ", "   A A             ", "   A A             ", "   A A             ", "  A   A            ", "  A   A            ", "  A   A            ", "  A   A            ", "  A   A            ", " AA   AA           ", " AA   AA           ", "  A   A            ", "  A   A            ", "  A   A            ", "  A   A            ", "  A   A            ", "   A A             ", "   A A             ", "   A A             ", "   A A             ", "   A A             ", "   A A             ", "   A A             ", "   A A             ", "   A A             ", "   A A             ", "   A A             ", "    A              ", "    A              ", "    A              ", "    A              ", "    A              ")
            .aisle("CAAAAAAAC   AAAAAA ", "   A A             ", "   A A             ", "   A A             ", "   A A             ", "   A A             ", "   A A             ", "   A A             ", "   A A             ", "   A A             ", "  A   A            ", "  A   A            ", "  A   A            ", "  A   A            ", "  A   A            ", " AA   AA           ", " AA   AA           ", "  A   A            ", "  A   A            ", "  A   A            ", "  A   A            ", "  A   A            ", "   A A             ", "   A A             ", "   A A             ", "   A A             ", "   A A             ", "   A A             ", "   A A             ", "   A A             ", "   A A             ", "   A A             ", "   A A             ", "    A              ", "    A              ", "    A              ", "    A              ", "    A              ")
            .aisle("CAAAAAAAC  AAAAAAAA", "   A A             ", "   A A             ", "   A A             ", "   A A             ", "   A A             ", "   A A             ", "   A A             ", "   A A             ", "   A A             ", "  A   A            ", "  A   A            ", "  A   A            ", "  A   A            ", "  A   A            ", " AA   AA           ", " AA   AA           ", "  A   A            ", "  A   A            ", "  A   A            ", "  A   A            ", "  A   A            ", "   A A             ", "   A A             ", "   A A             ", "   A A             ", "   A A             ", "   A A             ", "   A A             ", "   A A             ", "   A A             ", "   A A             ", "   A A             ", "    A              ", "    A              ", "    A              ", "    A              ", "    A              ")
            .aisle(" CAAAAAC   AAAAAAAA", "   DAD             ", "   DAD             ", "   DAD             ", "   DAD             ", "   DAD        AA   ", "   DAD        BB   ", "   DAD        AA   ", "  DA AD            ", "  DA AD            ", "  DA AD            ", "  DA AD            ", "  AA AA       AA   ", "  AA AA       BB   ", "  AA AA       AA   ", "  AA AA            ", "  AA AA            ", "  AA AA            ", "  AA AA            ", "  AA AA            ", "  DA AD            ", "  DA AD            ", "  DA AD            ", "  DA AD            ", "   DAD             ", "   DAD             ", "   DAD             ", "   DAD             ", "   DAD             ", "   DAD             ", "   DAD             ", "   DAD             ", "   DAD             ", "    D              ", "    D              ", "    D              ", "    D              ", "    D              ")
            .aisle("  CC~CC    AAAAAAAA", "              AA   ", "              AA   ", "              AA   ", "              AA   ", "             AAAA  ", "             BAAB  ", "             AAAA  ", "   DAD        AA   ", "   DAD        AA   ", "   DAD        AA   ", "   DAD        AA   ", "   DAD       AAAA  ", "   DAD       BAAB  ", "   DAD       AAAA  ", "   DAD             ", "   DAD             ", "   DAD             ", "   DAD             ", "   DAD             ", "   DAD             ", "   DAD             ", "   DAD             ", "   DAD             ", "                   ", "                   ", "                   ", "                   ", "                   ", "                   ", "                   ", "                   ", "                   ", "                   ", "                   ", "                   ", "                   ", "                   ")
            .aisle("           AAAAAAAA", "              AA   ", "              AA   ", "              AA   ", "              AA   ", "             AAAA  ", "             BAAB  ", "             AAAA  ", "              AA   ", "              AA   ", "              AA   ", "              AA   ", "    A        AAAA  ", "    A        BAAB  ", "    A        AAAA  ", "    A              ", "    A              ", "    A              ", "    A              ", "    A              ", "                   ", "                   ", "                   ", "                   ", "                   ", "                   ", "                   ", "                   ", "                   ", "                   ", "                   ", "                   ", "                   ", "                   ", "                   ", "                   ", "                   ", "                   ")
            .aisle("           AAAAAAAA", "                   ", "                   ", "                   ", "                   ", "              AA   ", "              BB   ", "              AA   ", "                   ", "                   ", "                   ", "                   ", "              AA   ", "              BB   ", "              AA   ", "                   ", "                   ", "                   ", "                   ", "                   ", "                   ", "                   ", "                   ", "                   ", "                   ", "                   ", "                   ", "                   ", "                   ", "                   ", "                   ", "                   ", "                   ", "                   ", "                   ", "                   ", "                   ", "                   ")
            .aisle("           AAAAAAAA", "                   ", "                   ", "                   ", "                   ", "                   ", "                   ", "                   ", "                   ", "                   ", "                   ", "                   ", "                   ", "                   ", "                   ", "                   ", "                   ", "                   ", "                   ", "                   ", "                   ", "                   ", "                   ", "                   ", "                   ", "                   ", "                   ", "                   ", "                   ", "                   ", "                   ", "                   ", "                   ", "                   ", "                   ", "                   ", "                   ", "                   ")
            .aisle("            AAAAAA ", "                   ", "                   ", "                   ", "                   ", "                   ", "                   ", "                   ", "                   ", "                   ", "                   ", "                   ", "                   ", "                   ", "                   ", "                   ", "                   ", "                   ", "                   ", "                   ", "                   ", "                   ", "                   ", "                   ", "                   ", "                   ", "                   ", "                   ", "                   ", "                   ", "                   ", "                   ", "                   ", "                   ", "                   ", "                   ", "                   ", "                   ");

    public static final FactoryBlockPattern NANO_FORGE_3 = FactoryBlockPattern.start()
            .aisle("                             ", "                             ", "                             ", "                             ", "                             ", "                             ", "                             ", "                             ", "                             ", "                             ", "                             ", "                             ", "              A              ", "              A              ", "              A              ", "              A              ", "              A              ", "              A              ", "              A              ", "              A              ", "                             ", "                             ", "                             ", "                             ", "                             ", "                             ", "                             ", "                             ", "                             ", "                             ", "                             ", "                             ", "                             ", "                             ", "                             ", "                             ", "                             ", "                             ")
            .aisle("            DDDDD            ", "                             ", "                             ", "                             ", "                             ", "                             ", "                             ", "                             ", "             CAC             ", "             CAC             ", "             CAC             ", "             CAC             ", "             CAC             ", "             CAC             ", "             CAC             ", "             CAC             ", "             CAC             ", "             CAC             ", "             CAC             ", "             CAC             ", "             CAC             ", "             CAC             ", "             CAC             ", "             CAC             ", "                             ", "                             ", "                             ", "                             ", "                             ", "                             ", "                             ", "                             ", "                             ", "                             ", "                             ", "                             ", "                             ", "                             ")
            .aisle("           DAAAAAD           ", "             CAC             ", "             CAC             ", "             CAC             ", "             CAC             ", "             CAC             ", "             CAC             ", "             CAC             ", "            CA AC            ", "            CA AC            ", "            CA AC            ", "            CA AC            ", "            AA AA            ", "            AA AA            ", "            AA AA            ", "            AA AA            ", "            AA AA            ", "            AA AA            ", "            AA AA            ", "            AA AA            ", "            CA AC            ", "            CA AC            ", "            CA AC            ", "            CA AC            ", "             CAC             ", "             CAC             ", "             CAC             ", "             CAC             ", "             CAC             ", "             CAC             ", "             CAC             ", "             CAC             ", "             CAC             ", "              C              ", "              C              ", "              C              ", "              C              ", "              C              ")
            .aisle("          DAAAAAAAD          ", "             A A             ", "             A A             ", "             A A             ", "             A A             ", "             A A             ", "             A A             ", "             A A             ", "             A A             ", "             A A             ", "            A   A            ", "            A   A            ", "            A   A            ", "            A   A            ", "            A   A            ", "           AA   AA           ", "           AA   AA           ", "            A   A            ", "            A   A            ", "            A   A            ", "            A   A            ", "            A   A            ", "             A A             ", "             A A             ", "             A A             ", "             A A             ", "             A A             ", "             A A             ", "             A A             ", "             A A             ", "             A A             ", "             A A             ", "             A A             ", "              A              ", "              A              ", "              A              ", "              A              ", "              A              ")
            .aisle("          DAAAAAAAD          ", "             A A             ", "             A A             ", "             A A             ", "             A A             ", "             A A             ", "             A A             ", "             A A             ", "             A A             ", "             A A             ", "            A   A            ", "            A   A            ", "            A   A            ", "            A   A            ", "            A   A            ", "           AA   AA           ", "           AA   AA           ", "            A   A            ", "            A   A            ", "            A   A            ", "            A   A            ", "            A   A            ", "             A A             ", "             A A             ", "             A A             ", "             A A             ", "             A A             ", "             A A             ", "             A A             ", "             A A             ", "             A A             ", "             A A             ", "             A A             ", "              A              ", "              A              ", "              A              ", "              A              ", "              A              ")
            .aisle(" AAAAAA   DAAAAAAAD   AAAAAA ", "             A A             ", "    CC       A A             ", "  CC         A A             ", "             A A             ", "             A A             ", "             A A             ", "             A A             ", "    CC       A A             ", "  CC         A A             ", "            A   A            ", "            A   A            ", "            A   A            ", "            A   A            ", "    CC      A   A            ", "  CC       AA   AA           ", "           AA   AA           ", "            A   A            ", "            A   A            ", "            A   A            ", "    CC      A   A            ", "  CC        A   A            ", "             A A             ", "             A A             ", "             A A             ", "             A A             ", "             A A             ", "             A A             ", "             A A             ", "             A A             ", "             A A             ", "             A A             ", "             A A             ", "              A              ", "              A              ", "              A              ", "              A              ", "              A              ")
            .aisle("AAAAAAAA  DAAAAAAAD  AAAAAAAA", "      C      A A             ", "             A A             ", "             A A             ", " C           A A             ", "             A A             ", "             A A             ", "      C      A A             ", "             A A             ", "             A A             ", " C          A   A            ", "            A   A            ", "            A   A            ", "      C     A   A            ", "            A   A            ", "           AA   AA           ", " C         AA   AA           ", "            A   A            ", "            A   A            ", "      C     A   A            ", "            A   A            ", "            A   A            ", " C           A A             ", "             A A             ", "             A A             ", "             A A             ", "             A A             ", "             A A             ", "             A A             ", "             A A             ", "             A A             ", "             A A             ", "             A A             ", "              A              ", "              A              ", "              A              ", "              A              ", "              A              ")
            .aisle("AAAAAAAA   DAAAAAD   AAAAAAAA", "             CAC             ", "             CAC             ", "             CAC             ", "   AA        CAC             ", "C  BB        CAC        AA   ", "   AA  C     CAC        BB   ", "             CAC        AA   ", "            CA AC            ", "            CA AC            ", "            CA AC            ", "C           CA AC            ", "       C    AA AA       AA   ", "            AA AA       BB   ", "   AA       AA AA       AA   ", "   AA       AA AA            ", "   AA       AA AA            ", "C  AA       AA AA            ", "       C    AA AA            ", "            AA AA            ", "            CA AC            ", "            CA AC            ", "            CA AC            ", "C           CA AC            ", "   AA  C     CAC             ", "   BBCC      CAC             ", "   AA        CAC             ", "             CAC             ", "             CAC             ", "             CAC             ", "             CAC             ", "             CAC             ", "             CAC             ", "              C              ", "              C              ", "              C              ", "              C              ", "              C              ")
            .aisle("AAAAAAAA    DD~DD    AAAAAAAA", "   AA                   AA   ", "   AA                   AA   ", "   AA                   AA   ", "  AAAA                  AA   ", "C BAAB                 AAAA  ", "  AAAA C               BAAB  ", "   AA                  AAAA  ", "   AA        CAC        AA   ", "   AA        CAC        AA   ", "   AA        CAC        AA   ", "C  AA        CAC        AA   ", "   AA  C     CAC       AAAA  ", "   AA        CAC       BAAB  ", "  AAAA       CAC       AAAA  ", "  AAAA       CAC             ", "  AAAA       CAC             ", "C AAAA       CAC             ", "   AA  C     CAC             ", "   AA        CAC             ", "   AA        CAC             ", "   AA        CAC             ", "   AA        CAC             ", "C  AA        CAC             ", "  AAAA C                     ", "  BAAB                       ", "  AAAA                       ", "                             ", "                             ", "                             ", "                             ", "                             ", "                             ", "                             ", "                             ", "                             ", "                             ", "                             ")
            .aisle("AAAAAAAA             AAAAAAAA", "   AA                   AA   ", "   AA                   AA   ", "   AA                   AA   ", "  AAAA                  AA   ", "  BAAB C               AAAA  ", "C AAAA                 BAAB  ", "   AA                  AAAA  ", "   AA                   AA   ", "   AA                   AA   ", "   AA                   AA   ", "   AA  C                AA   ", "C  AA         A        AAAA  ", "   AA         A        BAAB  ", "  AAAA        A        AAAA  ", "  AAAA        A              ", "  AAAA        A              ", "  AAAA C      A              ", "C  AA         A              ", "   AA         A              ", "   AA                        ", "   AA                        ", "   AA                        ", "   AA  C                     ", "C AAAA                       ", "  BAAB                       ", "  AAAA                       ", "                             ", "                             ", "                             ", "                             ", "                             ", "                             ", "                             ", "                             ", "                             ", "                             ", "                             ")
            .aisle("AAAAAAAA             AAAAAAAA", "                             ", "                             ", "                             ", "   AA                        ", "   BB  C                AA   ", "C  AA                   BB   ", "                        AA   ", "                             ", "                             ", "                             ", "       C                     ", "C                       AA   ", "                        BB   ", "   AA                   AA   ", "   AA                        ", "   AA                        ", "   AA  C                     ", "C                            ", "                             ", "                             ", "                             ", "                             ", "       C                     ", "C  AA                        ", " CCBB                        ", "   AA                        ", "                             ", "                             ", "                             ", "                             ", "                             ", "                             ", "                             ", "                             ", "                             ", "                             ", "                             ")
            .aisle("AAAAAAAA             AAAAAAAA", " C                           ", "                             ", "                             ", "      C                      ", "                             ", "                             ", " C                           ", "                             ", "                             ", "      C                      ", "                             ", "                             ", " C                           ", "                             ", "                             ", "      C                      ", "                             ", "                             ", " C                           ", "                             ", "                             ", "      C                      ", "                             ", "                             ", "                             ", "                             ", "                             ", "                             ", "                             ", "                             ", "                             ", "                             ", "                             ", "                             ", "                             ", "                             ", "                             ")
            .aisle(" AAAAAA               AAAAAA ", "                             ", "  CC                         ", "    CC                       ", "                             ", "                             ", "                             ", "                             ", "  CC                         ", "    CC                       ", "                             ", "                             ", "                             ", "                             ", "  CC                         ", "    CC                       ", "                             ", "                             ", "                             ", "                             ", "  CC                         ", "    CC                       ", "                             ", "                             ", "                             ", "                             ", "                             ", "                             ", "                             ", "                             ", "                             ", "                             ", "                             ", "                             ", "                             ", "                             ", "                             ", "                             ");

    public static final FactoryBlockPattern ISA_MILL = FactoryBlockPattern.start()
            .aisle("BBB", "BBB", "BBB")
            .aisle("BBB", "BCB", "BBB")
            .aisle("BBB", "BCB", "BBB")
            .aisle("BBB", "BCB", "BBB")
            .aisle("BBB", "BCB", "BBB")
            .aisle("BBB", "BCB", "BBB")
            .aisle("AAA", "A~A", "AAA");

    public static final FactoryBlockPattern HEAT_EXCHANGER = FactoryBlockPattern.start()
            .aisle(" AAA ", " AAA ", " AAA ", " AAA ", " AAA ", " AAA ")
            .aisle("AAAAA", "BCCCB", "BCCCB", "BCCCB", "BCCCB", "AAAAA")
            .aisle("AAAAA", "BDDDB", "BDCDB", "BDCDB", "BDDDB", "AAAAA")
            .aisle("AAAAA", "BCCCB", "BCCCB", "BCCCB", "BCCCB", "AAAAA")
            .aisle("AAAAA", "BDDDB", "BDCDB", "BDCDB", "BDDDB", "AAAAA")
            .aisle("AAAAA", "BCCCB", "BCCCB", "BCCCB", "BCCCB", "AAAAA")
            .aisle("AAAAA", "BDDDB", "BDCDB", "BDCDB", "BDDDB", "AAAAA")
            .aisle("AAAAA", "BCCCB", "BCCCB", "BCCCB", "BCCCB", "AAAAA")
            .aisle(" ASA ", " AAA ", " AAA ", " AAA ", " AAA ", " AAA ");

    public static final FactoryBlockPattern HEAT_EXCHANGER_2 = FactoryBlockPattern.start()
            .aisle("XXX", "#F#", "#F#", "#F#", "###", "###", "###")
            .aisle("XXX", "FCF", "FCF", "FCF", "#F#", "#F#", "#F#")
            .aisle("XSX", "#F#", "#F#", "#F#", "###", "###", "###");

    public static final FactoryBlockPattern FISSION_REACTOR = FactoryBlockPattern.start()
            .aisle("AAAAAAAAA", "ABBBBBBBA", "ABBBBBBBA", "ABBBBBBBA", "ABBBBBBBA", "ABBBBBBBA", "ABBBBBBBA", "ABBBBBBBA", "AAAAAAAAA")
            .aisle("AAAAAAAAA", "BCCCCCCCB", "BCCCCCCCB", "BCCCCCCCB", "BCCCCCCCB", "BCCCCCCCB", "BCCCCCCCB", "BCCCCCCCB", "AAAAAAAAA")
            .aisle("AAAAAAAAA", "BCCCCCCCB", "BCCCCCCCB", "BCCCCCCCB", "BCCCCCCCB", "BCCCCCCCB", "BCCCCCCCB", "BCCCCCCCB", "AAAAAAAAA")
            .aisle("AAAAAAAAA", "BCCCCCCCB", "BCCCCCCCB", "BCCCCCCCB", "BCCCCCCCB", "BCCCCCCCB", "BCCCCCCCB", "BCCCCCCCB", "AAAAAAAAA")
            .aisle("AAAAAAAAA", "BCCCCCCCB", "BCCCCCCCB", "BCCCCCCCB", "BCCCCCCCB", "BCCCCCCCB", "BCCCCCCCB", "BCCCCCCCB", "AAAAAAAAA")
            .aisle("AAAAAAAAA", "BCCCCCCCB", "BCCCCCCCB", "BCCCCCCCB", "BCCCCCCCB", "BCCCCCCCB", "BCCCCCCCB", "BCCCCCCCB", "AAAAAAAAA")
            .aisle("AAAAAAAAA", "BCCCCCCCB", "BCCCCCCCB", "BCCCCCCCB", "BCCCCCCCB", "BCCCCCCCB", "BCCCCCCCB", "BCCCCCCCB", "AAAAAAAAA")
            .aisle("AAAAAAAAA", "BCCCCCCCB", "BCCCCCCCB", "BCCCCCCCB", "BCCCCCCCB", "BCCCCCCCB", "BCCCCCCCB", "BCCCCCCCB", "AAAAAAAAA")
            .aisle("AAAA~AAAA", "ABBBBBBBA", "ABBBBBBBA", "ABBBBBBBA", "ABBBBBBBA", "ABBBBBBBA", "ABBBBBBBA", "ABBBBBBBA", "AAAAAAAAA");

    public static final FactoryBlockPattern SLAUGHTERHOUSE = FactoryBlockPattern.start()
            .aisle("AAAAAAA", "AAAAAAA", "ABBBBBA", "ABBBBBA", "ABBBBBA", "ABBBBBA", "ABBBBBA", "ABBBBBA", "ABBBBBA", "AAAAAAA")
            .aisle("AAAAAAA", "ACCCCCA", "BDDDDDB", "BDDDDDB", "BDDDDDB", "BDDDDDB", "BDDDDDB", "BDDDDDB", "BEEEEEB", "AAAAAAA")
            .aisle("AAAAAAA", "ACCCCCA", "BD   DB", "BD   DB", "BD   DB", "BD   DB", "BD   DB", "BD   DB", "BEEEEEB", "AAAAAAA")
            .aisle("AAAAAAA", "ACCCCCA", "BD   DB", "BD   DB", "BD   DB", "BD   DB", "BD   DB", "BD   DB", "BEEEEEB", "AAAAAAA")
            .aisle("AAAAAAA", "ACCCCCA", "BD   DB", "BD   DB", "BD   DB", "BD   DB", "BD   DB", "BD   DB", "BEEEEEB", "AAAAAAA")
            .aisle("AAAAAAA", "ACCCCCA", "BDDDDDB", "BDDDDDB", "BDDDDDB", "BDDDDDB", "BDDDDDB", "BDDDDDB", "BEEEEEB", "AAAAAAA")
            .aisle("AAAAAAA", "AAA~AAA", "ABBBBBA", "ABBBBBA", "ABBBBBA", "ABBBBBA", "ABBBBBA", "ABBBBBA", "ABBBBBA", "AAAAAAA");

    public static final FactoryBlockPattern SLAUGHTERHOUSE_2 = FactoryBlockPattern.start()
            .aisle("###############", "######OGO######", "###############")
            .aisle("######ICI######", "####GGAAAGG####", "######ICI######")
            .aisle("####CC###CC####", "###EAAOGOAAE###", "####CC###CC####")
            .aisle("###C#######C###", "##EKEG###GEKE##", "###C#######C###")
            .aisle("##C#########C##", "#GAE#######EAG#", "##C#########C##")
            .aisle("##C#########C##", "#GAG#######GAG#", "##C#########C##")
            .aisle("#I###########I#", "OAO#########OAO", "#I###########I#")
            .aisle("#C###########C#", "GAG#########GAG", "#C###########C#")
            .aisle("#I###########I#", "OAO#########OAO", "#I###########I#")
            .aisle("##C#########C##", "#GAG#######GAG#", "##C#########C##")
            .aisle("##C#########C##", "#GAE#######EAG#", "##C#########C##")
            .aisle("###C#######C###", "##EKEG###GEKE##", "###C#######C###")
            .aisle("####CC###CC####", "###EAAOGOAAE###", "####CC###CC####")
            .aisle("######ICI######", "####GGAAAGG####", "######ICI######")
            .aisle("###############", "######OSO######", "###############");

    public static final FactoryBlockPattern SLAUGHTERHOUSE_3 = FactoryBlockPattern.start()
            .aisle("                                               ", "                                               ", "                    FCCCCCF                    ", "                    FCIBICF                    ", "                    FCCCCCF                    ", "                                               ", "                                               ")
            .aisle("                                               ", "                    FCBBBCF                    ", "                   CC#####CC                   ", "                   CC#####CC                   ", "                   CC#####CC                   ", "                    FCBBBCF                    ", "                                               ")
            .aisle("                    FCBBBCF                    ", "                   CC#####CC                   ", "                CCCCC#####CCCCC                ", "                CCCHHHHHHHHHCCC                ", "                CCCCC#####CCCCC                ", "                   CC#####CC                   ", "                    FCBBBCF                    ")
            .aisle("                    FCIBICF                    ", "                CCCCC#####CCCCC                ", "              CCCCCHHHHHHHHHCCCCC              ", "              CCHHHHHHHHHHHHHHHCC              ", "              CCCCCHHHHHHHHHCCCCC              ", "                CCCCC#####CCCCC                ", "                    FCIBICF                    ")
            .aisle("                    FCBBBCF                    ", "              CCCCCCC#####CCCCCCC              ", "            CCCCHHHCC#####CCHHHCCCC            ", "            CCHHHHHHHHHHHHHHHHHHHCC            ", "            CCCCHHHCC#####CCHHHCCCC            ", "              CCCCCCC#####CCCCCCC              ", "                    FCBBBCF                    ")
            .aisle("                                               ", "            CCCCCCC FCBBBCF CCCCCCC            ", "           CCCHHCCCCC#####CCCCCHHCCC           ", "           CHHHHHHHCC#####CCHHHHHHHC           ", "           CCCHHCCCCC#####CCCCCHHCCC           ", "            CCCCCCC FCBBBCF CCCCCCC            ", "                                               ")
            .aisle("                                               ", "           CCCCC               CCCCC           ", "          CCHHCCCCC FCCCCCF CCCCCHHCC          ", "          CHHHHHCCC FCIBICF CCCHHHHHC          ", "          CCHHCCCCC FCCCCCF CCCCCHHCC          ", "           CCCCC               CCCCC           ", "                                               ")
            .aisle("                                               ", "          CCCC                   CCCC          ", "         CCHCCCC               CCCCHCC         ", "         CHHHHCC               CCHHHHC         ", "         CCHCCCC               CCCCHCC         ", "          CCCC                   CCCC          ", "                                               ")
            .aisle("                                               ", "         CCC                       CCC         ", "        CCHCCC                   CCCHCC        ", "        CHHHCC                   CCHHHC        ", "        CCHCCC                   CCCHCC        ", "         CCC                       CCC         ", "                                               ")
            .aisle("                                               ", "        CCC                         CCC        ", "       CCHCE                       ECHCC       ", "       CHHHC                       CHHHC       ", "       CCHCE                       ECHCC       ", "        CCC                         CCC        ", "                                               ")
            .aisle("                                               ", "       CCC                           CCC       ", "      CCHCC                         CCHCC      ", "      CHHHC                         CHHHC      ", "      CCHCC                         CCHCC      ", "       CCC                           CCC       ", "                                               ")
            .aisle("                                               ", "      CCC                             CCC      ", "     CCHCE                           ECHCC     ", "     CHHHC                           CHHHC     ", "     CCHCE                           ECHCC     ", "      CCC                             CCC      ", "                                               ")
            .aisle("                                               ", "     CCC                               CCC     ", "    CCHCC                             CCHCC    ", "    CHHHC                             CHHHC    ", "    CCHCC                             CCHCC    ", "     CCC                               CCC     ", "                                               ")
            .aisle("                                               ", "     CCC                               CCC     ", "    CCHCC                             CCHCC    ", "    CHHHC                             CHHHC    ", "    CCHCC                             CCHCC    ", "     CCC                               CCC     ", "                                               ")
            .aisle("                                               ", "    CCC                                 CCC    ", "   CCHCC                               CCHCC   ", "   CHHHC                               CHHHC   ", "   CCHCC                               CCHCC   ", "    CCC                                 CCC    ", "                                               ")
            .aisle("                                               ", "    CCC                                 CCC    ", "   CCHCC                               CCHCC   ", "   CHHHC                               CHHHC   ", "   CCHCC                               CCHCC   ", "    CCC                                 CCC    ", "                                               ")
            .aisle("                                               ", "   CCC                                   CCC   ", "  CCHCC                                 CCHCC  ", "  CHHHC                                 CHHHC  ", "  CCHCC                                 CCHCC  ", "   CCC                                   CCC   ", "                                               ")
            .aisle("                                               ", "   CCC                                   CCC   ", "  CCHCC                                 CCHCC  ", "  CHHHC                                 CHHHC  ", "  CCHCC                                 CCHCC  ", "   CCC                                   CCC   ", "                                               ")
            .aisle("                                               ", "   CCC                                   CCC   ", "  CCHCC                                 CCHCC  ", "  CHHHC                                 CHHHC  ", "  CCHCC                                 CCHCC  ", "   CCC                                   CCC   ", "                                               ")
            .aisle("                                               ", "  CCC                                     CCC  ", " CCHCC                                   CCHCC ", " CHHHC                                   CHHHC ", " CCHCC                                   CCHCC ", "  CCC                                     CCC  ", "                                               ")
            .aisle("  FFF                                     FFF  ", " FCCCF                                   FCCCF ", "FCCHCCF                                 FCCHCCF", "FCHHHCF                                 FCHHHCF", "FCCHCCF                                 FCCHCCF", " FCCCF                                   FCCCF ", "  FFF                                     FFF  ")
            .aisle("  CCC                                     CCC  ", " C###C                                   C###C ", "C##H##C                                 C##H##C", "C#HHH#C                                 C#HHH#C", "C##H##C                                 C##H##C", " C###C                                   C###C ", "  CCC                                     CCC  ")
            .aisle("  CIC                                     CIC  ", " B###B                                   B###B ", "C##H##C                                 C##H##C", "I#HHH#I                                 I#HHH#I", "C##H##C                                 C##H##C", " B###B                                   B###B ", "  CIC                                     CIC  ")
            .aisle("  CBC                                     CBC  ", " B###B                                   B###B ", "C##H##C                                 C##H##C", "B#HHH#B                                 B#HHH#B", "C##H##C                                 C##H##C", " B###B                                   B###B ", "  CBC                                     CBC  ")
            .aisle("  CIC                                     CIC  ", " B###B                                   B###B ", "C##H##C                                 C##H##C", "I#HHH#I                                 I#HHH#I", "C##H##C                                 C##H##C", " B###B                                   B###B ", "  CIC                                     CIC  ")
            .aisle("  CCC                                     CCC  ", " C###C                                   C###C ", "C##H##C                                 C##H##C", "C#HHH#C                                 C#HHH#C", "C##H##C                                 C##H##C", " C###C                                   C###C ", "  CCC                                     CCC  ")
            .aisle("  FFF                                     FFF  ", " FCCCF                                   FCCCF ", "FCCHCCF                                 FCCHCCF", "FCHHHCF                                 FCHHHCF", "FCCHCCF                                 FCCHCCF", " FCCCF                                   FCCCF ", "  FFF                                     FFF  ")
            .aisle("                                               ", "  CCC                                     CCC  ", " CCHCC                                   CCHCC ", " CHHHC                                   CHHHC ", " CCHCC                                   CCHCC ", "  CCC                                     CCC  ", "                                               ")
            .aisle("                                               ", "   CCC                                   CCC   ", "  CCHCC                                 CCHCC  ", "  CHHHC                                 CHHHC  ", "  CCHCC                                 CCHCC  ", "   CCC                                   CCC   ", "                                               ")
            .aisle("                                               ", "   CCC                                   CCC   ", "  CCHCC                                 CCHCC  ", "  CHHHC                                 CHHHC  ", "  CCHCC                                 CCHCC  ", "   CCC                                   CCC   ", "                                               ")
            .aisle("                                               ", "   CCC                                   CCC   ", "  CCHCC                                 CCHCC  ", "  CHHHC                                 CHHHC  ", "  CCHCC                                 CCHCC  ", "   CCC                                   CCC   ", "                                               ")
            .aisle("                                               ", "    CCC                                 CCC    ", "   CCHCC                               CCHCC   ", "   CHHHC                               CHHHC   ", "   CCHCC                               CCHCC   ", "    CCC                                 CCC    ", "                                               ")
            .aisle("                                               ", "    CCC                                 CCC    ", "   CCHCC                               CCHCC   ", "   CHHHC                               CHHHC   ", "   CCHCC                               CCHCC   ", "    CCC                                 CCC    ", "                                               ")
            .aisle("                                               ", "     CCC                               CCC     ", "    CCHCC                             CCHCC    ", "    CHHHC                             CHHHC    ", "    CCHCC                             CCHCC    ", "     CCC                               CCC     ", "                                               ")
            .aisle("                                               ", "     CCC                               CCC     ", "    CCHCC                             CCHCC    ", "    CHHHC                             CHHHC    ", "    CCHCC                             CCHCC    ", "     CCC                               CCC     ", "                                               ")
            .aisle("                                               ", "      CCC                             CCC      ", "     CCHCE                           ECHCC     ", "     CHHHC                           CHHHC     ", "     CCHCE                           ECHCC     ", "      CCC                             CCC      ", "                                               ")
            .aisle("                                               ", "       CCC                           CCC       ", "      CCHCC                         CCHCC      ", "      CHHHC                         CHHHC      ", "      CCHCC                         CCHCC      ", "       CCC                           CCC       ", "                                               ")
            .aisle("                                               ", "        CCC                         CCC        ", "       CCHCE                       ECHCC       ", "       CHHHC                       CHHHC       ", "       CCHCE                       ECHCC       ", "        CCC                         CCC        ", "                                               ")
            .aisle("                                               ", "         CCC                       CCC         ", "        CCHCCC                   CCCHCC        ", "        CHHHCC                   CCHHHC        ", "        CCHCCC                   CCCHCC        ", "         CCC                       CCC         ", "                                               ")
            .aisle("                                               ", "          CCCC                   CCCC          ", "         CCHCCCC               CCCCHCC         ", "         CHHHHCC               CCHHHHC         ", "         CCHCCCC               CCCCHCC         ", "          CCCC                   CCCC          ", "                                               ")
            .aisle("                                               ", "           CCCCC               CCCCC           ", "          CCHHCCCCC FCCCCCF CCCCCHHCC          ", "          CHHHHHCCC FCIBICF CCCHHHHHC          ", "          CCHHCCCCC FCCCCCF CCCCCHHCC          ", "           CCCCC               CCCCC           ", "                                               ")
            .aisle("                                               ", "            CCCCCCC FCBBBCF CCCCCCC            ", "           CCCHHCCCCC#####CCCCCHHCCC           ", "           CHHHHHHHCC#####CCHHHHHHHC           ", "           CCCHHCCCCC#####CCCCCHHCCC           ", "            CCCCCCC FCBBBCF CCCCCCC            ", "                                               ")
            .aisle("                    FCBBBCF                    ", "              CCCCCCC#####CCCCCCC              ", "            CCCCHHHCC#####CCHHHCCCC            ", "            CCHHHHHHHHHHHHHHHHHHHCC            ", "            CCCCHHHCC#####CCHHHCCCC            ", "              CCCCCCC#####CCCCCCC              ", "                    FCBBBCF                    ")
            .aisle("                    FCIBICF                    ", "                CCCCC#####CCCCC                ", "              CCCCCHHHHHHHHHCCCCC              ", "              CCHHHHHHHHHHHHHHHCC              ", "              CCCCCHHHHHHHHHCCCCC              ", "                CCCCC#####CCCCC                ", "                    FCIBICF                    ")
            .aisle("                    FCBBBCF                    ", "                   CC#####CC                   ", "                CCCCC#####CCCCC                ", "                CCCHHHHHHHHHCCC                ", "                CCCCC#####CCCCC                ", "                   CC#####CC                   ", "                    FCBBBCF                    ")
            .aisle("                                               ", "                    FCBBBCF                    ", "                   CC#####CC                   ", "                   CC#####CC                   ", "                   CC#####CC                   ", "                    FCBBBCF                    ", "                                               ")
            .aisle("                                               ", "                                               ", "                    FCPPPCF                    ", "                    FCISICF                    ", "                    FCPPPCF                    ", "                                               ", "                                               ");

    public static final FactoryBlockPattern SUPER_COMPUTATION = FactoryBlockPattern.start()
            .aisle("    aaaaaaa    ", "    abbbbba    ", "    abbbbba    ", "    abbbbba    ", "    aaaaaaa    ", "    abbbbba    ", "    abbbbba    ", "    abbbbba    ", "    aaaaaaa    ")
            .aisle("   aaaaaaaaa   ", "   adedededa   ", "   adedededa   ", "   adedededa   ", "   afffffffa   ", "   adedededa   ", "   adedededa   ", "   adedededa   ", "   aaaaaaaaa   ")
            .aisle("  aaaaaaaaaaa  ", "  addedededda  ", "  addedededda  ", "  addedededda  ", "  afffffffffa  ", "  addedededda  ", "  addedededda  ", "  addedededda  ", "  aaaaaaaaaaa  ")
            .aisle(" aaaaaaaaaaaaa ", " adddedededdda ", " adddedededdda ", " adddedededdda ", " afffffffffffa ", " adddedededdda ", " adddedededdda ", " adddedededdda ", " aaaaaaaaaaaaa ")
            .aisle("aaaaaaaaaaaaaaa", "addd       ddda", "addd       ddda", "addd       ddda", "afff       fffa", "addd       ddda", "addd       ddda", "adddcccccccddda", "aaaagggagggaaaa")
            .aisle("aaaaaaaaaaaaaaa", "beee       eeeb", "beee       eeeb", "beee       eeeb", "afff       fffa", "beee       eeeb", "beee       eeeb", "beeeccccccceeeb", "aaaagggagggaaaa")
            .aisle("aaaaaaaaaaaaaaa", "bddd       dddb", "bddd       dddb", "bddd       dddb", "afff       fffa", "bddd       dddb", "bddd       dddb", "bdddcccccccdddb", "aaaagggagggaaaa")
            .aisle("aaaaaaaaaaaaaaa", "beee       eeeb", "beee       eeeb", "beee       eeeb", "afff       fffa", "beee       eeeb", "beee       eeeb", "beeeccccccceeeb", "aaaaaaa~aaaaaaa")
            .aisle("aaaaaaaaaaaaaaa", "bddd       dddb", "bddd       dddb", "bddd       dddb", "afff       fffa", "bddd       dddb", "bddd       dddb", "bdddcccccccdddb", "aaaagggagggaaaa")
            .aisle("aaaaaaaaaaaaaaa", "beee       eeeb", "beee       eeeb", "beee       eeeb", "afff       fffa", "beee       eeeb", "beee       eeeb", "beeeccccccceeeb", "aaaagggagggaaaa")
            .aisle("aaaaaaaaaaaaaaa", "addd       ddda", "addd       ddda", "addd       ddda", "afff       fffa", "addd       ddda", "addd       ddda", "adddcccccccddda", "aaaagggagggaaaa")
            .aisle(" aaaaaaaaaaaaa ", " adddedededdda ", " adddedededdda ", " adddedededdda ", " afffffffffffa ", " adddedededdda ", " adddedededdda ", " adddedededdda ", " aaaaaaaaaaaaa ")
            .aisle("  aaaaaaaaaaa  ", "  addedededda  ", "  addedededda  ", "  addedededda  ", "  afffffffffa  ", "  addedededda  ", "  addedededda  ", "  addedededda  ", "  aaaaaaaaaaa  ")
            .aisle("   aaaaaaaaa   ", "   adedededa   ", "   adedededa   ", "   adedededa   ", "   afffffffa   ", "   adedededa   ", "   adedededa   ", "   adedededa   ", "   aaaaaaaaa   ")
            .aisle("    aaaaaaa    ", "    abbbbba    ", "    abbbbba    ", "    abbbbba    ", "    aaaaaaa    ", "    abbbbba    ", "    abbbbba    ", "    abbbbba    ", "    aaaaaaa    ");

    public static final FactoryBlockPattern CREATE_COMPUTATION = FactoryBlockPattern.start()
            .aisle("aa", "bb", "bb", "bb", "aa")
            .aisle("aa", "cc", "cc", "cc", "aa")
            .aisle("aa", "cc", "cc", "cc", "aa")
            .aisle("aa", "cc", "cc", "cc", "aa")
            .aisle("~a", "bb", "bb", "bb", "aa");

    public static final FactoryBlockPattern ADVANCED_INFINITE_DRILLER = FactoryBlockPattern.start()
            .aisle("          AABAA          ", "          CCCCC          ", "          CCCCC          ", "                         ", "                         ", "                         ", "                         ", "                         ", "                         ", "                         ", "                         ", "                         ", "                         ", "                         ", "                         ", "                         ", "                         ", "                         ", "                         ", "                         ", "                         ", "                         ", "                         ", "                         ", "                         ", "                         ", "                         ", "                         ", "                         ", "                         ", "                         ", "                         ", "                         ", "                         ", "                         ", "                         ", "                         ", "                         ", "                         ", "                         ", "                         ", "                         ")
            .aisle("         AAABAAA         ", "          CCCCC          ", "          CCCCC          ", "                         ", "                         ", "                         ", "                         ", "                         ", "                         ", "                         ", "                         ", "                         ", "                         ", "                         ", "                         ", "                         ", "                         ", "                         ", "                         ", "                         ", "                         ", "                         ", "                         ", "                         ", "                         ", "                         ", "                         ", "                         ", "                         ", "                         ", "                         ", "                         ", "                         ", "                         ", "                         ", "                         ", "                         ", "                         ", "                         ", "                         ", "                         ", "                         ")
            .aisle("         AAABAAA         ", "          CCCCC          ", "          CCCCC          ", "           CEC           ", "           CEC           ", "                         ", "                         ", "                         ", "                         ", "                         ", "                         ", "                         ", "                         ", "                         ", "                         ", "                         ", "                         ", "                         ", "                         ", "                         ", "                         ", "                         ", "                         ", "                         ", "                         ", "                         ", "                         ", "                         ", "                         ", "                         ", "                         ", "                         ", "                         ", "                         ", "                         ", "                         ", "                         ", "                         ", "                         ", "                         ", "                         ", "                         ")
            .aisle("         AAABAAA         ", "                         ", "                         ", "           E E           ", "           CEC           ", "          CCECC          ", "           CEC           ", "                         ", "                         ", "                         ", "                         ", "                         ", "                         ", "                         ", "                         ", "                         ", "                         ", "                         ", "                         ", "                         ", "                         ", "                         ", "                         ", "                         ", "                         ", "                         ", "                         ", "                         ", "                         ", "                         ", "                         ", "                         ", "                         ", "                         ", "                         ", "                         ", "                         ", "                         ", "                         ", "                         ", "                         ", "                         ")
            .aisle("         AAABAAA         ", "                         ", "                         ", "           E E           ", "          C   C          ", "         CCE ECC         ", "           CEC           ", "           CEC           ", "           CEC           ", "                         ", "                         ", "                         ", "                         ", "                         ", "                         ", "                         ", "                         ", "                         ", "                         ", "                         ", "                         ", "                         ", "                         ", "                         ", "                         ", "                         ", "                         ", "                         ", "                         ", "                         ", "                         ", "                         ", "                         ", "                         ", "                         ", "                         ", "                         ", "                         ", "                         ", "                         ", "                         ", "                         ")
            .aisle("         AAABAAA         ", "          C   C          ", "                         ", "          CE EC          ", "                         ", "        CC E E CC        ", "                         ", "           E E           ", "           CEC           ", "           CEC           ", "           CEC           ", "           CEC           ", "                         ", "                         ", "                         ", "                         ", "                         ", "                         ", "                         ", "                         ", "                         ", "                         ", "                         ", "                         ", "                         ", "                         ", "                         ", "                         ", "                         ", "                         ", "                         ", "                         ", "                         ", "                         ", "                         ", "                         ", "                         ", "                         ", "                         ", "                         ", "                         ", "                         ")
            .aisle("         AAABAAA         ", "                         ", "          C   C          ", "           E E           ", "                         ", "       CC  E E  CC       ", "                         ", "           E E           ", "          A   A          ", "          A   A          ", "          AAAAA          ", "           CEC           ", "           CEC           ", "           CEC           ", "           CEC           ", "          CCECC          ", "                         ", "                         ", "                         ", "                         ", "                         ", "                         ", "                         ", "                         ", "                         ", "                         ", "                         ", "                         ", "                         ", "                         ", "                         ", "                         ", "                         ", "                         ", "                         ", "                         ", "                         ", "                         ", "                         ", "                         ", "                         ", "                         ")
            .aisle("        AAAABAAAA        ", "           E E           ", "           E E           ", "          CE EC          ", "           E E           ", "      CC   E E   CC      ", "          AE EA          ", "          AE EA          ", "                         ", "                         ", "                         ", "                         ", "                         ", "                         ", "                         ", "         CCCECCC         ", "           CEC           ", "           CEC           ", "           CEC           ", "           CEC           ", "           CEC           ", "                         ", "                         ", "                         ", "                         ", "                         ", "                         ", "                         ", "                         ", "                         ", "                         ", "                         ", "                         ", "                         ", "                         ", "                         ", "                         ", "                         ", "                         ", "                         ", "                         ", "                         ")
            .aisle("       AAAFFFFFAAA       ", "        E FCCCF E        ", "        E FCCCF E        ", "        E FFFFF E        ", "        E A   A E        ", "     CC E A   A E CC     ", "        E       E        ", "        E       E        ", "        E       E        ", "        E       E        ", "        E       E        ", "        E       E        ", "        E       E        ", "        E       E        ", "        E       E        ", "        CC     CC        ", "                         ", "                         ", "                         ", "                         ", "           CEC           ", "           CEC           ", "           CEC           ", "           CEC           ", "          AAAAA          ", "          EEEEE          ", "          EEEEE          ", "                         ", "                         ", "                         ", "                         ", "                         ", "                         ", "                         ", "                         ", "                         ", "                         ", "                         ", "                         ", "                         ", "                         ", "                         ")
            .aisle("AAAAAAAAAFAGGGAFAAAAAAAAA", "CCCC     FA   AF     CCCC", "CHHC     FA   AF     CHHC", "CHHC     FA   AF     CHHC", "CCCC                 CCCC", "     C             C     ", "                         ", "                         ", "                         ", "                         ", "                         ", "                         ", "                         ", "                         ", "                         ", "       CC       CC       ", "                         ", "                         ", "                         ", "                         ", "                         ", "                         ", "           C C           ", "           AAA           ", "          AIIIA          ", "          E   E          ", "          E   E          ", "                         ", "                         ", "                         ", "                         ", "                         ", "                         ", "                         ", "                         ", "                         ", "                         ", "                         ", "                         ", "                         ", "                         ", "                         ")
            .aisle("AAAAAAAAFAG   GAFAAAAAAAA", "CCCC AAAFA     AFAAA CCCC", "C JC AAAFA     AFAAA C JC", "CJ C AAAFA     AFAAA CJ C", "C  C AAAA       AAAA C  C", " CC  C             C  CC ", "                         ", "                         ", "                         ", "                         ", "                         ", "                         ", "                         ", "                         ", "                         ", "      CC         CC      ", "                         ", "                         ", "                         ", "                         ", "                         ", "                         ", "          AAAAA          ", "          AAAAA          ", "          AIIIA          ", "          E   E          ", "          E   E          ", "                         ", "                         ", "                         ", "                         ", "                         ", "                         ", "                         ", "                         ", "                         ", "                         ", "                         ", "                         ", "                         ", "                         ", "                         ")
            .aisle("AAAAAAAAFG     GFAAAAAAAA", "CCCCAA AC       CA AACCCC", "C JCAA AC   K   CA AAC JC", "CJJJAA AF   G   FA AACJJJ", "C  CAAFA    G    AFAAC  C", " CCCCCC    ML     CCCCCC ", "      C     L     C      ", "      C     L     C      ", "      B     L     B      ", "      B     L     B      ", "      C     L     C      ", "            LM           ", "            M            ", "           ML            ", "            L            ", "      C     L     C      ", "            L            ", "            L            ", "           LLL           ", "            L            ", "      C     L     C      ", "      BA    L    AB      ", "      CAAAA L AAAAC      ", "      CAAAA L AAAAC      ", "          A L A          ", "            L            ", "            L            ", "            L            ", "            L            ", "            L            ", "            L            ", "            L            ", "            L            ", "            L            ", "            L            ", "            L            ", "            L            ", "            L            ", "            L            ", "            L            ", "            L            ", "            L            ")
            .aisle("BBBBBBBBFG     GFBBBBBBBB", "CCCCA  AC   K   CA  ACCCC", "C JCA  AC  KNK  CA  AC JC", "CJJJA  AF  GNG  FA  ACJJJ", "C  CAFFA   GNG   AFFAC  C", " CC  CCC   LNL   CCC  CC ", "     CCC   MNL   CCC     ", "     CCC   LNL   CCC     ", "     BCC   LNL   CCB     ", "     BCC   LNL   CCB     ", "     CCC   LNM   CCC     ", "      CM   LNL   MC      ", "      CM   LNL   MC      ", "      CM   LNL   MC      ", "      CM   MNL   MC      ", "      CM   LNL   MC      ", "      CM   LNL   MC      ", "      CM   LNL   MC      ", "      CM   LNL   MC      ", "      CM   LNL   MC      ", "     CCC   LNL   CCC     ", "     BCBAAMLNLMAABCB     ", "     CCCMMMLNLMMMCCC     ", "     CCCMMMLNLMMMCCC     ", "      AAAAALNLAAAAA      ", "           LNL           ", "           LNL           ", "           LNL           ", "           LNL           ", "           LNL           ", "           LNL           ", "           LNL           ", "           LNL           ", "           LNL           ", "           LNL           ", "           LNL           ", "           LNL           ", "           LNL           ", "           LNL           ", "           LNL           ", "           LNL           ", "           LNL           ")
            .aisle("AAAAAAAAFG     GFAAAAAAAA", "CCCCAA AC       CA AACCCC", "C JCAA AC   K   CA AAC JC", "CJJJAA AF   G   FA AACJJJ", "C  CAAFA    G    AFAAC  C", " CCCCCC     L     CCCCCC ", "      C     L     C      ", "      C    ML     C      ", "      B     M     B      ", "      B     LM    B      ", "      C     L     C      ", "            L            ", "            L            ", "            L            ", "            L            ", "      C    ML     C      ", "            M            ", "            LM           ", "           LLL           ", "            L            ", "      C     L     C      ", "      BA    L    AB      ", "      CAAAA L AAAAC      ", "      CAAAA L AAAAC      ", "          A L A          ", "            L            ", "            L            ", "            L            ", "            L            ", "            L            ", "            L            ", "            L            ", "            L            ", "            L            ", "            L            ", "            L            ", "            L            ", "            L            ", "            L            ", "            L            ", "            L            ", "            L            ")
            .aisle("AAAAAAAAFAG   GAFAAAAAAAA", "CCCC AAAFA     AFAAA CCCC", "C JC AAAFA     AFAAA C JC", "CJ C AAAFA     AFAAA CJ C", "C  C AAAA       AAAA C  C", " CC  C             C  CC ", "                         ", "                         ", "                         ", "                         ", "                         ", "                         ", "                         ", "                         ", "                         ", "      CC         CC      ", "                         ", "                         ", "                         ", "                         ", "                         ", "                         ", "          AAAAA          ", "          AAAAA          ", "          AIIIA          ", "          E   E          ", "          E   E          ", "                         ", "                         ", "                         ", "                         ", "                         ", "                         ", "                         ", "                         ", "                         ", "                         ", "                         ", "                         ", "                         ", "                         ", "                         ")
            .aisle("AAAAAAAAAFAGGGAFAAAAAAAAA", "CCCC     FA   AF     CCCC", "CHHC     FA   AF     CHHC", "CHHC     FA   AF     CHHC", "CCCC                 CCCC", "     C             C     ", "                         ", "                         ", "                         ", "                         ", "                         ", "                         ", "                         ", "                         ", "                         ", "       CC       CC       ", "                         ", "                         ", "                         ", "                         ", "                         ", "                         ", "           C C           ", "           AAA           ", "          AIIIA          ", "          E   E          ", "          E   E          ", "                         ", "                         ", "                         ", "                         ", "                         ", "                         ", "                         ", "                         ", "                         ", "                         ", "                         ", "                         ", "                         ", "                         ", "                         ")
            .aisle("       AAAFFFFFAAA       ", "        E FCCCF E        ", "        E FCCCF E        ", "        E FFFFF E        ", "        E A   A E        ", "     CC E A   A E CC     ", "        E       E        ", "        E       E        ", "        E       E        ", "        E       E        ", "        E       E        ", "        E       E        ", "        E       E        ", "        E       E        ", "        E       E        ", "        CC     CC        ", "                         ", "                         ", "                         ", "                         ", "           CEC           ", "           CEC           ", "           CEC           ", "           CEC           ", "          AAAAA          ", "          EEEEE          ", "          EEEEE          ", "                         ", "                         ", "                         ", "                         ", "                         ", "                         ", "                         ", "                         ", "                         ", "                         ", "                         ", "                         ", "                         ", "                         ", "                         ")
            .aisle("        AAAABAAAA        ", "           E E           ", "           E E           ", "          CE EC          ", "           E E           ", "      CC   E E   CC      ", "          AE EA          ", "          AE EA          ", "                         ", "                         ", "                         ", "                         ", "                         ", "                         ", "                         ", "         CCCECCC         ", "           CEC           ", "           CEC           ", "           CEC           ", "           CEC           ", "           CEC           ", "                         ", "                         ", "                         ", "                         ", "                         ", "                         ", "                         ", "                         ", "                         ", "                         ", "                         ", "                         ", "                         ", "                         ", "                         ", "                         ", "                         ", "                         ", "                         ", "                         ", "                         ")
            .aisle("         AAABAAA         ", "                         ", "          C   C          ", "           E E           ", "                         ", "       CC  E E  CC       ", "                         ", "           E E           ", "          A   A          ", "          A   A          ", "          AAAAA          ", "           CEC           ", "           CEC           ", "           CEC           ", "           CEC           ", "          CCECC          ", "                         ", "                         ", "                         ", "                         ", "                         ", "                         ", "                         ", "                         ", "                         ", "                         ", "                         ", "                         ", "                         ", "                         ", "                         ", "                         ", "                         ", "                         ", "                         ", "                         ", "                         ", "                         ", "                         ", "                         ", "                         ", "                         ")
            .aisle("         AAABAAA         ", "          C   C          ", "                         ", "          CE EC          ", "                         ", "        CC E E CC        ", "                         ", "           E E           ", "           CEC           ", "           CEC           ", "           CEC           ", "           CEC           ", "                         ", "                         ", "                         ", "                         ", "                         ", "                         ", "                         ", "                         ", "                         ", "                         ", "                         ", "                         ", "                         ", "                         ", "                         ", "                         ", "                         ", "                         ", "                         ", "                         ", "                         ", "                         ", "                         ", "                         ", "                         ", "                         ", "                         ", "                         ", "                         ", "                         ")
            .aisle("         AAABAAA         ", "                         ", "                         ", "           E E           ", "          C   C          ", "         CCE ECC         ", "           CEC           ", "           CEC           ", "           CEC           ", "                         ", "                         ", "                         ", "                         ", "                         ", "                         ", "                         ", "                         ", "                         ", "                         ", "                         ", "                         ", "                         ", "                         ", "                         ", "                         ", "                         ", "                         ", "                         ", "                         ", "                         ", "                         ", "                         ", "                         ", "                         ", "                         ", "                         ", "                         ", "                         ", "                         ", "                         ", "                         ", "                         ")
            .aisle("         AAABAAA         ", "                         ", "                         ", "           E E           ", "           CEC           ", "          CCECC          ", "           CEC           ", "                         ", "                         ", "                         ", "                         ", "                         ", "                         ", "                         ", "                         ", "                         ", "                         ", "                         ", "                         ", "                         ", "                         ", "                         ", "                         ", "                         ", "                         ", "                         ", "                         ", "                         ", "                         ", "                         ", "                         ", "                         ", "                         ", "                         ", "                         ", "                         ", "                         ", "                         ", "                         ", "                         ", "                         ", "                         ")
            .aisle("         AAABAAA         ", "          CCCCC          ", "          CCCCC          ", "           CEC           ", "           CEC           ", "                         ", "                         ", "                         ", "                         ", "                         ", "                         ", "                         ", "                         ", "                         ", "                         ", "                         ", "                         ", "                         ", "                         ", "                         ", "                         ", "                         ", "                         ", "                         ", "                         ", "                         ", "                         ", "                         ", "                         ", "                         ", "                         ", "                         ", "                         ", "                         ", "                         ", "                         ", "                         ", "                         ", "                         ", "                         ", "                         ", "                         ")
            .aisle("         AAABAAA         ", "          CCCCC          ", "          CCCCC          ", "                         ", "                         ", "                         ", "                         ", "                         ", "                         ", "                         ", "                         ", "                         ", "                         ", "                         ", "                         ", "                         ", "                         ", "                         ", "                         ", "                         ", "                         ", "                         ", "                         ", "                         ", "                         ", "                         ", "                         ", "                         ", "                         ", "                         ", "                         ", "                         ", "                         ", "                         ", "                         ", "                         ", "                         ", "                         ", "                         ", "                         ", "                         ", "                         ")
            .aisle("          AAQAA          ", "          CC#CC          ", "          CCCCC          ", "                         ", "                         ", "                         ", "                         ", "                         ", "                         ", "                         ", "                         ", "                         ", "                         ", "                         ", "                         ", "                         ", "                         ", "                         ", "                         ", "                         ", "                         ", "                         ", "                         ", "                         ", "                         ", "                         ", "                         ", "                         ", "                         ", "                         ", "                         ", "                         ", "                         ", "                         ", "                         ", "                         ", "                         ", "                         ", "                         ", "                         ", "                         ", "                         ")
            .aisle("                         ", "                         ", "                         ", "                         ", "                         ", "                         ", "                         ", "                         ", "                         ", "                         ", "                         ", "                         ", "                         ", "                         ", "                         ", "                         ", "                         ", "                         ", "                         ", "                         ", "                         ", "                         ", "                         ", "                         ", "                         ", "                         ", "                         ", "                         ", "                         ", "                         ", "                         ", "                         ", "                         ", "                         ", "                         ", "                         ", "                         ", "                         ", "                         ", "                         ", "                         ", "                         ");

    public static final FactoryBlockPattern SUPRACHRONAL_ASSEMBLY_LINE = FactoryBlockPattern.start(RelativeDirection.UP, RelativeDirection.BACK, RelativeDirection.LEFT)
            .aisle("                                   ", "                                   ", "                                   ", "                                   ", "                                   ", "               IIIII               ", "                                   ", "                                   ", "                                   ", "                                   ", "                                   ", "                                   ", "                                   ", "               IIIII               ", "                                   ", "                                   ", "                                   ", "                                   ", "                                   ", "                                   ", "                                   ", "               IIIII               ", "                                   ", "                                   ", "                                   ", "                                   ", "                                   ", "                                   ", "                                   ", "               IIIII               ", "                                   ", "                                   ", "                                   ", "                                   ", "                                   ", "                                   ", "                                   ", "               IIIII               ", "                                   ", "                                   ", "                                   ", "                                   ", "                                   ", "                                   ", "                                   ", "               IIIII               ", "                                   ", "                                   ", "                                   ", "                                   ", "                                   ", "                                   ", "                                   ", "               IIIII               ", "                                   ", "                                   ", "                                   ", "                                   ", "                                   ", "                                   ", "                                   ", "               IIIII               ", "                                   ", "                                   ", "                                   ", "                                   ", "                                   ", "                                   ", "                                   ", "               IIIII               ", "                                   ", "                                   ", "                                   ", "                                   ", "                                   ", "                                   ", "                                   ", "               IIIII               ", "                                   ", "                                   ", "                                   ", "                                   ", "                                   ", "                                   ", "                                   ", "               IIIII               ", "                                   ", "                                   ", "                                   ", "                                   ", "                                   ", "                                   ", "                                   ", "               IIIII               ", "                                   ", "                                   ", "                                   ", "                                   ", "                                   ", "                                   ", "                                   ", "               IIIII               ", "                                   ", "                                   ", "                                   ", "                                   ", "                                   ", "                                   ", "                                   ", "               IIIII               ", "                                   ", "                                   ", "                                   ", "                                   ", "                                   ", "                                   ", "                                   ", "               IIIII               ", "                                   ", "                                   ", "                                   ", "                                   ", "                                   ", "                                   ", "                                   ", "               IIIII               ", "                                   ", "                                   ", "                                   ", "                                   ", "                                   ")
