package org.gtlcore.gtlcore.common.data.machines.structure;

import com.gregtechceu.gtceu.api.pattern.FactoryBlockPattern;
import com.gregtechceu.gtceu.api.pattern.util.RelativeDirection;

public class MultiBlockMachineAStructureD {

    public static final FactoryBlockPattern MEGA_CANNER = FactoryBlockPattern.start()
            .aisle("AAAAAAAAA", "AAAAAAAAA", "AAAAAAAAA", "         ", "         ", "         ", "         ", "         ", "         ", "         ", "         ", "         ", "         ", "         ", "         ", "         ", "         ", "         ")
            .aisle("AAAAAAAAA", "AAAAAAAAA", "AAAAAAAAA", " AAAAAAA ", "         ", "         ", "         ", "         ", "         ", "         ", "         ", "         ", "         ", "         ", "         ", "         ", "         ", "         ")
            .aisle("AAAAAAAAA", "AAAAAAAAA", "AAAAAAAAA", " AAAAAAA ", "  AAAAA  ", "         ", "         ", "         ", "    B    ", "   DBD   ", "   D D   ", "         ", "         ", "   D D   ", "   D D   ", "    B    ", "    B    ", "         ")
            .aisle("AAAAAAAAA", "AAAAAAAAA", "AAAAAAAAA", " AAAAAAA ", "  AAAAA  ", "    B    ", "   BBB   ", "   BBB   ", "   BDB   ", "  DDDDD  ", "  DEEED  ", "   EFE   ", "   EFE   ", "  DEEED  ", "  DDDDD  ", "   BDB   ", "   BBB   ", "    B    ")
            .aisle("AAAAAAAAA", "AAAAAAAAA", "AAAAAAAAA", " AAAAAAA ", "  AAAAA  ", "   BBB   ", "   BCB   ", "   BCB   ", "  BDCDB  ", "  BDCDB  ", "   EEE   ", "   F F   ", "   F F   ", "   EEE   ", "  BDCDB  ", "  BDCDB  ", "  BBCBB  ", "   BBB   ")
            .aisle("AAAAAAAAA", "AAAAAAAAA", "AAAAAAAAA", " AAAAAAA ", "  AAAAA  ", "   BCB   ", "   BBB   ", "   BBB   ", "   BDB   ", "  DDDDD  ", "  DEEED  ", "   EFE   ", "   EFE   ", "  DEEED  ", "  DDDDD  ", "   BDB   ", "   BCB   ", "    B    ")
            .aisle("AAAAAAAAA", "AAAAAAAAA", "AAAAAAAAA", " AAAAAAA ", "  AAAAA  ", "   BCB   ", "   BBB   ", "         ", "    B    ", "   DBD   ", "   D D   ", "         ", "         ", "   D D   ", "   DDD   ", "   BBB   ", "   BCB   ", "    B    ")
            .aisle("AAAAAAAAA", "AAAAAAAAA", "AAAAAAAAA", " AAAAAAA ", "  AAAAA  ", "   BCB   ", "   BBB   ", "         ", "         ", "         ", "         ", "         ", "         ", "         ", "         ", "   BBB   ", "   BCB   ", "    B    ")
            .aisle("AAAAAAAAA", "AAAAAAAAA", "AAAAAAAAA", " AAAAAAA ", "  AAAAA  ", "   BCB   ", "   BBB   ", "    B    ", "         ", "         ", "         ", "         ", "         ", "         ", "    B    ", "   BBB   ", "   BCB   ", "    B    ")
            .aisle("AAAAAAAAA", "AAAAAAAAA", "AAAAAAAAA", " AAAAAAA ", "  AAAAA  ", "   BBB   ", "   BCB   ", "   BBB   ", "    B    ", "    B    ", "    B    ", "    B    ", "    B    ", "    B    ", "   BBB   ", "   BBB   ", "   BCB   ", "    B    ")
            .aisle("AAAAAAAAA", "AAAAAAAAA", "AAAAAAAAA", " AAAAAAA ", "  AAAAA  ", "    B    ", "   BBB   ", "   BCB   ", "   BCB   ", "   BCB   ", "   BCB   ", "   BCB   ", "   BCB   ", "   BCB   ", "   BCB   ", "   BCB   ", "    B    ", "         ")
            .aisle("AAAAAAAAA", "AAAAAAAAA", "AAAAAAAAA", " AAAAAAA ", "  AAAAA  ", "         ", "    B    ", "   BBB   ", "   BBB   ", "   BBB   ", "   BBB   ", "   BBB   ", "   BBB   ", "   BBB   ", "   BBB   ", "    B    ", "         ", "         ")
            .aisle("AAAAAAAAA", "AAAAAAAAA", "AAAAAAAAA", " AAAAAAA ", "  AAAAA  ", "         ", "         ", "    B    ", "    B    ", "    B    ", "    B    ", "    B    ", "    B    ", "    B    ", "    B    ", "         ", "         ", "         ")
            .aisle("AAAAAAAAA", "AAAAAAAAA", "AAAAAAAAA", " AAAAAAA ", "         ", "         ", "         ", "         ", "         ", "         ", "         ", "         ", "         ", "         ", "         ", "         ", "         ", "         ")
            .aisle("AAAAAAAAA", "AAAAAAAAA", "AAAAGAAAA", "         ", "         ", "         ", "         ", "         ", "         ", "         ", "         ", "         ", "         ", "         ", "         ", "         ", "         ", "         ");
    public static final FactoryBlockPattern DISASSEMBLY = FactoryBlockPattern.start()
            .aisle("AAA", "AAA", "AAA")
            .aisle("AAA", "ABA", "AAA")
            .aisle("AAA", "A~A", "AAA");
    public static final FactoryBlockPattern ELEMENT_COPYING = FactoryBlockPattern.start()
            .aisle("     AAFAA     ", "     AAFAA     ", "      AAA      ")
            .aisle("   AAAAAAAAA   ", "   AACCCCCAA   ", "     ADADA     ")
            .aisle("  AAAAABAAAAA  ", "  ACCCABACCCA  ", "   AAE ~ EAA   ")
            .aisle(" AAAAA   AAAAA ", " ACCAA   AACCA ", "  AE       EA  ")
            .aisle(" AAA       AAA ", " ACA       ACA ", "  A         A  ")
            .aisle("AAAA       AAAA", "ACCA       ACCA", " AE         EA ")
            .aisle("AAA         AAA", "ACA         ACA", "AD           DA")
            .aisle("FAB         BAF", "FCB         BCF", "AA           AA")
            .aisle("AAA         AAA", "ACA         ACA", "AD           DA")
            .aisle("AAAA       AAAA", "ACCA       ACCA", " AE         EA ")
            .aisle(" AAA       AAA ", " ACA       ACA ", "  A         A  ")
            .aisle(" AAAAA   AAAAA ", " ACCAA   AACCA ", "  AE       EA  ")
            .aisle("  AAAAABAAAAA  ", "  ACCCABACCCA  ", "   AAE   EAA   ")
            .aisle("   AAAAAAAAA   ", "   AACCCCCAA   ", "     ADADA     ")
            .aisle("     AAFAA     ", "     AAFAA     ", "      AAA      ");
    public static final FactoryBlockPattern ATOMIC_ENERGY_EXCITATION_PLANT = FactoryBlockPattern.start()
            .aisle("                   ", "                   ", "                   ", "                   ", "         A         ", "        ABA        ", "        CCC        ", "        ABA        ", "         A         ", "                   ", "                   ", "                   ", "                   ")
            .aisle("DDD             DDD", "DDD     AAA     EEE", "EEE   AA A AA   EEE", "EEE  A   A   A  EEE", "EEE  A  AAA  A   B ", " A  A  AA#AA  A  A ", " AAAB  CC#CC  BAAA ", "    A  AA#AA  A    ", "     A  AAA  A     ", "     A   A   A     ", "      AA A AA      ", "        ABA        ", "                   ")
            .aisle("DDD     AAA     DDD", "D#D   AAFGFAA   E#E", "E#E  AHHAHAHHA  E#E", "E#E AHAAAHAAAHA E#E", "E#E AHA AIA AHA A#A", "AHAAFA B###B AFAAHA", "AFHHGA C#J#C AGHHFA", " AAAFA B###B AFAAA ", "    AHA AIA AHA    ", "    AHAAAHAAAHA    ", "     AHHAHAHHA     ", "      AAFGFAA      ", "        AAA        ")
            .aisle("D~D             DDD", "DDD     AAA     EEE", "EEE   AA A AA   EEE", "EEE  A   A   A  EEE", "EEE  A  AAA  A   B ", " A  A  AA#AA  A  A ", " AAAB  CC#CC  BAAA ", "    A  AA#AA  A    ", "     A  AAA  A     ", "     A   A   A     ", "      AA A AA      ", "        ABA        ", "                   ")
            .aisle("                   ", "                   ", "                   ", "                   ", "         A         ", "        ABA        ", "        CCC        ", "        ABA        ", "         A         ", "                   ", "                   ", "                   ", "                   ");
    public static final FactoryBlockPattern FLOTATION_CELL_REGULATOR = FactoryBlockPattern.start()
            .aisle("  AAA  ", " AAAAA ", "AAAAAAA", "AAAAAAA", "AAAAAAA", " AAAAA ", "  AAA  ")
            .aisle("  AAA  ", " AADAA ", "AADDDAA", "ADDDDDA", "AADDDAA", " AADAA ", "  AAA  ")
            .aisle("       ", "   B   ", "  B#B  ", " B#C#B ", "  B#B  ", "   B   ", "       ")
            .aisle("       ", "   B   ", "  B#B  ", " B#C#B ", "  B#B  ", "   B   ", "       ")
            .aisle("       ", "   B   ", "  B#B  ", " B#C#B ", "  B#B  ", "   B   ", "       ")
            .aisle("       ", "   B   ", "  B#B  ", " B#C#B ", "  B#B  ", "   B   ", "       ")
            .aisle("       ", "   B   ", "  B#B  ", " B#C#B ", "  B#B  ", "   B   ", "       ")
            .aisle("       ", "   B   ", "  B#B  ", " B#C#B ", "  B#B  ", "   B   ", "       ")
            .aisle("       ", "       ", "   E   ", "  E~E  ", "   E   ", "       ", "       ");
    public static final FactoryBlockPattern VACUUM_DRYING_FURNACE = FactoryBlockPattern.start()
            .aisle("AAA", "BBB", "BBB", "BBB", "AAA")
            .aisle("AAA", "B B", "B B", "B B", "ACA")
            .aisle("A~A", "BBB", "BBB", "BBB", "AAA");
    public static final FactoryBlockPattern MEGA_FLUID_HEATER = FactoryBlockPattern.start()
            .aisle("           ", "           ", "           ", "   AAAAA   ", "   BBBBB   ", "   BBBBB   ", "   AAAAA   ", "           ", "           ", "           ", "           ", "           ", "           ", "           ", "           ", "           ", "           ")
            .aisle("           ", "   AAAAA   ", "   AAAAA   ", "  ACCCCCA  ", "  B     B  ", "  B     B  ", "  ACCCCCA  ", "   AAAAA   ", "           ", "           ", "           ", "           ", "           ", "           ", "           ", "           ", "           ")
            .aisle("   AAAAA   ", "  ACCCCCA  ", "  ACCCCCA  ", " ACDDDDDCA ", " B       B ", " B       B ", " AC     CA ", "  ACCCCCA  ", "   AAAAA   ", "           ", "           ", "           ", "           ", "           ", "    EEE    ", "    EEE    ", "           ")
            .aisle("  AAAAAAA  ", " ACCCCCCCA ", " ACDDDDDCA ", "ACD FFF DCA", "B   F F   B", "B   F F   B", "AC  F F  CA", " AC FFF CA ", "  A FFF A  ", "   AAAAA   ", "    ABA    ", "    ABA    ", "    ABA    ", "    EEE    ", "   EGGGE   ", "   EGGGE   ", "    GGG    ")
            .aisle("  AAAAAAA  ", " ACCCCCCCA ", " ACDHHHDCA ", "ACDFHHHFDCA", "B  FHHHF  B", "B  FHHHF  B", "AC FHHHF CA", " ACFHHHFCA ", "  AFHHHFA  ", "   AHHHA   ", "   A   A   ", "   A   A   ", "   A   A   ", "   EGGGE   ", "  EGGGGGE  ", "  EGGGGGE  ", "   GGGGG   ")
            .aisle("  AAAAAAA  ", " ACCCCCCCA ", " ACDH HDCA ", "ACDFH HFDCA", "B   H H   B", "B   H H   B", "AC  H H  CA", " ACFH HFCA ", "  AFH HFA  ", "   AH HA   ", "   B   B   ", "   B   B   ", "   B   B   ", "   EGGGE   ", "  EGGGGGE  ", "  EGGGGGE  ", "   GGGGG   ")
            .aisle("  AAAAAAA  ", " ACCCCCCCA ", " ACDHHHDCA ", "ACDFHHHFDCA", "B  FHHHF  B", "B  FHHHF  B", "AC FHHHF CA", " ACFHHHFCA ", "  AFHHHFA  ", "   AHHHA   ", "   A   A   ", "   A   A   ", "   A   A   ", "   EGGGE   ", "  EGGGGGE  ", "  EGGGGGE  ", "   GGGGG   ")
            .aisle("  AAAAAAA  ", " ACCCCCCCA ", " ACDDDDDCA ", "ACD FFF DCA", "B   F F   B", "B   F F   B", "AC  F F  CA", " AC FFF CA ", "  A FFF A  ", "   AAAAA   ", "    ABA    ", "    ABA    ", "    ABA    ", "    EEE    ", "   EGGGE   ", "   EGGGE   ", "    GGG    ")
            .aisle("   AAAAA   ", "  ACCCCCA  ", "  ACCCCCA  ", " ACDDDDDCA ", " B       B ", " B       B ", " AC     CA ", "  ACCCCCA  ", "   AAAAA   ", "           ", "           ", "           ", "           ", "           ", "    EEE    ", "    EEE    ", "    E~E    ")
            .aisle("           ", "   AAAAA   ", "   AAAAA   ", "  ACCCCCA  ", "  B     B  ", "  B     B  ", "  ACCCCCA  ", "   AAAAA   ", "           ", "           ", "           ", "           ", "           ", "           ", "           ", "           ", "           ")
            .aisle("           ", "           ", "           ", "   AAAAA   ", "   BBBBB   ", "   BBBBB   ", "   AAAAA   ", "           ", "           ", "           ", "           ", "           ", "           ", "           ", "           ", "           ", "           ");
    public static final FactoryBlockPattern ELECTRIC_IMPLOSION_COMPRESSOR = FactoryBlockPattern.start()
            .aisle("XXXXX", "F###F", "F###F", "F###F", "F###F", "F###F", "F###F", "XXXXX")
            .aisle("XXXXX", "#PGP#", "#PGP#", "#PGP#", "#PGP#", "#PGP#", "#PGP#", "XXXXX")
            .aisle("XXXXX", "#GAG#", "#GAG#", "#GAG#", "#GAG#", "#GAG#", "#GAG#", "XXMXX")
            .aisle("XXXXX", "#PGP#", "#PGP#", "#PGP#", "#PGP#", "#PGP#", "#PGP#", "XXXXX")
            .aisle("XXSXX", "F###F", "F###F", "F###F", "F###F", "F###F", "F###F", "XXXXX");
    public static final FactoryBlockPattern STELLAR_FORGE = FactoryBlockPattern.start()
            .aisle("               ", "      bbb      ", "      b b      ", "      b b      ", "      b b      ", "      b b      ", "      b b      ", "      bbb      ", "               ")
            .aisle("      b b      ", "     ccccc     ", "               ", "               ", "               ", "               ", "               ", "     ccccc     ", "      b b      ")
            .aisle("      b b      ", "   cc     cc   ", "               ", "               ", "               ", "               ", "               ", "   cc     cc   ", "      b b      ")
            .aisle("      b b      ", "  c         c  ", "     ccccc     ", "               ", "               ", "               ", "     ccccc     ", "  c         c  ", "      b b      ")
            .aisle("      b b      ", "  c         c  ", "    c ddd c    ", "      ddd      ", "      ddd      ", "      ddd      ", "    c ddd c    ", "  c         c  ", "      b b      ")
            .aisle("      b b      ", " c    ddd    c ", "   c d   d c   ", "     d   d     ", "     d   d     ", "     d   d     ", "   c d   d c   ", " c    ddd    c ", "      b b      ")
            .aisle(" bbbbbbbbbbbbb ", "bc   ddddd   cb", "b  cd     dc  b", "b   d     d   b", "b   d     d   b", "b   d     d   b", "b  cd     dc  b", "bc   ddddd   cb", " bbbbbbbbbbbbb ")
            .aisle("      bbb      ", "bc   ddddd   cb", "   cd     dc   ", "    d     d    ", "    d     d    ", "    d     d    ", "   cd     dc   ", "bc   ddddd   cb", "      bbb      ")
            .aisle(" bbbbbbbbbbbbb ", "bc   ddddd   cb", "b  cd     dc  b", "b   d     d   b", "b   d     d   b", "b   d     d   b", "b  cd     dc  b", "bc   ddddd   cb", " bbbbbbbbbbbbb ")
            .aisle("      b b      ", " c    ddd    c ", "   c d   d c   ", "     d   d     ", "     d   d     ", "     d   d     ", "   c d   d c   ", " c    ddd    c ", "      b b      ")
            .aisle("      b b      ", "  c         c  ", "    c ddd c    ", "      ddd      ", "      ddd      ", "      ddd      ", "    c ddd c    ", "  c         c  ", "      b b      ")
            .aisle("      b b      ", "  c         c  ", "     ccccc     ", "               ", "               ", "               ", "     ccccc     ", "  c         c  ", "      b b      ")
            .aisle("      b b      ", "   cc     cc   ", "               ", "               ", "               ", "               ", "               ", "   cc     cc   ", "      b b      ")
            .aisle("      b b      ", "     ccccc     ", "               ", "               ", "               ", "               ", "               ", "     ccccc     ", "      b b      ")
            .aisle("               ", "      bab      ", "      b b      ", "      b b      ", "      b b      ", "      b b      ", "      b b      ", "      bbb      ", "               ");
    public static final FactoryBlockPattern COMPONENT_ASSEMBLY_LINE = FactoryBlockPattern.start()
            .aisle("AAAAAAAAA", "A  NNN  A", "A       A", "A       A", "A       A", "A       A", "AA     AA", " AAAAAAA ", "         ", "         ")
            .aisle("AAAAAAAAA", "F       F", "F  AAA  F", "F       F", "F       F", "F       F", "A       A", "G       G", " GHAAAHG ", "         ")
            .aisle("AAAAAAAAA", "F       F", "F  AAA  F", "F I   I F", "FJ     JF", "FJ     JF", "AJ     JA", "G       G", " GA   AG ", "   AKA   ")
            .aisle("AAAAAAAAA", "F  M M  F", "F  AAA  F", "F       F", "F       F", "F       F", "A       A", "G       G", " GA   AG ", "   AKA   ")
            .aisle("AAAAAAAAA", "FL     LF", "FL AAA LF", "FL     LF", "FL     LF", "FL  J  LF", "ALL I LLA", "G LLILL G", " GA   AG ", "   KKK   ")
            .aisle("AAAAAAAAA", "F       F", "F  AAA  F", "F       F", "F       F", "F       F", "A       A", "G       G", " GA   AG ", "   AKA   ")
            .aisle("AAAAAAAAA", "F       F", "F  AAA  F", "F I   I F", "FJ     JF", "FJ     JF", "AJ     JA", "G       G", " GA   AG ", "   AKA   ")
            .aisle("AAAAAAAAA", "F       F", "F  AAA  F", "F       F", "F       F", "F       F", "A       A", "G       G", " GA   AG ", "   AKA   ")
            .aisle("AAAAAAAAA", "AL     LA", "AL AAA LA", "AL     LA", "AL     LA", "AL  J  LA", "ALL I LLA", "G LLILL G", " GA   AG ", "   KKK   ")
            .aisle("AAAAAAAAA", "F       F", "F  AAA  F", "F       F", "F       F", "F       F", "A       A", "G       G", " GA   AG ", "   AKA   ")
            .aisle("AAAAAAAAA", "F       F", "F  AAA  F", "F I   I F", "FJ     JF", "FJ     JF", "AJ     JA", "G       G", " GA   AG ", "   AKA   ")
            .aisle("AAAAAAAAA", "F       F", "F  AAA  F", "F       F", "F       F", "F       F", "A       A", "G       G", " GA   AG ", "   AKA   ")
            .aisle("AAAAAAAAA", "FL     LF", "FL AAA LF", "FL     LF", "FL     LF", "FL  J  LF", "ALL I LLA", "G LLILL G", " GA   AG ", "   KKK   ")
            .aisle("AAAAAAAAA", "F       F", "F  AAA  F", "F       F", "F       F", "F       F", "A       A", "G       G", " GA   AG ", "   AKA   ")
            .aisle("AAAAAAAAA", "F       F", "F  AAA  F", "F I   I F", "FJ     JF", "FJ     JF", "AJ     JA", "G       G", " GA   AG ", "   AKA   ")
            .aisle("AAAAAAAAA", "F       F", "F  AAA  F", "F       F", "F       F", "F       F", "A       A", "G       G", " GA   AG ", "   AKA   ")
            .aisle("AAAAAAAAA", "AL     LA", "AL AAA LA", "AL     LA", "AL     LA", "AL  J  LA", "ALL I LLA", "G LLILL G", " GA   AG ", "   KKK   ")
            .aisle("AAAAAAAAA", "F       F", "F  AAA  F", "F       F", "F       F", "F       F", "A       A", "G       G", " GA   AG ", "   AKA   ")
            .aisle("AAAAAAAAA", "F       F", "F  AAA  F", "F I   I F", "FJ     JF", "FJ     JF", "AJ     JA", "G       G", " GA   AG ", "   AKA   ")
            .aisle("AAAAAAAAA", "F       F", "F  AAA  F", "F       F", "F       F", "F       F", "A       A", "G       G", " GA   AG ", "   AKA   ")
            .aisle("AAAAAAAAA", "FL     LF", "FL AAA LF", "FL     LF", "FL     LF", "FL  J  LF", "ALL I LLA", "G LLILL G", " GA   AG ", "   KKK   ")
            .aisle("AAAAAAAAA", "F       F", "F  AAA  F", "F       F", "F       F", "F       F", "A       A", "G       G", " GA   AG ", "   AKA   ")
            .aisle("AAAAAAAAA", "F       F", "F  AAA  F", "F I   I F", "FJ     JF", "FJ     JF", "AJ     JA", "G       G", " GA   AG ", "   AKA   ")
            .aisle("AAAAAAAAA", "F       F", "F  AAA  F", "F       F", "F       F", "F       F", "A       A", "G       G", " GA   AG ", "   AKA   ")
            .aisle("AAAAAAAAA", "AL     LA", "AL AAA LA", "AL     LA", "AL     LA", "AL  J  LA", "ALL I LLA", "G LLILL G", " GA   AG ", "   KKK   ")
            .aisle("AAAAAAAAA", "F       F", "F  AAA  F", "F       F", "F       F", "F       F", "A       A", "G       G", " GA   AG ", "   AKA   ")
            .aisle("AAAAAAAAA", "F       F", "F  AAA  F", "F I   I F", "FJ     JF", "FJ     JF", "AJ     JA", "G       G", " GA   AG ", "   AKA   ")
            .aisle("AAAAAAAAA", "F       F", "F  AAA  F", "F       F", "F       F", "F       F", "A       A", "G       G", " GA   AG ", "   AKA   ")
            .aisle("AAAAAAAAA", "FL     LF", "FL AAA LF", "FL     LF", "FL     LF", "FL  J  LF", "ALL I LLA", "G LLILL G", " GA   AG ", "   KKK   ")
            .aisle("AAAAAAAAA", "F       F", "F  AAA  F", "F       F", "F       F", "F       F", "A       A", "G       G", " GA   AG ", "   AKA   ")
            .aisle("AAAAAAAAA", "F       F", "F  AAA  F", "F I   I F", "FJ     JF", "FJ     JF", "AJ     JA", "G       G", " GA   AG ", "   AKA   ")
            .aisle("AAAAAAAAA", "F       F", "F  AAA  F", "F       F", "F       F", "F       F", "A       A", "G       G", " GHAAAHG ", "         ")
            .aisle("AAAAAAAAA", "A  B B  A", "A  CCC  A", "A  CCC  A", "A       A", "A       A", "AA DDD AA", " AAD~DAA ", "   DDD   ", "         ");
    public static final FactoryBlockPattern ADVANCED_INTEGRATED_ORE_PROCESSOR = FactoryBlockPattern.start()
            .aisle("    AAAAAAAAAA ", "    AAAGGGGAAA ", "    AAAGHHGAAA ", "    AAAGHHGAAA ", "    AAAGHHGAAA ", "    AAAGHHGAAA ", "    AAAGHHGAAA ", "    AAAGHHGAAA ", "    AAAGHHGAAA ", "   AAAAGHHGAAAA", "     AAGHHGAA  ", "      AGGGGA   ")
            .aisle("   AAAAAAAAAAAA", "   BADEE  EEDAB", "   BADEE  EEDAB", "   BADEE  EEDAB", "   BADEE  EEDAB", "   BADEE  EEDAB", "   BADEE  EEDAB", "   BADEE  EEDAB", "   BADEE  EEDAB", "   AAAFF  FFAAA", "     AFF  FFA  ", "      AGCCGA   ")
            .aisle("   AAAAAAAAAAAA", "   BADEE  EEDAB", "   BADEE  EEDAB", "   BADEE  EEDAB", "   BADEE  EEDAB", "   BADEE  EEDAB", "   BADEE  EEDAB", "   BADEE  EEDAB", "   BADEE  EEDAB", "   AAAFF  FFAAA", "     AFF  FFA  ", "      AGCCGA   ")
            .aisle("   AAAAAAAAAAAA", "    A        A ", "    A        A ", "    A        A ", "    A        A ", "    A        A ", "    A        A ", "    A        A ", "    A        A ", "   AAA      AAA", "     A      A  ", "      AGGGGA   ")
            .aisle("   AAAAAAAAAAAA", "    A        A ", "    A        A ", "    A        A ", "    A        A ", "    A        A ", "    A        A ", "    A        A ", "    A        A ", "   AAA      AAA", "     A      A  ", "      AGGGGA   ")
            .aisle("   AAAAAAAAAAAA", "   BADEE  EEDAB", "   BADEE  EEDAB", "   BADEE  EEDAB", "   BADEE  EEDAB", "   BADEE  EEDAB", "   BADEE  EEDAB", "   BADEE  EEDAB", "   BADEE  EEDAB", "   AAAFF  FFAAA", "     AFF  FFA  ", "      AGCCGA   ")
            .aisle("   AAAAAAAAAAAA", "   BADEE  EEDAB", "   BADEE  EEDAB", "   BADEE  EEDAB", "   BADEE  EEDAB", "   BADEE  EEDAB", "   BADEE  EEDAB", "   BADEE  EEDAB", "   BADEE  EEDAB", "   AAAFF  FFAAA", "     AFF  FFA  ", "      AGCCGA   ")
            .aisle("   AAAAAAAAAAAA", "    A        A ", "    A        A ", "    A        A ", "    A        A ", "    A        A ", "    A        A ", "    A        A ", "    A        A ", "   AAA      AAA", "     A      A  ", "      AGGGGA   ")
            .aisle("   AAAAAAAAAAAA", "    A        A ", "    A        A ", "    A        A ", "    A        A ", "    A        A ", "    A        A ", "    A        A ", "    A        A ", "   AAA      AAA", "     A      A  ", "      AGGGGA   ")
            .aisle("   AAAAAAAAAAAA", "   BADEE  EEDAB", "   BADEE  EEDAB", "   BADEE  EEDAB", "   BADEE  EEDAB", "   BADEE  EEDAB", "   BADEE  EEDAB", "   BADEE  EEDAB", "   BADEE  EEDAB", "   AAAFF  FFAAA", "     AFF  FFA  ", "      AGCCGA   ")
            .aisle("   AAAAAAAAAAAA", "   BADEE  EEDAB", "   BADEE  EEDAB", "   BADEE  EEDAB", "   BADEE  EEDAB", "   BADEE  EEDAB", "   BADEE  EEDAB", "   BADEE  EEDAB", "   BADEE  EEDAB", "   AAAFF  FFAAA", "     AFF  FFA  ", "      AGCCGA   ")
            .aisle("   AAAAAAAAAAAA", "    A        A ", "    A        A ", "    A        A ", "    A        A ", "    A        A ", "    A        A ", "    A        A ", "    A        A ", "   AAA      AAA", "     A      A  ", "      AGGGGA   ")
            .aisle("   AAAAAAAAAAAA", "    A        A ", "    A        A ", "    A        A ", "    A        A ", "    A        A ", "    A        A ", "    A        A ", "    A        A ", "   AAA      AAA", "     A      A  ", "      AGGGGA   ")
            .aisle("   AAAAAAAAAAAA", "   BADEE  EEDAB", "   BADEE  EEDAB", "   BADEE  EEDAB", "   BADEE  EEDAB", "   BADEE  EEDAB", "   BADEE  EEDAB", "   BADEE  EEDAB", "   BADEE  EEDAB", "   AAAFF  FFAAA", "     AFF  FFA  ", "      AGCCGA   ")
            .aisle("   AAAAAAAAAAAA", "   BADEE  EEDAB", "   BADEE  EEDAB", "   BADEE  EEDAB", "   BADEE  EEDAB", "   BADEE  EEDAB", "   BADEE  EEDAB", "   BADEE  EEDAB", "   BADEE  EEDAB", "   AAAFF  FFAAA", "     AFF  FFA  ", "      AGCCGA   ")
            .aisle("   AAAAAAAAAAAA", "    A        A ", "    A        A ", "    A        A ", "    A        A ", "    A        A ", "    A        A ", "    A        A ", "    A        A ", "   AAA      AAA", "     A      A  ", "      AGGGGA   ")
            .aisle("   AAAAAAAAAAAA", "    A        A ", "    A        A ", "    A        A ", "    A        A ", "    A        A ", "    A        A ", "    A        A ", "    A        A ", "   AAA      AAA", "     A      A  ", "      AGGGGA   ")
            .aisle("   AAAAAAAAAAAA", "   BADEE  EEDAB", "   BADEE  EEDAB", "   BADEE  EEDAB", "   BADEE  EEDAB", "   BADEE  EEDAB", "   BADEE  EEDAB", "   BADEE  EEDAB", "   BADEE  EEDAB", "   AAAFF  FFAAA", "     AFF  FFA  ", "      AGCCGA   ")
            .aisle("   AAAAAAAAAAAA", "   BADEE  EEDAB", "   BADEE  EEDAB", "   BADEE  EEDAB", "   BADEE  EEDAB", "   BADEE  EEDAB", "   BADEE  EEDAB", "   BADEE  EEDAB", "   BADEE  EEDAB", "   AAAFF  FFAAA", "     AFF  FFA  ", "      AGCCGA   ")
            .aisle("   AAAAAAAAAAAA", "    A        A ", "    A        A ", "    A        A ", "    A        A ", "    A        A ", "    A        A ", "    A        A ", "    A        A ", "   AAA      AAA", "     A      A  ", "      AGGGGA   ")
            .aisle("   AAAAAAAAAAAA", "    A        A ", "    A        A ", "    A        A ", "    A        A ", "    A        A ", "    A        A ", "    A        A ", "    A        A ", "   AAA      AAA", "     A      A  ", "      AGGGGA   ")
            .aisle("   AAAAAAAAAAAA", "   BADEE  EEDAB", "   BADEE  EEDAB", "   BADEE  EEDAB", "   BADEE  EEDAB", "   BADEE  EEDAB", "   BADEE  EEDAB", "   BADEE  EEDAB", "   BADEE  EEDAB", "   AAAFF  FFAAA", "     AFF  FFA  ", "      AGCCGA   ")
            .aisle("   AAAAAAAAAAAA", "   BADEE  EEDAB", "   BADEE  EEDAB", "   BADEE  EEDAB", "   BADEE  EEDAB", "   BADEE  EEDAB", "   BADEE  EEDAB", "   BADEE  EEDAB", "   BADEE  EEDAB", "   AAAFF  FFAAA", "     AFF  FFA  ", "      AGCCGA   ")
            .aisle("   AAAAAAAAAAAA", "    A        A ", "    A        A ", "    A        A ", "    A        A ", "    A        A ", "    A        A ", "    A        A ", "    A        A ", "   AAA      AAA", "     A      A  ", "      AGGGGA   ")
            .aisle("   AAAAAAAAAAAA", "    A        A ", "    A        A ", "    A        A ", "    A        A ", "    A        A ", "    A        A ", "    A        A ", "    A        A ", "   AAA      AAA", "     A      A  ", "      AGGGGA   ")
            .aisle("   AAAAAAAAAAAA", "   BADEE  EEDAB", "   BADEE  EEDAB", "   BADEE  EEDAB", "   BADEE  EEDAB", "   BADEE  EEDAB", "   BADEE  EEDAB", "   BADEE  EEDAB", "   BADEE  EEDAB", "   AAAFF  FFAAA", "     AFF  FFA  ", "      AGCCGA   ")
            .aisle("   AAAAAAAAAAAA", "   BADEE  EEDAB", "   BADEE  EEDAB", "   BADEE  EEDAB", "   BADEE  EEDAB", "   BADEE  EEDAB", "   BADEE  EEDAB", "   BADEE  EEDAB", "   BADEE  EEDAB", "   AAAFF  FFAAA", "     AFF  FFA  ", "      AGCCGA   ")
            .aisle("   AAAAAAAAAAAA", "    A        A ", "    A        A ", "    A        A ", "    A        A ", "    A        A ", "    A        A ", "    A        A ", "    A        A ", "   AAA      AAA", "     A      A  ", "      AGGGGA   ")
            .aisle("   AAAAAAAAAAAA", "    A        A ", "    A        A ", "    A        A ", "    A        A ", "    A        A ", "    A        A ", "    A        A ", "    A        A ", "   AAA      AAA", "     A      A  ", "      AGGGGA   ")
            .aisle("IIIAAAAAAAAAAAA", "IIIBADEE  EEDAB", "IIIBADEE  EEDAB", "IIIBADEE  EEDAB", "IIIBADEE  EEDAB", "   BADEE  EEDAB", "   BADEE  EEDAB", "   BADEE  EEDAB", "   BADEE  EEDAB", "   AAAFF  FFAAA", "     AFF  FFA  ", "      AGCCGA   ")
            .aisle("IIIAAAAAAAAAAAA", "IDIBADEE  EEDAB", "IDIBADEE  EEDAB", "IDIBADEE  EEDAB", "IIIBADEE  EEDAB", "   BADEE  EEDAB", "   BADEE  EEDAB", "   BADEE  EEDAB", "   BADEE  EEDAB", "   AAAFF  FFAAA", "     AFF  FFA  ", "      AGCCGA   ")
            .aisle("III AAAAAAAAAA ", "III AAAGGGGAAA ", "I~I AAAGHHGAAA ", "III AAAGHHGAAA ", "III AAAGHHGAAA ", "    AAAGHHGAAA ", "    AAAGHHGAAA ", "    AAAGHHGAAA ", "    AAAGHHGAAA ", "   AAAAGHHGAAAA", "     AAGHHGAA  ", "      AGGGGA   ");
    public static final FactoryBlockPattern DIMENSIONALLY_TRANSCENDENT_STEAM_OVEN = FactoryBlockPattern.start()
            .aisle("XXX", "CCC", "XXX")
            .aisle("XXX", "C#C", "XMX")
            .aisle("XSX", "CCC", "XXX");
    public static final FactoryBlockPattern CRYSTALLINE_INFINITY = FactoryBlockPattern.start(RelativeDirection.LEFT, RelativeDirection.BACK, RelativeDirection.DOWN)
            .aisle("                               ", "                               ", "                               ", "                               ", "                               ", "                               ", "                               ", "                               ", "                               ", "                               ", "              BBB              ", "            BBBBBBB            ", "           BBBBBBBBB           ", "          BBBBBBBBBBB          ", "          BBBBBBBBBBB          ", "         BBBBBBBBBBBBB         ", "         BBBBBBBBBBBBB         ", "         BBBBBBBBBBBBB         ", "          BBBBBBBBBBB          ", "          BBBBBBBBBBB          ", "           BBBBBBBBB           ", "            BBBBBBB            ", "              BBB              ", "                               ", "                               ", "                               ", "                               ", "                               ", "                               ", "                               ", "                               ", "                               ")
            .aisle("                               ", "                               ", "                               ", "                               ", "                               ", "                               ", "                               ", "                               ", "                               ", "                               ", "                               ", "              GBG              ", "                               ", "                               ", "                               ", "          G   CDC   G          ", "          B   DED   B          ", "          G   CDC   G          ", "                               ", "                               ", "                               ", "              GBG              ", "                               ", "                               ", "                               ", "                               ", "                               ", "                               ", "                               ", "                               ", "                               ", "                               ")
            .aisle("                               ", "                               ", "                               ", "                               ", "                               ", "                               ", "                               ", "                               ", "                               ", "                               ", "                               ", "              GBG              ", "                               ", "                               ", "                               ", "          G   CDC   G          ", "          B   DED   B          ", "          G   CDC   G          ", "                               ", "                               ", "                               ", "              GBG              ", "                               ", "                               ", "                               ", "                               ", "                               ", "                               ", "                               ", "                               ", "                               ", "                               ")
            .aisle("                               ", "                               ", "                               ", "                               ", "                               ", "                               ", "                               ", "                               ", "                               ", "                               ", "                               ", "              GBG              ", "                               ", "                               ", "                               ", "          G   CDC   G          ", "          B   DED   B          ", "          G   CDC   G          ", "                               ", "                               ", "                               ", "              GBG              ", "                               ", "                               ", "                               ", "                               ", "                               ", "                               ", "                               ", "                               ", "                               ", "                               ")
            .aisle("                               ", "                               ", "                               ", "                               ", "                               ", "                               ", "                               ", "                               ", "                               ", "                               ", "                               ", "              GBG              ", "                               ", "                               ", "                               ", "          G   CDC   G          ", "          B   DED   B          ", "          G   CDC   G          ", "                               ", "                               ", "                               ", "              GBG              ", "                               ", "                               ", "                               ", "                               ", "                               ", "                               ", "                               ", "                               ", "                               ", "                               ")
            .aisle("                               ", "                               ", "                               ", "                               ", "                               ", "                               ", "                               ", "                               ", "                               ", "                               ", "              GBG              ", "                               ", "                               ", "                               ", "               A               ", "         G    AAA    G         ", "         B   AAEAA   B         ", "         G    AAA    G         ", "               A               ", "                               ", "                               ", "                               ", "              GBG              ", "                               ", "                               ", "                               ", "                               ", "                               ", "                               ", "                               ", "                               ", "                               ")
            .aisle("                               ", "                               ", "                               ", "                               ", "                               ", "                               ", "                               ", "                               ", "                               ", "                               ", "              GBG              ", "                               ", "                               ", "              AAA              ", "             AA AA             ", "         G  AA   AA  G         ", "         B  A     A  B         ", "         G  AA   AA  G         ", "             AA AA             ", "              AAA              ", "                               ", "                               ", "              GBG              ", "                               ", "                               ", "                               ", "                               ", "                               ", "                               ", "                               ", "                               ", "                               ")
            .aisle("                               ", "                               ", "                               ", "                               ", "                               ", "                               ", "                               ", "                               ", "                               ", "                               ", "              GBG              ", "                               ", "             AAAAA             ", "            AA   AA            ", "           AA     AA           ", "         G A       A G         ", "         B A       A B         ", "         G A       A G         ", "           AA     AA           ", "            AA   AA            ", "             AAAAA             ", "                               ", "              GBG              ", "                               ", "                               ", "                               ", "                               ", "                               ", "                               ", "                               ", "                               ", "                               ")
            .aisle("                               ", "                               ", "                               ", "                               ", "                               ", "                               ", "                               ", "                               ", "                               ", "              GBG              ", "                               ", "              AAA              ", "            AA   AA            ", "           A       A           ", "           A       A           ", "        G A         A G        ", "        B A         A B        ", "        G A         A G        ", "           A       A           ", "           A       A           ", "            AA   AA            ", "              AAA              ", "                               ", "              GBG              ", "                               ", "                               ", "                               ", "                               ", "                               ", "                               ", "                               ", "                               ")
            .aisle("                               ", "                               ", "                               ", "                               ", "                               ", "                               ", "                               ", "                               ", "                               ", "              GBG              ", "                               ", "             AAAAA             ", "           AA     AA           ", "           A       A           ", "          A         A          ", "        G A         A G        ", "        B A         A B        ", "        G A         A G        ", "          A         A          ", "           A       A           ", "           AA     AA           ", "             AAAAA             ", "                               ", "              GBG              ", "                               ", "                               ", "                               ", "                               ", "                               ", "                               ", "                               ", "                               ")
            .aisle("                               ", "                               ", "                               ", "                               ", "                               ", "                               ", "                               ", "                               ", "                               ", "              GBG              ", "              AAA              ", "            AA   AA            ", "           A       A           ", "          A         A          ", "          A         A          ", "        GA           AG        ", "        BA           AB        ", "        GA           AG        ", "          A         A          ", "          A         A          ", "           A       A           ", "            AA   AA            ", "              AAA              ", "              GBG              ", "                               ", "                               ", "                               ", "                               ", "                               ", "                               ", "                               ", "                               ")
            .aisle("                               ", "                               ", "                               ", "                               ", "                               ", "                               ", "                               ", "                               ", "              GBG              ", "                               ", "             AAAAA             ", "           AA     AA           ", "          A         A          ", "          A         A          ", "         A           A         ", "       G A           A G       ", "       B A           A B       ", "       G A           A G       ", "         A           A         ", "          A         A          ", "          A         A          ", "           AA     AA           ", "             AAAAA             ", "                               ", "              GBG              ", "                               ", "                               ", "                               ", "                               ", "                               ", "                               ", "                               ")
            .aisle("                               ", "                               ", "                               ", "                               ", "                               ", "                               ", "                               ", "                               ", "              GBG              ", "                               ", "            AAAAAAA            ", "           A       A           ", "          A         A          ", "         A           A         ", "         A           A         ", "       G A           A G       ", "       B A           A B       ", "       G A           A G       ", "         A           A         ", "         A           A         ", "          A         A          ", "           A       A           ", "            AAAAAAA            ", "                               ", "              GBG              ", "                               ", "                               ", "                               ", "                               ", "                               ", "                               ", "                               ")
            .aisle("                               ", "                               ", "                               ", "                               ", "                               ", "                               ", "                               ", "                               ", "              GBG              ", "              AAA              ", "            AA   AA            ", "          AA       AA          ", "          A         A          ", "         A           A         ", "         A           A         ", "       GA             AG       ", "       BA             AB       ", "       GA             AG       ", "         A           A         ", "         A           A         ", "          A         A          ", "          AA       AA          ", "            AA   AA            ", "              AAA              ", "              GBG              ", "                               ", "                               ", "                               ", "                               ", "                               ", "                               ", "                               ")
            .aisle("                               ", "                               ", "                               ", "                               ", "                               ", "                               ", "                               ", "              GBG              ", "                               ", "             AAAAA             ", "           AA     AA           ", "          A         A          ", "         A           A         ", "         A           A         ", "        A             A        ", "      G A             A G      ", "      B A             A B      ", "      G A             A G      ", "        A             A        ", "         A           A         ", "         A           A         ", "          A         A          ", "           AA     AA           ", "             AAAAA             ", "                               ", "              GBG              ", "                               ", "                               ", "                               ", "                               ", "                               ", "                               ")
            .aisle("                               ", "                               ", "                               ", "                               ", "                               ", "                               ", "                               ", "              GBG              ", "                               ", "             AAAAA             ", "           AA     AA           ", "          A         A          ", "         A           A         ", "         A           A         ", "        A             A        ", "      G A             A G      ", "      B A             A B      ", "      G A             A G      ", "        A             A        ", "         A           A         ", "         A           A         ", "          A         A          ", "           AA     AA           ", "             AAAAA             ", "                               ", "              GBG              ", "                               ", "                               ", "                               ", "                               ", "                               ", "                               ")
            .aisle("                               ", "                               ", "                               ", "                               ", "                               ", "                               ", "                               ", "              GBG              ", "                               ", "             AAAAA             ", "           AA     AA           ", "          A         A          ", "         A           A         ", "         A           A         ", "        A             A        ", "      G A             A G      ", "      B A             A B      ", "      G A             A G      ", "        A             A        ", "         A           A         ", "         A           A         ", "          A         A          ", "           AA     AA           ", "             AAAAA             ", "                               ", "              GBG              ", "                               ", "                               ", "                               ", "                               ", "                               ", "                               ")
            .aisle("                               ", "                               ", "                               ", "                               ", "                               ", "                               ", "              GBG              ", "              GBG              ", "             DDDDD             ", "           DDAAAAADD           ", "          DAA     AAD          ", "         DA         AD         ", "        DA           AD        ", "        DA           AD        ", "       DA             AD       ", "     GGDA             ADGG     ", "     BBDA      F      ADBB     ", "     GGDA             ADGG     ", "       DA             AD       ", "        DA           AD        ", "        DA           AD        ", "         DA         AD         ", "          DAA     AAD          ", "           DDAAAAADD           ", "             DDDDD             ", "              GBG              ", "              GBG              ", "                               ", "                               ", "                               ", "                               ", "                               ")
            .aisle("                               ", "                               ", "                               ", "                               ", "                               ", "                               ", "              GBG              ", "              GBG              ", "                               ", "             AAAAA             ", "           AA     AA           ", "          A         A          ", "         A           A         ", "         A           A         ", "        A             A        ", "     GG A             A GG     ", "     BB A             A BB     ", "     GG A             A GG     ", "        A             A        ", "         A           A         ", "         A           A         ", "          A         A          ", "           AA     AA           ", "             AAAAA             ", "                               ", "              GBG              ", "              GBG              ", "                               ", "                               ", "                               ", "                               ", "                               ")
            .aisle("                               ", "                               ", "                               ", "                               ", "                               ", "                               ", "              GBG              ", "              GBG              ", "                               ", "             AAAAA             ", "           AA     AA           ", "          A         A          ", "         A           A         ", "         A           A         ", "        A             A        ", "     GG A             A GG     ", "     BB A             A BB     ", "     GG A             A GG     ", "        A             A        ", "         A           A         ", "         A           A         ", "          A         A          ", "           AA     AA           ", "             AAAAA             ", "                               ", "              GBG              ", "              GBG              ", "                               ", "                               ", "                               ", "                               ", "                               ")
            .aisle("                               ", "                               ", "                               ", "                               ", "                               ", "              GBG              ", "                               ", "              GBG              ", "                               ", "             AAAAA             ", "           AA     AA           ", "          A         A          ", "         A           A         ", "         A           A         ", "        A             A        ", "    G G A             A G G    ", "    B B A             A B B    ", "    G G A             A G G    ", "        A             A        ", "         A           A         ", "         A           A         ", "          A         A          ", "           AA     AA           ", "             AAAAA             ", "                               ", "              GBG              ", "                               ", "              GBG              ", "                               ", "                               ", "                               ", "                               ")
            .aisle("                               ", "                               ", "                               ", "                               ", "                               ", "              GBG              ", "                               ", "                               ", "              GBG              ", "              AAA              ", "            AA   AA            ", "          AA       AA          ", "          A         A          ", "         A           A         ", "         A           A         ", "    G  GA             AG  G    ", "    B  BA             AB  B    ", "    G  GA             AG  G    ", "         A           A         ", "         A           A         ", "          A         A          ", "          AA       AA          ", "            AA   AA            ", "              AAA              ", "              GBG              ", "                               ", "                               ", "              GBG              ", "                               ", "                               ", "                               ", "                               ")
            .aisle("                               ", "                               ", "                               ", "                               ", "                               ", "              GBG              ", "                               ", "                               ", "              GBG              ", "                               ", "            AAAAAAA            ", "           A       A           ", "          A         A          ", "         A           A         ", "         A           A         ", "    G  G A           A G  G    ", "    B  B A           A B  B    ", "    G  G A           A G  G    ", "         A           A         ", "         A           A         ", "          A         A          ", "           A       A           ", "            AAAAAAA            ", "                               ", "              GBG              ", "                               ", "                               ", "              GBG              ", "                               ", "                               ", "                               ", "                               ")
            .aisle("                               ", "                               ", "                               ", "                               ", "              GBG              ", "                               ", "                               ", "                               ", "              GBG              ", "                               ", "             AAAAA             ", "           AA     AA           ", "          A         A          ", "          A         A          ", "         A           A         ", "   G   G A           A G   G   ", "   B   B A           A B   B   ", "   G   G A           A G   G   ", "         A           A         ", "          A         A          ", "          A         A          ", "           AA     AA           ", "             AAAAA             ", "                               ", "              GBG              ", "                               ", "                               ", "                               ", "              GBG              ", "                               ", "                               ", "                               ")
            .aisle("                               ", "                               ", "                               ", "                               ", "              GBG              ", "                               ", "                               ", "                               ", "                               ", "              GBG              ", "              AAA              ", "            AA   AA            ", "           A       A           ", "          A         A          ", "          A         A          ", "   G    GA           AG    G   ", "   B    BA           AB    B   ", "   G    GA           AG    G   ", "          A         A          ", "          A         A          ", "           A       A           ", "            AA   AA            ", "              AAA              ", "              GBG              ", "                               ", "                               ", "                               ", "                               ", "              GBG              ", "                               ", "                               ", "                               ")
            .aisle("                               ", "                               ", "                               ", "                               ", "              GBG              ", "                               ", "                               ", "                               ", "                               ", "              GBG              ", "                               ", "             AAAAA             ", "           AA     AA           ", "           A       A           ", "          A         A          ", "   G    G A         A G    G   ", "   B    B A         A B    B   ", "   G    G A         A G    G   ", "          A         A          ", "           A       A           ", "           AA     AA           ", "             AAAAA             ", "                               ", "              GBG              ", "                               ", "                               ", "                               ", "                               ", "              GBG              ", "                               ", "                               ", "                               ")
            .aisle("                               ", "                               ", "                               ", "              GBG              ", "                               ", "                               ", "                               ", "                               ", "                               ", "              GBG              ", "                               ", "              AAA              ", "            AA   AA            ", "           A       A           ", "           A       A           ", "  G     G A         A G     G  ", "  B     B A         A B     B  ", "  G     G A         A G     G  ", "           A       A           ", "           A       A           ", "            AA   AA            ", "              AAA              ", "                               ", "              GBG              ", "                               ", "                               ", "                               ", "                               ", "                               ", "              GBG              ", "                               ", "                               ")
            .aisle("                               ", "                               ", "                               ", "              GBG              ", "                               ", "                               ", "                               ", "                               ", "                               ", "                               ", "              GBG              ", "                               ", "             AAAAA             ", "            AA   AA            ", "           AA     AA           ", "  G      G A       A G      G  ", "  B      B A       A B      B  ", "  G      G A       A G      G  ", "           AA     AA           ", "            AA   AA            ", "             AAAAA             ", "                               ", "              GBG              ", "                               ", "                               ", "                               ", "                               ", "                               ", "                               ", "              GBG              ", "                               ", "                               ")
            .aisle("                               ", "                               ", "                               ", "              GBG              ", "                               ", "                               ", "                               ", "                               ", "                               ", "                               ", "              GBG              ", "                               ", "                               ", "              AAA              ", "             AA AA             ", "  G      G  AA   AA  G      G  ", "  B      B  A     A  B      B  ", "  G      G  AA   AA  G      G  ", "             AA AA             ", "              AAA              ", "                               ", "                               ", "              GBG              ", "                               ", "                               ", "                               ", "                               ", "                               ", "                               ", "              GBG              ", "                               ", "                               ")
            .aisle("                               ", "                               ", "              GBG              ", "                               ", "                               ", "                               ", "                               ", "                               ", "                               ", "                               ", "              GBG              ", "                               ", "                               ", "                               ", "               A               ", " G       G    AAA    G       G ", " B       B   AAEAA   B       B ", " G       G    AAA    G       G ", "               A               ", "                               ", "                               ", "                               ", "              GBG              ", "                               ", "                               ", "                               ", "                               ", "                               ", "                               ", "                               ", "              GBG              ", "                               ")
            .aisle("                               ", "                               ", "              GBG              ", "                               ", "                               ", "                               ", "                               ", "                               ", "                               ", "                               ", "                               ", "              GBG              ", "                               ", "                               ", "                               ", " G        G   CDC   G        G ", " B        B   DED   B        B ", " G        G   CDC   G        G ", "                               ", "                               ", "                               ", "              GBG              ", "                               ", "                               ", "                               ", "                               ", "                               ", "                               ", "                               ", "                               ", "              GBG              ", "                               ")
            .aisle("                               ", "                               ", "              GBG              ", "                               ", "                               ", "                               ", "                               ", "                               ", "                               ", "                               ", "                               ", "              GBG              ", "                               ", "                               ", "              CCC              ", " G        G  CCDCC  G        G ", " B        B  CDEDC  B        B ", " G        G  CCDCC  G        G ", "              CCC              ", "                               ", "                               ", "              GBG              ", "                               ", "                               ", "                               ", "                               ", "                               ", "                               ", "                               ", "                               ", "              GBG              ", "                               ")
            .aisle("                               ", "             BBBBB             ", "             BBBBB             ", "             BBBBB             ", "                               ", "                               ", "                               ", "                               ", "                               ", "                               ", "                               ", "              GBG              ", "                               ", "                               ", "BBB           CCC           BBB", "BBB       G  CCDCC  G       BBB", "BBB       B  CDEDC  B       BBB", "BBB       G  CCDCC  G       BBB", "BBB           CCC           BBB", "                               ", "                               ", "              GBG              ", "                               ", "                               ", "                               ", "                               ", "                               ", "                               ", "                               ", "             BBBBB             ", "             BBBBB             ", "             BBBBB             ")
            .aisle("              BBB              ", "             BBBBB             ", "             BBBBB             ", "             BBBBB             ", "                               ", "                               ", "                               ", "                               ", "                               ", "                               ", "             BBBBB             ", "             BGBGB             ", "             BBBBB             ", "                               ", "BBB      BBB  CCC  BBB      BBB", "BBB      BGB CCDCC BGB      BBB", "BBB      BBB CDEDC BBB      BBB", "BBB      BGB CCDCC BGB      BBB", "BBB      BBB  CCC  BBB      BBB", "                               ", "             BBBBB             ", "             BGBGB             ", "             BBBBB             ", "                               ", "                               ", "                               ", "                               ", "                               ", "                               ", "             BBBBB             ", "             BBBBB             ", "             BBBBB             ")
            .aisle("              B~B              ", "             BBBBB             ", "             BBBBB             ", "             BBBBB             ", "             BBBBB             ", "            BBBBBBB            ", "            BBBBBBB            ", "            BBBBBBB            ", "           BBBBBBBBB           ", "           BBBBBBBBB           ", "          BBBBBBBBBBB          ", "         BBBBBBBBBBBBB         ", "       BBBBBBBBBBBBBBBBB       ", "    BBBBBBBBBBBBBBBBBBBBBBB    ", "BBBBBBBBBBBBBBBBBBBBBBBBBBBBBBB", "BBBBBBBBBBBBBBBBBBBBBBBBBBBBBBB", "BBBBBBBBBBBBBBBBBBBBBBBBBBBBBBB", "BBBBBBBBBBBBBBBBBBBBBBBBBBBBBBB", "BBBBBBBBBBBBBBBBBBBBBBBBBBBBBBB", "    BBBBBBBBBBBBBBBBBBBBBBB    ", "       BBBBBBBBBBBBBBBBB       ", "         BBBBBBBBBBBBB         ", "          BBBBBBBBBBB          ", "           BBBBBBBBB           ", "           BBBBBBBBB           ", "            BBBBBBB            ", "            BBBBBBB            ", "            BBBBBBB            ", "             BBBBB             ", "             BBBBB             ", "             BBBBB             ", "             BBBBB             ")
            .aisle("              BBB              ", "             BBBBB             ", "             BBBBB             ", "             BBBBB             ", "             BBBBB             ", "            BBBBBBB            ", "            BBBBBBB            ", "            BBBBBBB            ", "           BBBBBBBBB           ", "           BBBBBBBBB           ", "          BBBBBBBBBBB          ", "         BBBBBBBBBBBBB         ", "       BBBBBBBBBBBBBBBBB       ", "    BBBBBBBBBBBBBBBBBBBBBBB    ", "BBBBBBBBBBBBBBBBBBBBBBBBBBBBBBB", "BBBBBBBBBBBBBBBBBBBBBBBBBBBBBBB", "BBBBBBBBBBBBBBBBBBBBBBBBBBBBBBB", "BBBBBBBBBBBBBBBBBBBBBBBBBBBBBBB", "BBBBBBBBBBBBBBBBBBBBBBBBBBBBBBB", "    BBBBBBBBBBBBBBBBBBBBBBB    ", "       BBBBBBBBBBBBBBBBB       ", "         BBBBBBBBBBBBB         ", "          BBBBBBBBBBB          ", "           BBBBBBBBB           ", "           BBBBBBBBB           ", "            BBBBBBB            ", "            BBBBBBB            ", "            BBBBBBB            ", "             BBBBB             ", "             BBBBB             ", "             BBBBB             ", "             BBBBB             ");
}
